File: Datasets/ABS.is_tens_Exports/ABS_1_1.csv
Time,Displacement,Force,Strain 1,Tensile displacement,Tensile stress,Tensile strain (Displacement)
(s),(mm),(kN),(%),(mm),(MPa),(%)
"0.0000","0.0964","0.0001","0.0024","-0.0003","0.0029","-0.0004"
"0.0400","0.0972","0.0001","-0.0018","0.0004","0.0037","0.0006"
"0.0800","0.1010","0.0018","-0.0020","0.0043","0.0459","0.0053"
"0.1200","0.1049","0.0055","-0.0013","0.0082","0.1408","0.0102"
"0.1600","0.1088","0.0089","0.0017","0.0120","0.2268","0.0150"
"0.2000","0.1129","0.0123","-0.0007","0.0161","0.3145","0.0202"
"0.2400","0.1170","0.0157","-0.0019","0.0202","0.4029","0.0252"
"0.2800","0.1213","0.0194","-0.0019","0.0245","0.4958","0.0306"
"0.3200","0.1251","0.0229","0.0011","0.0283","0.5855","0.0354"
"0.3600","0.1289","0.0261","-0.0021","0.0322","0.6688","0.0401"
"0.4000","0.1330","0.0293","0.0011","0.0363","0.7504","0.0453"
"0.4400","0.1368","0.0325","-0.0043","0.0401","0.8329","0.0501"
"0.4800","0.1407","0.0353","0.0000","0.0439","0.9041","0.0549"
"0.5200","0.1450","0.0381","-0.0001","0.0483","0.9750","0.0602"
"0.5600","0.1491","0.0411","0.0005","0.0523","1.0525","0.0653"
"0.6000","0.1527","0.0440","-0.0029","0.0560","1.1265","0.0699"
"0.6400","0.1569","0.0463","-0.0019","0.0602","1.1862","0.0751"
"0.6800","0.1609","0.0485","0.0008","0.0641","1.2424","0.0801"
"0.7200","0.1647","0.0501","-0.0002","0.0680","1.2840","0.0848"
"0.7600","0.1689","0.0513","-0.0013","0.0721","1.3148","0.0900"
"0.8000","0.1729","0.0520","-0.0016","0.0761","1.3331","0.0950"
"0.8400","0.1769","0.0531","-0.0004","0.0802","1.3598","0.1001"
"0.8800","0.1808","0.0534","0.0004","0.0840","1.3680","0.1049"
"0.9200","0.1846","0.0539","0.0004","0.0879","1.3802","0.1097"
"0.9600","0.1887","0.0544","-0.0024","0.0919","1.3941","0.1148"
"1.0000","0.1927","0.0551","-0.0008","0.0959","1.4123","0.1197"
"1.0400","0.1965","0.0554","0.0004","0.0997","1.4197","0.1245"
"1.0800","0.2008","0.0556","0.0018","0.1041","1.4230","0.1299"
"1.1200","0.2050","0.0555","-0.0043","0.1082","1.4228","0.1351"
"1.1600","0.2087","0.0556","0.0009","0.1119","1.4251","0.1397"
"1.2000","0.2129","0.0559","-0.0009","0.1161","1.4312","0.1450"
"1.2400","0.2168","0.0559","0.0023","0.1201","1.4313","0.1499"
"1.2800","0.2207","0.0558","-0.0018","0.1239","1.4298","0.1547"
"1.3200","0.2248","0.0561","-0.0014","0.1280","1.4378","0.1598"
"1.3600","0.2288","0.0564","-0.0013","0.1321","1.4437","0.1649"
"1.4000","0.2329","0.0565","0.0020","0.1362","1.4463","0.1700"
"1.4400","0.2368","0.0565","0.0009","0.1401","1.4478","0.1749"
"1.4800","0.2407","0.0567","-0.0014","0.1439","1.4512","0.1797"
"1.5200","0.2448","0.0566","-0.0029","0.1480","1.4507","0.1848"
"1.5600","0.2488","0.0567","0.0016","0.1521","1.4517","0.1899"
"1.6000","0.2526","0.0569","-0.0004","0.1559","1.4576","0.1946"
"1.6400","0.2569","0.0570","0.0017","0.1601","1.4603","0.1999"
"1.6800","0.2610","0.0572","-0.0031","0.1643","1.4646","0.2051"
"1.7200","0.2646","0.0573","0.0016","0.1679","1.4681","0.2096"
"1.7600","0.2687","0.0575","-0.0003","0.1720","1.4728","0.2147"
"1.8000","0.2727","0.0576","-0.0016","0.1760","1.4763","0.2197"
"1.8400","0.2766","0.0580","0.0009","0.1798","1.4864","0.2245"
"1.8800","0.2806","0.0580","-0.0036","0.1839","1.4856","0.2296"
"1.9200","0.2848","0.0583","0.0033","0.1880","1.4928","0.2348"
"1.9600","0.2890","0.0583","0.0009","0.1922","1.4928","0.2400"
"2.0000","0.2929","0.0585","-0.0019","0.1961","1.4973","0.2449"
"2.0400","0.2968","0.0588","0.0003","0.2001","1.5055","0.2498"
"2.0800","0.3008","0.0589","-0.0028","0.2041","1.5088","0.2548"
"2.1200","0.3048","0.0590","0.0034","0.2080","1.5100","0.2597"
"2.1600","0.3086","0.0591","-0.0011","0.2118","1.5127","0.2645"
"2.2000","0.3128","0.0591","-0.0007","0.2161","1.5126","0.2698"
"2.2400","0.3169","0.0592","0.0007","0.2202","1.5159","0.2749"
"2.2800","0.3206","0.0593","-0.0012","0.2239","1.5196","0.2795"
"2.3200","0.3248","0.0594","0.0018","0.2280","1.5208","0.2847"
"2.3600","0.3288","0.0596","-0.0015","0.2320","1.5261","0.2897"
"2.4000","0.3327","0.0598","-0.0015","0.2360","1.5312","0.2946"
"2.4400","0.3368","0.0600","0.0021","0.2400","1.5368","0.2996"
"2.4800","0.3408","0.0600","-0.0010","0.2441","1.5381","0.3047"
"2.5200","0.3449","0.0601","0.0019","0.2481","1.5405","0.3098"
"2.5600","0.3489","0.0603","-0.0038","0.2521","1.5440","0.3148"
"2.6000","0.3527","0.0603","0.0011","0.2559","1.5453","0.3195"
"2.6400","0.3567","0.0604","0.0015","0.2599","1.5474","0.3245"
"2.6800","0.3608","0.0605","-0.0018","0.2641","1.5499","0.3297"
"2.7200","0.3645","0.0606","0.0011","0.2678","1.5519","0.3343"
"2.7600","0.3688","0.0609","-0.0042","0.2720","1.5608","0.3396"
"2.8000","0.3731","0.0611","0.0037","0.2763","1.5641","0.3450"
"2.8400","0.3767","0.0611","-0.0014","0.2800","1.5660","0.3495"
"2.8800","0.3808","0.0611","0.0011","0.2841","1.5648","0.3546"
"2.9200","0.3849","0.0612","-0.0024","0.2881","1.5676","0.3597"
"2.9600","0.3887","0.0615","0.0000","0.2920","1.5745","0.3645"
"3.0000","0.3927","0.0618","0.0012","0.2959","1.5827","0.3694"
"3.0400","0.3968","0.0619","0.0005","0.3001","1.5867","0.3746"
"3.0800","0.4008","0.0624","-0.0023","0.3041","1.5995","0.3796"
"3.1200","0.4047","0.0632","0.0014","0.3080","1.6183","0.3845"
"3.1600","0.4087","0.0643","-0.0013","0.3119","1.6478","0.3894"
"3.2000","0.4127","0.0658","0.0028","0.3160","1.6863","0.3945"
"3.2400","0.4169","0.0679","-0.0037","0.3201","1.7389","0.3997"
"3.2800","0.4207","0.0692","0.0010","0.3239","1.7724","0.4044"
"3.3200","0.4248","0.0712","-0.0003","0.3281","1.8229","0.4096"
"3.3600","0.4290","0.0728","0.0007","0.3322","1.8655","0.4148"
"3.4000","0.4327","0.0742","0.0016","0.3359","1.9013","0.4194"
"3.4400","0.4367","0.0758","-0.0048","0.3400","1.9417","0.4245"
"3.4800","0.4408","0.0782","0.0008","0.3440","2.0025","0.4295"
"3.5200","0.4447","0.0808","0.0004","0.3479","2.0694","0.4344"
"3.5600","0.4487","0.0835","0.0011","0.3519","2.1399","0.4394"
"3.6000","0.4528","0.0865","0.0001","0.3561","2.2148","0.4446"
"3.6400","0.4569","0.0892","-0.0041","0.3601","2.2861","0.4496"
"3.6800","0.4610","0.0922","0.0023","0.3642","2.3629","0.4547"
"3.7200","0.4648","0.0952","-0.0018","0.3680","2.4388","0.4595"
"3.7600","0.4688","0.0982","0.0009","0.3721","2.5157","0.4645"
"3.8000","0.4730","0.1014","-0.0001","0.3762","2.5965","0.4697"
"3.8400","0.4766","0.1045","-0.0026","0.3799","2.6758","0.4743"
"3.8800","0.4808","0.1075","0.0023","0.3841","2.7534","0.4795"
"3.9200","0.4851","0.1109","-0.0031","0.3883","2.8410","0.4848"
"3.9600","0.4887","0.1143","0.0018","0.3919","2.9279","0.4893"
"4.0000","0.4927","0.1173","-0.0024","0.3959","3.0045","0.4943"
"4.0400","0.4969","0.1207","0.0009","0.4001","3.0930","0.4995"
"4.0800","0.5007","0.1242","0.0011","0.4040","3.1804","0.5044"
"4.1200","0.5047","0.1273","-0.0034","0.4079","3.2618","0.5093"
"4.1600","0.5089","0.1308","0.0003","0.4121","3.3516","0.5145"
"4.2000","0.5128","0.1342","0.0005","0.4161","3.4374","0.5195"
"4.2400","0.5168","0.1375","-0.0008","0.4201","3.5230","0.5244"
"4.2800","0.5207","0.1408","0.0018","0.4239","3.6063","0.5293"
"4.3200","0.5246","0.1440","-0.0047","0.4279","3.6891","0.5342"
"4.3600","0.5288","0.1474","0.0024","0.4320","3.7764","0.5394"
"4.4000","0.5325","0.1508","-0.0010","0.4358","3.8624","0.5441"
"4.4400","0.5367","0.1540","0.0017","0.4400","3.9458","0.5493"
"4.4800","0.5410","0.1576","-0.0017","0.4443","4.0367","0.5547"
"4.5200","0.5448","0.1612","-0.0028","0.4481","4.1285","0.5594"
"4.5600","0.5489","0.1643","0.0019","0.4521","4.2074","0.5645"
"4.6000","0.5530","0.1676","-0.0003","0.4562","4.2937","0.5696"
"4.6400","0.5568","0.1711","0.0001","0.4600","4.3834","0.5744"
"4.6800","0.5607","0.1743","-0.0007","0.4640","4.4645","0.5793"
"4.7200","0.5648","0.1778","-0.0014","0.4681","4.5530","0.5844"
"4.7600","0.5688","0.1811","0.0020","0.4720","4.6389","0.5893"
"4.8000","0.5729","0.1845","-0.0022","0.4762","4.7259","0.5945"
"4.8400","0.5767","0.1877","0.0005","0.4799","4.8089","0.5992"
"4.8800","0.5807","0.1910","-0.0009","0.4839","4.8913","0.6042"
"4.9200","0.5849","0.1944","-0.0001","0.4881","4.9799","0.6094"
"4.9600","0.5887","0.1977","0.0016","0.4919","5.0631","0.6141"
"5.0000","0.5928","0.2011","-0.0024","0.4960","5.1503","0.6193"
"5.0400","0.5970","0.2046","0.0001","0.5003","5.2399","0.6246"
"5.0800","0.6008","0.2079","0.0004","0.5041","5.3244","0.6293"
"5.1200","0.6047","0.2109","0.0004","0.5079","5.4018","0.6342"
"5.1600","0.6088","0.2143","0.0007","0.5121","5.4897","0.6393"
"5.2000","0.6127","0.2175","-0.0020","0.5159","5.5717","0.6441"
"5.2400","0.6165","0.2207","0.0013","0.5198","5.6544","0.6489"
"5.2800","0.6208","0.2241","0.0004","0.5240","5.7392","0.6543"
"5.3200","0.6248","0.2275","0.0011","0.5281","5.8265","0.6593"
"5.3600","0.6289","0.2309","-0.0010","0.5322","5.9150","0.6644"
"5.4000","0.6328","0.2341","-0.0015","0.5361","5.9969","0.6693"
"5.4400","0.6368","0.2373","0.0017","0.5400","6.0776","0.6742"
"5.4800","0.6409","0.2407","0.0007","0.5441","6.1644","0.6793"
"5.5200","0.6446","0.2440","0.0006","0.5478","6.2504","0.6839"
"5.5600","0.6487","0.2471","-0.0017","0.5519","6.3286","0.6891"
"5.6000","0.6529","0.2506","-0.0004","0.5561","6.4181","0.6943"
"5.6400","0.6568","0.2539","0.0013","0.5600","6.5047","0.6992"
"5.6800","0.6607","0.2570","0.0008","0.5640","6.5832","0.7041"
"5.7200","0.6649","0.2603","-0.0005","0.5681","6.6684","0.7093"
"5.7600","0.6688","0.2636","-0.0012","0.5720","6.7528","0.7142"
"5.8000","0.6727","0.2670","-0.0006","0.5759","6.8389","0.7190"
"5.8400","0.6769","0.2704","0.0027","0.5801","6.9253","0.7243"
"5.8800","0.6808","0.2736","-0.0016","0.5841","7.0091","0.7292"
"5.9200","0.6849","0.2770","0.0002","0.5882","7.0954","0.7343"
"5.9600","0.6887","0.2803","-0.0020","0.5920","7.1790","0.7391"
"6.0000","0.6926","0.2834","0.0027","0.5959","7.2599","0.7439"
"6.0400","0.6968","0.2867","-0.0010","0.6000","7.3428","0.7491"
"6.0800","0.7005","0.2901","-0.0001","0.6038","7.4299","0.7538"
"6.1200","0.7046","0.2933","-0.0006","0.6079","7.5136","0.7589"
"6.1600","0.7090","0.2968","-0.0007","0.6122","7.6013","0.7644"
"6.2000","0.7129","0.3002","0.0015","0.6162","7.6899","0.7693"
"6.2400","0.7168","0.3033","-0.0015","0.6200","7.7691","0.7741"
"6.2800","0.7209","0.3066","0.0000","0.6242","7.8525","0.7793"
"6.3200","0.7248","0.3100","-0.0003","0.6281","7.9401","0.7841"
"6.3600","0.7286","0.3132","0.0011","0.6319","8.0216","0.7889"
"6.4000","0.7328","0.3164","-0.0004","0.6361","8.1039","0.7942"
"6.4400","0.7368","0.3197","-0.0024","0.6401","8.1903","0.7991"
"6.4800","0.7409","0.3231","0.0000","0.6442","8.2758","0.8042"
"6.5200","0.7447","0.3262","0.0012","0.6480","8.3546","0.8090"
"6.5600","0.7487","0.3295","0.0005","0.6520","8.4396","0.8140"
"6.6000","0.7528","0.3328","-0.0001","0.6561","8.5253","0.8191"
"6.6400","0.7566","0.3361","-0.0024","0.6599","8.6091","0.8239"
"6.6800","0.7607","0.3392","0.0010","0.6639","8.6879","0.8289"
"6.7200","0.7649","0.3426","-0.0001","0.6682","8.7758","0.8342"
"6.7600","0.7688","0.3459","0.0008","0.6721","8.8614","0.8391"
"6.8000","0.7726","0.3491","-0.0008","0.6759","8.9426","0.8438"
"6.8400","0.7768","0.3523","-0.0015","0.6800","9.0251","0.8490"
"6.8800","0.7807","0.3556","0.0017","0.6839","9.1092","0.8539"
"6.9200","0.7846","0.3588","-0.0004","0.6878","9.1895","0.8588"
"6.9600","0.7888","0.3621","0.0001","0.6921","9.2758","0.8641"
"7.0000","0.7929","0.3655","-0.0010","0.6961","9.3618","0.8691"
"7.0400","0.7971","0.3688","0.0001","0.7004","9.4478","0.8744"
"7.0800","0.8009","0.3722","0.0015","0.7042","9.5331","0.8792"
"7.1200","0.8048","0.3752","-0.0019","0.7081","9.6113","0.8840"
"7.1600","0.8090","0.3785","0.0015","0.7122","9.6950","0.8892"
"7.2000","0.8127","0.3818","-0.0010","0.7160","9.7805","0.8939"
"7.2400","0.8167","0.3848","0.0019","0.7199","9.8565","0.8988"
"7.2800","0.8210","0.3882","-0.0010","0.7243","9.9430","0.9042"
"7.3200","0.8249","0.3915","-0.0008","0.7281","10.0275","0.9091"
"7.3600","0.8286","0.3945","-0.0001","0.7319","10.1061","0.9137"
"7.4000","0.8328","0.3978","0.0018","0.7361","10.1885","0.9190"
"7.4400","0.8368","0.4011","0.0014","0.7400","10.2735","0.9239"
"7.4800","0.8406","0.4041","-0.0010","0.7438","10.3513","0.9287"
"7.5200","0.8448","0.4073","-0.0023","0.7481","10.4322","0.9340"
"7.5600","0.8488","0.4105","0.0023","0.7521","10.5153","0.9389"
"7.6000","0.8529","0.4137","0.0001","0.7561","10.5964","0.9440"
"7.6400","0.8567","0.4163","0.0015","0.7599","10.6647","0.9488"
"7.6800","0.8607","0.4194","-0.0011","0.7639","10.7420","0.9537"
"7.7200","0.8647","0.4226","-0.0006","0.7680","10.8253","0.9588"
"7.7600","0.8686","0.4259","0.0030","0.7718","10.9082","0.9636"
"7.8000","0.8726","0.4289","-0.0015","0.7759","10.9852","0.9687"
"7.8400","0.8769","0.4322","0.0022","0.7802","11.0717","0.9740"
"7.8800","0.8809","0.4357","-0.0036","0.7842","11.1605","0.9791"
"7.9200","0.8848","0.4386","0.0036","0.7880","11.2345","0.9838"
"7.9600","0.8889","0.4418","0.0004","0.7922","11.3175","0.9890"
"8.0000","0.8928","0.4452","0.0002","0.7960","11.4028","0.9938"
"8.0400","0.8966","0.4482","-0.0005","0.7999","11.4801","0.9986"
"8.0800","0.9008","0.4513","-0.0007","0.8040","11.5595","1.0038"
"8.1200","0.9048","0.4546","0.0017","0.8080","11.6439","1.0088"
"8.1600","0.9090","0.4579","0.0013","0.8122","11.7292","1.0140"
"8.2000","0.9128","0.4610","-0.0011","0.8160","11.8094","1.0188"
"8.2400","0.9167","0.4642","0.0018","0.8199","11.8892","1.0236"
"8.2800","0.9208","0.4673","-0.0020","0.8241","11.9690","1.0289"
"8.3200","0.9247","0.4706","0.0031","0.8280","12.0541","1.0337"
"8.3600","0.9286","0.4737","-0.0009","0.8319","12.1333","1.0386"
"8.4000","0.9329","0.4769","-0.0010","0.8362","12.2145","1.0440"
"8.4400","0.9370","0.4803","0.0033","0.8402","12.3038","1.0490"
"8.4800","0.9406","0.4834","-0.0024","0.8439","12.3815","1.0536"
"8.5200","0.9448","0.4863","0.0029","0.8480","12.4573","1.0587"
"8.5600","0.9487","0.4896","-0.0024","0.8519","12.5408","1.0636"
"8.6000","0.9525","0.4927","0.0015","0.8558","12.6205","1.0684"
"8.6400","0.9567","0.4957","0.0018","0.8599","12.6978","1.0736"
"8.6800","0.9608","0.4990","-0.0018","0.8640","12.7828","1.0787"
"8.7200","0.9650","0.5024","0.0022","0.8683","12.8678","1.0840"
"8.7600","0.9689","0.5056","-0.0030","0.8721","12.9510","1.0888"
"8.8000","0.9728","0.5086","0.0036","0.8760","13.0267","1.0937"
"8.8400","0.9768","0.5117","0.0007","0.8801","13.1076","1.0988"
"8.8800","0.9807","0.5150","-0.0012","0.8840","13.1923","1.1036"
"8.9200","0.9847","0.5179","0.0004","0.8879","13.2671","1.1086"
"8.9600","0.9889","0.5212","-0.0020","0.8922","13.3515","1.1139"
"9.0000","0.9930","0.5245","0.0029","0.8962","13.4360","1.1189"
"9.0400","0.9966","0.5276","0.0012","0.8999","13.5149","1.1235"
"9.0800","1.0008","0.5305","-0.0017","0.9041","13.5897","1.1287"
"9.1200","1.0048","0.5339","0.0012","0.9080","13.6767","1.1336"
"9.1600","1.0086","0.5369","-0.0021","0.9119","13.7525","1.1385"
"9.2000","1.0128","0.5400","0.0025","0.9161","13.8325","1.1437"
"9.2400","1.0168","0.5433","-0.0001","0.9200","13.9166","1.1486"
"9.2800","1.0209","0.5463","-0.0005","0.9241","13.9928","1.1538"
"9.3200","1.0247","0.5496","0.0017","0.9280","14.0767","1.1586"
"9.3600","1.0286","0.5526","-0.0016","0.9318","14.1547","1.1634"
"9.4000","1.0327","0.5556","0.0026","0.9359","14.2314","1.1685"
"9.4400","1.0366","0.5589","-0.0025","0.9399","14.3157","1.1734"
"9.4800","1.0405","0.5618","0.0012","0.9438","14.3905","1.1783"
"9.5200","1.0449","0.5651","0.0016","0.9481","14.4741","1.1837"
"9.5600","1.0490","0.5685","-0.0004","0.9523","14.5632","1.1889"
"9.6000","1.0527","0.5715","0.0015","0.9560","14.6381","1.1935"
"9.6400","1.0569","0.5744","-0.0033","0.9601","14.7143","1.1987"
"9.6800","1.0608","0.5777","0.0032","0.9641","14.7988","1.2037"
"9.7200","1.0646","0.5807","-0.0006","0.9679","14.8741","1.2084"
"9.7600","1.0688","0.5838","0.0012","0.9720","14.9541","1.2135"
"9.8000","1.0728","0.5869","-0.0009","0.9761","15.0343","1.2186"
"9.8400","1.0769","0.5902","-0.0001","0.9802","15.1171","1.2237"
"9.8800","1.0807","0.5933","0.0009","0.9840","15.1973","1.2285"
"9.9200","1.0846","0.5962","0.0010","0.9879","15.2710","1.2334"
"9.9600","1.0887","0.5992","-0.0020","0.9920","15.3488","1.2385"
"10.0000","1.0927","0.6024","0.0018","0.9960","15.4314","1.2435"
"10.0400","1.0966","0.6055","-0.0014","0.9999","15.5106","1.2483"
"10.0800","1.1009","0.6086","0.0040","1.0041","15.5896","1.2536"
"10.1200","1.1050","0.6117","-0.0031","1.0082","15.6697","1.2587"
"10.1600","1.1086","0.6148","-0.0003","1.0119","15.7490","1.2633"
"10.2000","1.1128","0.6178","0.0008","1.0160","15.8236","1.2685"
"10.2400","1.1168","0.6210","-0.0004","1.0200","15.9065","1.2735"
"10.2800","1.1206","0.6240","0.0027","1.0239","15.9846","1.2783"
"10.3200","1.1247","0.6270","-0.0035","1.0280","16.0606","1.2834"
"10.3600","1.1288","0.6303","0.0017","1.0321","16.1458","1.2886"
"10.4000","1.1330","0.6334","-0.0002","1.0363","16.2234","1.2938"
"10.4400","1.1370","0.6365","0.0011","1.0403","16.3050","1.2987"
"10.4800","1.1408","0.6395","0.0013","1.0441","16.3811","1.3035"
"10.5200","1.1449","0.6425","-0.0034","1.0481","16.4575","1.3086"
"10.5600","1.1488","0.6456","0.0029","1.0521","16.5378","1.3135"
"10.6000","1.1526","0.6486","-0.0009","1.0558","16.6133","1.3182"
"10.6400","1.1569","0.6517","0.0005","1.0601","16.6934","1.3236"
"10.6800","1.1610","0.6549","-0.0001","1.0643","16.7748","1.3288"
"10.7200","1.1647","0.6579","-0.0004","1.0679","16.8519","1.3333"
"10.7600","1.1688","0.6609","0.0019","1.0721","16.9289","1.3385"
"10.8000","1.1728","0.6640","-0.0006","1.0761","17.0094","1.3435"
"10.8400","1.1767","0.6669","-0.0017","1.0799","17.0831","1.3483"
"10.8800","1.1808","0.6699","0.0008","1.0841","17.1597","1.3534"
"10.9200","1.1849","0.6731","0.0001","1.0882","17.2411","1.3586"
"10.9600","1.1889","0.6762","0.0037","1.0922","17.3214","1.3636"
"11.0000","1.1928","0.6793","-0.0026","1.0961","17.3994","1.3684"
"11.0400","1.1967","0.6822","-0.0004","1.1000","17.4751","1.3733"
"11.0800","1.2007","0.6852","0.0004","1.1039","17.5502","1.3783"
"11.1200","1.2047","0.6883","0.0007","1.1080","17.6294","1.3833"
"11.1600","1.2086","0.6911","0.0032","1.1118","17.7032","1.3881"
"11.2000","1.2128","0.6942","-0.0040","1.1161","17.7822","1.3934"
"11.2400","1.2170","0.6974","0.0010","1.1203","17.8645","1.3987"
"11.2800","1.2207","0.7003","-0.0003","1.1240","17.9382","1.4033"
"11.3200","1.2249","0.7032","0.0027","1.1281","18.0135","1.4085"
"11.3600","1.2288","0.7063","-0.0005","1.1321","18.0920","1.4134"
"11.4000","1.2327","0.7093","-0.0011","1.1360","18.1681","1.4182"
"11.4400","1.2367","0.7122","0.0000","1.1400","18.2440","1.4232"
"11.4800","1.2408","0.7152","0.0011","1.1440","18.3187","1.4283"
"11.5200","1.2449","0.7181","0.0004","1.1481","18.3945","1.4334"
"11.5600","1.2488","0.7210","0.0002","1.1521","18.4681","1.4384"
"11.6000","1.2527","0.7237","-0.0004","1.1559","18.5385","1.4432"
"11.6400","1.2567","0.7266","0.0011","1.1600","18.6117","1.4482"
"11.6800","1.2609","0.7297","0.0004","1.1641","18.6918","1.4534"
"11.7200","1.2646","0.7325","-0.0011","1.1679","18.7628","1.4581"
"11.7600","1.2688","0.7355","0.0000","1.1720","18.8385","1.4633"
"11.8000","1.2730","0.7386","0.0013","1.1763","18.9203","1.4686"
"11.8400","1.2766","0.7415","0.0014","1.1799","18.9941","1.4730"
"11.8800","1.2806","0.7442","-0.0007","1.1839","19.0636","1.4781"
"11.9200","1.2847","0.7474","-0.0018","1.1880","19.1451","1.4832"
"11.9600","1.2886","0.7503","0.0001","1.1918","19.2183","1.4880"
"12.0000","1.2925","0.7532","0.0013","1.1958","19.2918","1.4929"
"12.0400","1.2968","0.7562","0.0020","1.2000","19.3691","1.4982"
"12.0800","1.3009","0.7593","-0.0011","1.2042","19.4501","1.5034"
"12.1200","1.3049","0.7624","-0.0006","1.2081","19.5296","1.5083"
"12.1600","1.3088","0.7652","-0.0010","1.2121","19.6013","1.5132"
"12.2000","1.3128","0.7681","0.0027","1.2161","19.6756","1.5183"
"12.2400","1.3168","0.7710","-0.0013","1.2201","19.7496","1.5233"
"12.2800","1.3206","0.7740","0.0008","1.2238","19.8247","1.5279"
"12.3200","1.3248","0.7769","-0.0009","1.2280","19.8999","1.5332"
"12.3600","1.3289","0.7799","0.0015","1.2322","19.9780","1.5384"
"12.4000","1.3326","0.7829","0.0001","1.2359","20.0536","1.5430"
"12.4400","1.3367","0.7857","-0.0006","1.2400","20.1264","1.5481"
"12.4800","1.3407","0.7887","0.0001","1.2440","20.2026","1.5531"
"12.5200","1.3447","0.7916","0.0013","1.2479","20.2767","1.5581"
"12.5600","1.3487","0.7945","0.0001","1.2520","20.3509","1.5631"
"12.6000","1.3528","0.7975","0.0013","1.2561","20.4265","1.5682"
"12.6400","1.3568","0.8004","-0.0030","1.2600","20.5014","1.5732"
"12.6800","1.3608","0.8034","0.0032","1.2641","20.5788","1.5782"
"12.7200","1.3646","0.8062","-0.0007","1.2679","20.6505","1.5829"
"12.7600","1.3686","0.8090","0.0014","1.2718","20.7220","1.5879"
"12.8000","1.3728","0.8119","-0.0009","1.2760","20.7974","1.5931"
"12.8400","1.3765","0.8148","-0.0009","1.2797","20.8721","1.5977"
"12.8800","1.3806","0.8177","0.0025","1.2839","20.9458","1.6029"
"12.9200","1.3850","0.8208","-0.0024","1.2882","21.0242","1.6083"
"12.9600","1.3887","0.8238","0.0009","1.2920","21.1006","1.6130"
"13.0000","1.3927","0.8264","-0.0018","1.2960","21.1692","1.6180"
"13.0400","1.3969","0.8294","0.0013","1.3001","21.2453","1.6232"
"13.0800","1.4007","0.8324","0.0015","1.3040","21.3224","1.6280"
"13.1200","1.4046","0.8351","-0.0023","1.3079","21.3913","1.6329"
"13.1600","1.4088","0.8381","0.0004","1.3121","21.4669","1.6381"
"13.2000","1.4128","0.8409","-0.0010","1.3161","21.5395","1.6431"
"13.2400","1.4168","0.8438","0.0019","1.3201","21.6140","1.6481"
"13.2800","1.4207","0.8467","0.0008","1.3240","21.6870","1.6530"
"13.3200","1.4247","0.8495","-0.0032","1.3280","21.7593","1.6579"
"13.3600","1.4288","0.8524","0.0016","1.3321","21.8334","1.6631"
"13.4000","1.4326","0.8552","-0.0010","1.3359","21.9047","1.6678"
"13.4400","1.4368","0.8581","0.0031","1.3400","21.9793","1.6730"
"13.4800","1.4409","0.8610","-0.0026","1.3442","22.0542","1.6782"
"13.5200","1.4447","0.8638","-0.0002","1.3479","22.1269","1.6829"
"13.5600","1.4487","0.8665","-0.0001","1.3519","22.1947","1.6879"
"13.6000","1.4528","0.8693","0.0007","1.3560","22.2682","1.6930"
"13.6400","1.4567","0.8724","0.0001","1.3599","22.3452","1.6979"
"13.6800","1.4606","0.8750","-0.0004","1.3638","22.4119","1.7028"
"13.7200","1.4648","0.8779","-0.0021","1.3680","22.4873","1.7080"
"13.7600","1.4688","0.8808","0.0032","1.3721","22.5606","1.7130"
"13.8000","1.4730","0.8839","-0.0031","1.3763","22.6405","1.7182"
"13.8400","1.4769","0.8866","0.0022","1.3801","22.7108","1.7231"
"13.8800","1.4808","0.8894","-0.0033","1.3841","22.7812","1.7280"
"13.9200","1.4850","0.8922","0.0036","1.3882","22.8526","1.7332"
"13.9600","1.4886","0.8949","-0.0003","1.3919","22.9228","1.7378"
"14.0000","1.4928","0.8978","-0.0011","1.3960","22.9959","1.7429"
"14.0400","1.4970","0.9006","-0.0003","1.4003","23.0698","1.7483"
"14.0800","1.5008","0.9036","-0.0011","1.4040","23.1452","1.7529"
"14.1200","1.5047","0.9060","0.0018","1.4079","23.2061","1.7578"
"14.1600","1.5089","0.9088","0.0005","1.4121","23.2799","1.7630"
"14.2000","1.5128","0.9118","-0.0013","1.4160","23.3548","1.7679"
"14.2400","1.5166","0.9144","0.0008","1.4199","23.4230","1.7727"
"14.2800","1.5208","0.9172","-0.0007","1.4241","23.4949","1.7780"
"14.3200","1.5249","0.9201","0.0019","1.4281","23.5689","1.7830"
"14.3600","1.5289","0.9230","-0.0015","1.4321","23.6415","1.7880"
"14.4000","1.5328","0.9258","-0.0015","1.4360","23.7133","1.7928"
"14.4400","1.5367","0.9284","0.0037","1.4400","23.7814","1.7978"
"14.4800","1.5409","0.9312","-0.0027","1.4441","23.8524","1.8030"
"14.5200","1.5446","0.9339","0.0031","1.4478","23.9205","1.8076"
"14.5600","1.5487","0.9365","-0.0041","1.4520","23.9889","1.8128"
"14.6000","1.5530","0.9395","0.0010","1.4562","24.0649","1.8181"
"14.6400","1.5569","0.9424","0.0012","1.4601","24.1399","1.8229"
"14.6800","1.5609","0.9450","-0.0006","1.4641","24.2064","1.8279"
"14.7200","1.5650","0.9478","0.0019","1.4682","24.2776","1.8330"
"14.7600","1.5688","0.9504","-0.0032","1.4720","24.3446","1.8378"
"14.8000","1.5727","0.9531","0.0024","1.4759","24.4127","1.8427"
"14.8400","1.5768","0.9558","0.0004","1.4801","24.4814","1.8479"
"14.8800","1.5807","0.9586","-0.0015","1.4840","24.5545","1.8528"
"14.9200","1.5849","0.9614","0.0019","1.4882","24.6248","1.8580"
"14.9600","1.5887","0.9641","-0.0025","1.4920","24.6952","1.8627"
"15.0000","1.5927","0.9666","0.0032","1.4959","24.7592","1.8677"
"15.0400","1.5969","0.9693","-0.0008","1.5002","24.8295","1.8730"
"15.0800","1.6007","0.9720","0.0002","1.5039","24.8980","1.8777"
"15.1200","1.6047","0.9746","0.0013","1.5080","24.9636","1.8827"
"15.1600","1.6090","0.9773","-0.0010","1.5123","25.0327","1.8880"
"15.2000","1.6129","0.9799","0.0022","1.5161","25.0991","1.8929"
"15.2400","1.6166","0.9822","-0.0016","1.5199","25.1594","1.8976"
"15.2800","1.6208","0.9848","0.0003","1.5241","25.2255","1.9028"
"15.3200","1.6247","0.9876","0.0027","1.5280","25.2975","1.9077"
"15.3600","1.6285","0.9902","-0.0010","1.5318","25.3626","1.9124"
"15.4000","1.6328","0.9928","0.0012","1.5360","25.4294","1.9177"
"15.4400","1.6368","0.9955","-0.0025","1.5401","25.5000","1.9227"
"15.4800","1.6409","0.9984","0.0018","1.5442","25.5745","1.9279"
"15.5200","1.6448","1.0009","0.0021","1.5481","25.6380","1.9328"
"15.5600","1.6488","1.0035","-0.0001","1.5520","25.7049","1.9377"
"15.6000","1.6528","1.0061","0.0002","1.5561","25.7716","1.9428"
"15.6400","1.6566","1.0088","-0.0025","1.5599","25.8404","1.9475"
"15.6800","1.6607","1.0112","0.0022","1.5639","25.9028","1.9525"
"15.7200","1.6649","1.0140","0.0014","1.5682","25.9745","1.9578"
"15.7600","1.6688","1.0168","-0.0005","1.5721","26.0441","1.9627"
"15.8000","1.6726","1.0192","0.0003","1.5759","26.1077","1.9675"
"15.8400","1.6768","1.0219","-0.0007","1.5801","26.1756","1.9727"
"15.8800","1.6807","1.0245","0.0032","1.5840","26.2426","1.9776"
"15.9200","1.6846","1.0271","-0.0014","1.5879","26.3091","1.9825"
"15.9600","1.6888","1.0298","-0.0003","1.5921","26.3775","1.9877"
"16.0000","1.6928","1.0324","-0.0005","1.5960","26.4435","1.9926"
"16.0400","1.6969","1.0350","0.0023","1.6002","26.5112","1.9978"
"16.0800","1.7007","1.0375","0.0012","1.6040","26.5743","2.0025"
"16.1200","1.7046","1.0399","-0.0009","1.6078","26.6358","2.0074"
"16.1600","1.7088","1.0426","-0.0007","1.6120","26.7052","2.0126"
"16.2000","1.7125","1.0452","0.0010","1.6158","26.7719","2.0173"
"16.2400","1.7166","1.0476","0.0016","1.6198","26.8347","2.0223"
"16.2800","1.7209","1.0503","0.0008","1.6242","26.9021","2.0278"
"16.3200","1.7249","1.0531","-0.0012","1.6282","26.9754","2.0328"
"16.3600","1.7288","1.0554","0.0006","1.6320","27.0346","2.0375"
"16.4000","1.7329","1.0580","0.0007","1.6362","27.1014","2.0428"
"16.4400","1.7368","1.0606","0.0019","1.6400","27.1674","2.0476"
"16.4800","1.7406","1.0630","-0.0018","1.6438","27.2287","2.0523"
"16.5200","1.7448","1.0656","0.0006","1.6480","27.2946","2.0576"
"16.5600","1.7488","1.0682","0.0012","1.6521","27.3620","2.0626"
"16.6000","1.7530","1.0708","0.0008","1.6562","27.4284","2.0678"
"16.6400","1.7567","1.0732","0.0001","1.6600","27.4904","2.0725"
"16.6800","1.7606","1.0756","-0.0004","1.6639","27.5517","2.0774"
"16.7200","1.7648","1.0781","0.0002","1.6681","27.6147","2.0826"
"16.7600","1.7687","1.0808","0.0023","1.6719","27.6834","2.0874"
"16.8000","1.7726","1.0831","-0.0002","1.6759","27.7432","2.0923"
"16.8400","1.7769","1.0857","-0.0001","1.6802","27.8087","2.0977"
"16.8800","1.7809","1.0883","-0.0014","1.6842","27.8772","2.1026"
"16.9200","1.7846","1.0905","0.0027","1.6879","27.9329","2.1073"
"16.9600","1.7888","1.0928","0.0011","1.6921","27.9929","2.1126"
"17.0000","1.7928","1.0956","-0.0004","1.6960","28.0626","2.1175"
"17.0400","1.7966","1.0979","-0.0005","1.6998","28.1221","2.1222"
"17.0800","1.8008","1.1004","-0.0010","1.7041","28.1852","2.1275"
"17.1200","1.8048","1.1030","0.0025","1.7081","28.2522","2.1325"
"17.1600","1.8091","1.1056","0.0000","1.7123","28.3189","2.1378"
"17.2000","1.8130","1.1080","0.0003","1.7162","28.3806","2.1427"
"17.2400","1.8168","1.1104","0.0004","1.7201","28.4419","2.1475"
"17.2800","1.8209","1.1127","0.0003","1.7242","28.5018","2.1526"
"17.3200","1.8247","1.1151","0.0012","1.7280","28.5620","2.1574"
"17.3600","1.8287","1.1174","-0.0022","1.7319","28.6217","2.1623"
"17.4000","1.8330","1.1199","0.0017","1.7362","28.6853","2.1676"
"17.4400","1.8370","1.1224","0.0004","1.7402","28.7512","2.1727"
"17.4800","1.8406","1.1246","0.0020","1.7439","28.8065","2.1772"
"17.5200","1.8449","1.1270","-0.0006","1.7481","28.8688","2.1825"
"17.5600","1.8488","1.1294","-0.0022","1.7520","28.9294","2.1874"
"17.6000","1.8526","1.1318","0.0013","1.7559","28.9910","2.1922"
"17.6400","1.8569","1.1341","0.0014","1.7601","29.0497","2.1975"
"17.6800","1.8608","1.1365","0.0013","1.7641","29.1123","2.2024"
"17.7200","1.8649","1.1389","-0.0009","1.7682","29.1730","2.2076"
"17.7600","1.8688","1.1413","-0.0017","1.7720","29.2333","2.2124"
"17.8000","1.8727","1.1436","0.0033","1.7759","29.2930","2.2172"
"17.8400","1.8768","1.1460","-0.0007","1.7800","29.3554","2.2224"
"17.8800","1.8806","1.1483","0.0016","1.7839","29.4132","2.2272"
"17.9200","1.8846","1.1504","-0.0018","1.7878","29.4681","2.2321"
"17.9600","1.8889","1.1529","0.0006","1.7921","29.5302","2.2375"
"18.0000","1.8930","1.1554","0.0018","1.7962","29.5955","2.2426"
"18.0400","1.8967","1.1577","-0.0005","1.8000","29.6531","2.2472"
"18.0800","1.9009","1.1597","0.0007","1.8042","29.7057","2.2525"
"18.1200","1.9048","1.1623","-0.0011","1.8080","29.7709","2.2573"
"18.1600","1.9086","1.1644","0.0016","1.8119","29.8247","2.2621"
"18.2000","1.9128","1.1666","0.0023","1.8161","29.8827","2.2673"
"18.2400","1.9168","1.1689","-0.0035","1.8201","29.9419","2.2723"
"18.2800","1.9210","1.1713","0.0032","1.8242","30.0032","2.2775"
"18.3200","1.9248","1.1735","-0.0023","1.8281","30.0595","2.2823"
"18.3600","1.9286","1.1756","0.0041","1.8319","30.1128","2.2871"
"18.4000","1.9328","1.1779","-0.0016","1.8360","30.1706","2.2923"
"18.4400","1.9368","1.1803","0.0000","1.8400","30.2320","2.2972"
"18.4800","1.9406","1.1823","0.0012","1.8439","30.2843","2.3020"
"18.5200","1.9449","1.1845","0.0001","1.8481","30.3408","2.3074"
"18.5600","1.9490","1.1869","0.0012","1.8523","30.4013","2.3125"
"18.6000","1.9526","1.1891","-0.0001","1.8558","30.4576","2.3170"
"18.6400","1.9567","1.1911","-0.0016","1.8600","30.5091","2.3222"
"18.6800","1.9607","1.1934","0.0045","1.8640","30.5678","2.3272"
"18.7200","1.9645","1.1955","-0.0025","1.8678","30.6214","2.3319"
"18.7600","1.9686","1.1973","0.0019","1.8719","30.6692","2.3370"
"18.8000","1.9728","1.1994","-0.0024","1.8761","30.7224","2.3422"
"18.8400","1.9770","1.2015","0.0017","1.8802","30.7758","2.3474"
"18.8800","1.9809","1.2038","0.0031","1.8841","30.8345","2.3523"
"18.9200","1.9848","1.2058","-0.0020","1.8881","30.8854","2.3573"
"18.9600","1.9888","1.2079","0.0012","1.8921","30.9409","2.3623"
"19.0000","1.9927","1.2100","-0.0021","1.8960","30.9927","2.3671"
"19.0400","1.9966","1.2119","0.0026","1.8999","31.0424","2.3720"
"19.0800","2.0009","1.2141","0.0018","1.9041","31.0987","2.3773"
"19.1200","2.0049","1.2163","-0.0021","1.9082","31.1540","2.3824"
"19.1600","2.0086","1.2184","0.0021","1.9119","31.2082","2.3870"
"19.2000","2.0128","1.2204","-0.0013","1.9160","31.2608","2.3922"
"19.2400","2.0167","1.2225","0.0027","1.9200","31.3138","2.3971"
"19.2800","2.0207","1.2246","0.0002","1.9239","31.3677","2.4020"
"19.3200","2.0248","1.2266","-0.0022","1.9281","31.4198","2.4072"
"19.3600","2.0288","1.2287","0.0031","1.9321","31.4727","2.4122"
"19.4000","2.0329","1.2307","-0.0019","1.9362","31.5232","2.4173"
"19.4400","2.0368","1.2328","0.0031","1.9401","31.5771","2.4222"
"19.4800","2.0406","1.2347","-0.0021","1.9439","31.6259","2.4269"
"19.5200","2.0447","1.2366","0.0005","1.9479","31.6753","2.4320"
"19.5600","2.0487","1.2386","0.0016","1.9520","31.7269","2.4370"
"19.6000","2.0525","1.2405","-0.0007","1.9557","31.7761","2.4417"
"19.6400","2.0568","1.2424","0.0005","1.9600","31.8248","2.4471"
"19.6800","2.0610","1.2447","-0.0010","1.9643","31.8825","2.4524"
"19.7200","2.0647","1.2468","0.0017","1.9680","31.9353","2.4570"
"19.7600","2.0688","1.2485","0.0027","1.9720","31.9809","2.4621"
"19.8000","2.0728","1.2506","-0.0018","1.9761","32.0331","2.4671"
"19.8400","2.0766","1.2525","0.0002","1.9799","32.0829","2.4719"
"19.8800","2.0807","1.2543","-0.0018","1.9839","32.1278","2.4769"
"19.9200","2.0848","1.2563","0.0036","1.9880","32.1801","2.4820"
"19.9600","2.0889","1.2582","0.0012","1.9921","32.2291","2.4872"
"20.0000","2.0927","1.2602","-0.0015","1.9960","32.2795","2.4920"
"20.0400","2.0967","1.2619","0.0005","1.9999","32.3225","2.4969"
"20.0800","2.1008","1.2637","-0.0011","2.0040","32.3694","2.5020"
"20.1200","2.1048","1.2657","0.0036","2.0081","32.4216","2.5071"
"20.1600","2.1087","1.2674","-0.0007","2.0119","32.4636","2.5119"
"20.2000","2.1129","1.2693","0.0000","2.0162","32.5120","2.5172"
"20.2400","2.1170","1.2714","0.0012","2.0203","32.5656","2.5223"
"20.2800","2.1207","1.2731","0.0002","2.0239","32.6103","2.5268"
"20.3200","2.1248","1.2748","0.0015","2.0281","32.6535","2.5320"
"20.3600","2.1288","1.2765","-0.0026","2.0320","32.6984","2.5370"
"20.4000","2.1327","1.2783","0.0007","2.0359","32.7440","2.5418"
"20.4400","2.1367","1.2799","0.0020","2.0399","32.7849","2.5469"
"20.4800","2.1408","1.2819","0.0007","2.0441","32.8345","2.5520"
"20.5200","2.1449","1.2836","0.0009","2.0482","32.8800","2.5571"
"20.5600","2.1489","1.2856","-0.0033","2.0522","32.9299","2.5622"
"20.6000","2.1528","1.2872","0.0024","2.0560","32.9711","2.5669"
"20.6400","2.1568","1.2888","0.0006","2.0601","33.0114","2.5720"
"20.6800","2.1609","1.2905","0.0006","2.0641","33.0564","2.5770"
"20.7200","2.1646","1.2922","0.0001","2.0679","33.0995","2.5817"
"20.7600","2.1688","1.2937","-0.0014","2.0721","33.1382","2.5870"
"20.8000","2.1731","1.2956","0.0034","2.0763","33.1863","2.5922"
"20.8400","2.1767","1.2972","-0.0004","2.0799","33.2267","2.5968"
"20.8800","2.1808","1.2987","-0.0001","2.0840","33.2653","2.6019"
"20.9200","2.1848","1.3004","0.0003","2.0881","33.3097","2.6070"
"20.9600","2.1887","1.3019","0.0007","2.0920","33.3478","2.6118"
"21.0000","2.1927","1.3035","0.0021","2.0960","33.3881","2.6168"
"21.0400","2.1968","1.3051","-0.0014","2.1001","33.4303","2.6219"
"21.0800","2.2008","1.3066","-0.0010","2.1041","33.4692","2.6269"
"21.1200","2.2048","1.3083","0.0017","2.1080","33.5124","2.6318"
"21.1600","2.2086","1.3097","0.0008","2.1119","33.5484","2.6367"
"21.2000","2.2127","1.3112","0.0023","2.1159","33.5857","2.6417"
"21.2400","2.2168","1.3128","-0.0029","2.1200","33.6276","2.6469"
"21.2800","2.2205","1.3142","0.0012","2.1238","33.6625","2.6515"
"21.3200","2.2248","1.3155","0.0005","2.1280","33.6970","2.6568"
"21.3600","2.2290","1.3172","0.0019","2.1323","33.7390","2.6621"
"21.4000","2.2328","1.3187","0.0000","2.1360","33.7790","2.6668"
"21.4400","2.2369","1.3200","-0.0013","2.1401","33.8118","2.6719"
"21.4800","2.2409","1.3215","0.0010","2.1441","33.8489","2.6769"
"21.5200","2.2448","1.3228","0.0011","2.1481","33.8839","2.6818"
"21.5600","2.2488","1.3241","0.0009","2.1520","33.9177","2.6868"
"21.6000","2.2528","1.3255","-0.0001","2.1561","33.9528","2.6918"
"21.6400","2.2568","1.3269","0.0003","2.1601","33.9870","2.6968"
"21.6800","2.2608","1.3281","0.0015","2.1640","34.0188","2.7018"
"21.7200","2.2646","1.3292","0.0010","2.1679","34.0475","2.7066"
"21.7600","2.2686","1.3305","-0.0018","2.1719","34.0812","2.7116"
"21.8000","2.2729","1.3318","0.0004","2.1761","34.1135","2.7169"
"21.8400","2.2766","1.3329","0.0007","2.1798","34.1407","2.7215"
"21.8800","2.2807","1.3341","0.0032","2.1840","34.1714","2.7267"
"21.9200","2.2850","1.3354","-0.0014","2.1882","34.2061","2.7320"
"21.9600","2.2887","1.3366","0.0008","2.1920","34.2376","2.7366"
"22.0000","2.2927","1.3375","-0.0023","2.1960","34.2585","2.7416"
"22.0400","2.2968","1.3387","0.0040","2.2001","34.2914","2.7467"
"22.0800","2.3007","1.3396","0.0003","2.2039","34.3143","2.7516"
"22.1200","2.3046","1.3405","0.0008","2.2078","34.3368","2.7564"
"22.1600","2.3088","1.3416","-0.0013","2.2121","34.3646","2.7617"
"22.2000","2.3129","1.3426","0.0005","2.2161","34.3914","2.7668"
"22.2400","2.3169","1.3436","0.0018","2.2202","34.4169","2.7718"
"22.2800","2.3208","1.3445","-0.0007","2.2241","34.4384","2.7767"
"22.3200","2.3248","1.3450","0.0012","2.2280","34.4528","2.7817"
"22.3600","2.3288","1.3460","-0.0004","2.2321","34.4773","2.7867"
"22.4000","2.3326","1.3465","0.0013","2.2358","34.4915","2.7914"
"22.4400","2.3368","1.3473","0.0009","2.2400","34.5107","2.7966"
"22.4800","2.3409","1.3481","-0.0009","2.2442","34.5308","2.8019"
"22.5200","2.3447","1.3488","0.0010","2.2480","34.5482","2.8066"
"22.5600","2.3487","1.3492","0.0014","2.2520","34.5583","2.8116"
"22.6000","2.3528","1.3497","0.0002","2.2561","34.5732","2.8167"
"22.6400","2.3568","1.3502","0.0015","2.2600","34.5838","2.8216"
"22.6800","2.3607","1.3505","-0.0022","2.2640","34.5931","2.8265"
"22.7200","2.3648","1.3508","0.0040","2.2680","34.6011","2.8316"
"22.7600","2.3688","1.3512","-0.0012","2.2720","34.6098","2.8366"
"22.8000","2.3729","1.3514","0.0015","2.2762","34.6163","2.8418"
"22.8400","2.3767","1.3515","-0.0010","2.2799","34.6190","2.8465"
"22.8800","2.3806","1.3513","0.0006","2.2839","34.6129","2.8514"
"22.9200","2.3849","1.3514","0.0024","2.2881","34.6151","2.8567"
"22.9600","2.3885","1.3515","0.0010","2.2917","34.6185","2.8612"
"23.0000","2.3926","1.3513","-0.0014","2.2959","34.6132","2.8664"
"23.0400","2.3970","1.3513","0.0014","2.3002","34.6144","2.8718"
"23.0800","2.4008","1.3512","-0.0016","2.3041","34.6118","2.8766"
"23.1200","2.4048","1.3506","0.0054","2.3081","34.5956","2.8816"
"23.1600","2.4089","1.3504","-0.0038","2.3122","34.5910","2.8867"
"23.2000","2.4128","1.3499","0.0031","2.3160","34.5777","2.8916"
"23.2400","2.4166","1.3492","-0.0017","2.3199","34.5597","2.8964"
"23.2800","2.4209","1.3486","0.0034","2.3241","34.5440","2.9016"
"23.3200","2.4248","1.3481","0.0000","2.3281","34.5324","2.9066"
"23.3600","2.4289","1.3473","-0.0014","2.3321","34.5112","2.9116"
"23.4000","2.4328","1.3464","0.0001","2.3360","34.4886","2.9165"
"23.4400","2.4367","1.3456","0.0019","2.3400","34.4663","2.9214"
"23.4800","2.4409","1.3445","0.0016","2.3442","34.4403","2.9267"
"23.5200","2.4447","1.3435","0.0017","2.3479","34.4145","2.9314"
"23.5600","2.4487","1.3424","-0.0026","2.3520","34.3857","2.9364"
"23.6000","2.4530","1.3414","0.0024","2.3562","34.3595","2.9417"
"23.6400","2.4568","1.3402","-0.0007","2.3600","34.3292","2.9465"
"23.6800","2.4607","1.3388","0.0018","2.3639","34.2941","2.9514"
"23.7200","2.4648","1.3375","0.0002","2.3681","34.2588","2.9565"
"23.7600","2.4687","1.3361","-0.0003","2.3720","34.2246","2.9614"
"23.8000","2.4726","1.3348","0.0035","2.3758","34.1901","2.9662"
"23.8400","2.4768","1.3334","-0.0025","2.3800","34.1541","2.9714"
"23.8800","2.4808","1.3319","0.0011","2.3841","34.1172","2.9765"
"23.9200","2.4850","1.3306","-0.0015","2.3883","34.0833","2.9817"
"23.9600","2.4889","1.3290","0.0030","2.3921","34.0415","2.9865"
"24.0000","2.4928","1.3275","0.0021","2.3961","34.0024","2.9915"
"24.0400","2.4970","1.3259","-0.0013","2.4002","33.9617","2.9967"
"24.0800","2.5007","1.3242","-0.0002","2.4039","33.9189","3.0013"
"24.1200","2.5047","1.3226","-0.0001","2.4080","33.8789","3.0063"
"24.1600","2.5090","1.3211","0.0022","2.4123","33.8386","3.0117"
"24.2000","2.5129","1.3196","0.0026","2.4161","33.8023","3.0165"
"24.2400","2.5167","1.3178","-0.0034","2.4200","33.7550","3.0213"
"24.2800","2.5209","1.3162","0.0015","2.4242","33.7153","3.0265"
"24.3200","2.5248","1.3148","-0.0008","2.4281","33.6780","3.0314"
"24.3600","2.5287","1.3130","0.0032","2.4319","33.6314","3.0362"
"24.4000","2.5329","1.3115","0.0008","2.4361","33.5947","3.0415"
"24.4400","2.5368","1.3101","-0.0023","2.4401","33.5591","3.0464"
"24.4800","2.5409","1.3085","0.0026","2.4442","33.5161","3.0515"
"24.5200","2.5448","1.3069","-0.0020","2.4480","33.4767","3.0563"
"24.5600","2.5487","1.3053","0.0032","2.4519","33.4347","3.0612"
"24.6000","2.5528","1.3038","-0.0011","2.4561","33.3957","3.0664"
"24.6400","2.5566","1.3023","-0.0001","2.4598","33.3574","3.0710"
"24.6800","2.5606","1.3006","0.0018","2.4639","33.3145","3.0761"
"24.7200","2.5649","1.2992","-0.0016","2.4682","33.2779","3.0815"
"24.7600","2.5689","1.2979","0.0008","2.4721","33.2448","3.0864"
"24.8000","2.5728","1.2961","0.0000","2.4760","33.1989","3.0913"
"24.8400","2.5769","1.2947","0.0003","2.4802","33.1646","3.0965"
"24.8800","2.5808","1.2933","0.0025","2.4840","33.1265","3.1013"
"24.9200","2.5846","1.2916","-0.0039","2.4879","33.0845","3.1061"
"24.9600","2.5888","1.2902","0.0019","2.4921","33.0474","3.1113"
"25.0000","2.5927","1.2888","-0.0014","2.4960","33.0111","3.1162"
"25.0400","2.5970","1.2874","0.0026","2.5002","32.9761","3.1215"
"25.0800","2.6008","1.2858","0.0007","2.5040","32.9350","3.1263"
"25.1200","2.6047","1.2843","-0.0026","2.5079","32.8972","3.1311"
"25.1600","2.6089","1.2829","0.0015","2.5122","32.8621","3.1364"
"25.2000","2.6127","1.2815","-0.0005","2.5160","32.8264","3.1412"
"25.2400","2.6167","1.2800","0.0021","2.5199","32.7863","3.1461"
"25.2800","2.6210","1.2786","-0.0004","2.5242","32.7521","3.1515"
"25.3200","2.6249","1.2773","-0.0023","2.5282","32.7180","3.1564"
"25.3600","2.6286","1.2756","0.0025","2.5319","32.6746","3.1610"
"25.4000","2.6328","1.2742","-0.0006","2.5361","32.6392","3.1663"
"25.4400","2.6367","1.2729","0.0027","2.5400","32.6039","3.1712"
"25.4800","2.6405","1.2713","-0.0014","2.5437","32.5628","3.1758"
"25.5200","2.6447","1.2698","-0.0009","2.5480","32.5268","3.1811"
"25.5600","2.6488","1.2686","0.0023","2.5521","32.4942","3.1862"
"25.6000","2.6530","1.2673","-0.0009","2.5562","32.4605","3.1914"
"25.6400","2.6568","1.2658","0.0013","2.5601","32.4231","3.1962"
"25.6800","2.6608","1.2644","-0.0018","2.5640","32.3882","3.2012"
"25.7200","2.6648","1.2630","0.0010","2.5681","32.3516","3.2062"
"25.7600","2.6686","1.2616","0.0021","2.5719","32.3146","3.2110"
"25.8000","2.6727","1.2600","-0.0012","2.5759","32.2751","3.2160"
"25.8400","2.6769","1.2588","0.0005","2.5801","32.2431","3.2213"
"25.8800","2.6809","1.2575","-0.0010","2.5841","32.2113","3.2263"
"25.9200","2.6847","1.2559","0.0022","2.5879","32.1686","3.2310"
"25.9600","2.6888","1.2545","0.0006","2.5921","32.1327","3.2362"
"26.0000","2.6927","1.2532","-0.0005","2.5960","32.1002","3.2411"
"26.0400","2.6967","1.2518","0.0006","2.5999","32.0640","3.2460"
"26.0800","2.7008","1.2503","0.0005","2.6041","32.0258","3.2511"
"26.1200","2.7048","1.2488","0.0015","2.6080","31.9878","3.2561"
"26.1600","2.7089","1.2474","-0.0003","2.6122","31.9518","3.2613"
"26.2000","2.7127","1.2461","-0.0012","2.6160","31.9182","3.2660"
"26.2400","2.7165","1.2444","0.0020","2.6198","31.8744","3.2708"
"26.2800","2.7207","1.2430","0.0009","2.6240","31.8380","3.2760"
"26.3200","2.7246","1.2415","0.0022","2.6279","31.8016","3.2809"
"26.3600","2.7285","1.2397","-0.0028","2.6318","31.7554","3.2858"
"26.4000","2.7329","1.2383","0.0005","2.6362","31.7194","3.2912"
"26.4400","2.7370","1.2371","0.0018","2.6403","31.6877","3.2963"
"26.4800","2.7407","1.2352","0.0019","2.6439","31.6396","3.3009"
"26.5200","2.7449","1.2336","0.0000","2.6481","31.5972","3.3062"
"26.5600","2.7488","1.2321","-0.0009","2.6521","31.5597","3.3111"
"26.6000","2.7526","1.2301","0.0007","2.6559","31.5092","3.3158"
"26.6400","2.7568","1.2282","0.0008","2.6601","31.4607","3.3211"
"26.6800","2.7608","1.2265","0.0017","2.6641","31.4169","3.3261"
"26.7200","2.7650","1.2245","-0.0002","2.6682","31.3659","3.3312"
"26.7600","2.7688","1.2225","0.0002","2.6720","31.3144","3.3360"
"26.8000","2.7727","1.2203","0.0019","2.6759","31.2588","3.3409"
"26.8400","2.7768","1.2181","0.0000","2.6800","31.2022","3.3460"
"26.8800","2.7807","1.2157","0.0005","2.6840","31.1402","3.3509"
"26.9200","2.7847","1.2131","-0.0007","2.6879","31.0737","3.3559"
"26.9600","2.7889","1.2106","0.0019","2.6922","31.0090","3.3612"
"27.0000","2.7930","1.2078","0.0019","2.6962","30.9365","3.3662"
"27.0400","2.7967","1.2045","-0.0008","2.6999","30.8532","3.3708"
"27.0800","2.8008","1.2010","0.0002","2.7041","30.7622","3.3760"
"27.1200","2.8047","1.1971","-0.0001","2.7080","30.6622","3.3809"
"27.1600","2.8086","1.1923","0.0022","2.7119","30.5415","3.3857"
"27.2000","2.8128","1.1867","0.0018","2.7160","30.3971","3.3909"
"27.2400","2.8169","1.1800","-0.0024","2.7201","30.2245","3.3960"
"27.2800","2.8211","1.1710","0.0027","2.7243","29.9936","3.4013"
"27.3200","2.8250","1.1584","-0.0017","2.7282","29.6723","3.4061"
"27.3600","2.8288","1.1392","0.0046","2.7320","29.1815","3.4109"
"27.4000","2.8329","1.1074","-0.0028","2.7361","28.3649","3.4160"
"27.4400","2.8369","1.0452","0.0010","2.7401","26.7719","3.4210"
"27.4800","2.8408","0.8981","0.0003","2.7441","23.0042","3.4260"
"27.5150","2.8453","0.2659","-0.0025","2.7485","6.8097","3.4315"