File: Datasets/HCS.is_tens_Exports/HCS_1_1.csv
Time,Displacement,Force,Strain 1,Tensile displacement,Tensile stress,Tensile strain (Displacement)
(s),(mm),(kN),(%),(mm),(MPa),(%)
"0.0000","0.0356","-0.0003","0.0044","-0.0004","-0.0086","-0.0005"
"0.3000","0.0628","0.0349","-0.0002","0.0267","0.8946","0.0334"
"0.6000","0.0924","0.0710","-0.0032","0.0564","1.8174","0.0704"
"0.9000","0.1223","0.1086","0.0015","0.0862","2.7814","0.1077"
"1.2000","0.1519","0.1619","0.0015","0.1158","4.1446","0.1447"
"1.5000","0.1819","0.2534","0.0035","0.1459","6.4886","0.1823"
"1.8000","0.2119","0.4345","-0.0006","0.1759","11.1248","0.2198"
"2.1000","0.2417","0.7493","-0.0015","0.2057","19.1820","0.2570"
"2.4000","0.2718","1.2028","0.0025","0.2358","30.7939","0.2946"
"2.7000","0.3018","1.7009","0.0014","0.2658","43.5468","0.3321"
"3.0000","0.3317","2.2266","0.0045","0.2957","57.0042","0.3695"
"3.3000","0.3616","2.7824","-0.0048","0.3256","71.2334","0.4068"
"3.6000","0.3915","3.3415","-0.0010","0.3555","85.5476","0.4442"
"3.9000","0.4216","3.9012","-0.0029","0.3856","99.8767","0.4818"
"4.2000","0.4517","4.4489","0.0013","0.4157","113.8982","0.5194"
"4.5000","0.4817","4.9799","-0.0013","0.4457","127.4943","0.5569"
"4.8000","0.5119","5.5044","-0.0032","0.4758","140.9216","0.5945"
"5.1000","0.5420","6.0221","-0.0043","0.5060","154.1757","0.6322"
"5.4000","0.5720","6.5253","-0.0040","0.5359","167.0588","0.6696"
"5.7000","0.6016","7.0182","-0.0033","0.5656","179.6780","0.7066"
"6.0000","0.6318","7.4991","0.0012","0.5958","191.9898","0.7444"
"6.3000","0.6617","7.9623","0.0036","0.6257","203.8468","0.7818"
"6.6000","0.6916","8.4188","-0.0037","0.6556","215.5359","0.8191"
"6.9000","0.7220","8.8635","0.0017","0.6859","226.9211","0.8571"
"7.2000","0.7519","9.2818","-0.0026","0.7159","237.6289","0.8945"
"7.5000","0.7818","9.6821","0.0028","0.7458","247.8775","0.9318"
"7.8000","0.8118","10.0361","0.0016","0.7758","256.9408","0.9693"
"8.1000","0.8415","10.3138","0.0011","0.8054","264.0501","1.0063"
"8.4000","0.8717","10.5959","-0.0010","0.8356","271.2731","1.0441"
"8.7000","0.9019","10.8694","0.0008","0.8658","278.2741","1.0818"
"9.0000","0.9320","11.1250","0.0010","0.8960","284.8174","1.1195"
"9.3000","0.9620","11.3725","0.0003","0.9260","291.1552","1.1570"
"9.6000","0.9922","11.6004","0.0007","0.9561","296.9884","1.1946"
"9.9000","1.0220","11.8072","-0.0033","0.9859","302.2829","1.2319"
"10.2000","1.0517","11.9941","-0.0021","1.0157","307.0699","1.2690"
"10.5000","1.0818","12.1555","-0.0036","1.0458","311.2018","1.3066"
"10.8000","1.1119","12.3016","-0.0002","1.0759","314.9411","1.3442"
"11.1000","1.1419","12.4378","-0.0018","1.1059","318.4278","1.3817"
"11.4000","1.1722","12.5610","-0.0027","1.1361","321.5816","1.4195"
"11.7000","1.2020","12.6636","-0.0032","1.1659","324.2090","1.4568"
"12.0000","1.2320","12.7607","-0.0026","1.1960","326.6949","1.4943"
"12.3000","1.2618","12.8482","-0.0006","1.2258","328.9361","1.5316"
"12.6000","1.2914","12.9172","0.0003","1.2554","330.7019","1.5685"
"12.9000","1.3217","12.9903","-0.0004","1.2857","332.5728","1.6064"
"13.2000","1.3519","13.0614","0.0006","1.3159","334.3924","1.6441"
"13.5000","1.3820","13.1245","-0.0017","1.3460","336.0090","1.6817"
"13.8000","1.4121","13.1877","-0.0017","1.3761","337.6259","1.7193"
"14.1000","1.4423","13.2488","0.0047","1.4063","339.1912","1.7570"
"14.4000","1.4721","13.3022","0.0014","1.4361","340.5593","1.7943"
"14.7000","1.5016","13.3473","0.0023","1.4655","341.7131","1.8311"
"15.0000","1.5319","13.3969","-0.0035","1.4958","342.9827","1.8690"
"15.3000","1.5621","13.4450","-0.0038","1.5261","344.2133","1.9067"
"15.6000","1.5919","13.4927","-0.0001","1.5558","345.4350","1.9439"
"15.9000","1.6221","13.5437","0.0016","1.5861","346.7404","1.9817"
"16.2000","1.6521","13.5891","-0.0043","1.6161","347.9022","2.0192"
"16.5000","1.6820","13.6342","-0.0019","1.6460","349.0577","2.0565"
"16.8000","1.7118","13.6775","-0.0023","1.6757","350.1668","2.0937"
"17.1000","1.7417","13.7127","-0.0007","1.7057","351.0680","2.1311"
"17.4000","1.7718","13.7559","0.0030","1.7358","352.1744","2.1687"
"17.7000","1.8019","13.7982","0.0017","1.7659","353.2577","2.2064"
"18.0000","1.8321","13.8398","0.0010","1.7961","354.3204","2.2441"
"18.3000","1.8621","13.8860","-0.0024","1.8261","355.5052","2.2816"
"18.6000","1.8923","13.9279","-0.0013","1.8562","356.5766","2.3192"
"18.9000","1.9222","13.9633","0.0003","1.8861","357.4838","2.3566"
"19.2000","1.9517","13.9973","0.0027","1.9156","358.3549","2.3935"
"19.5000","1.9820","14.0346","0.0025","1.9459","359.3091","2.4313"
"19.8000","2.0119","14.0678","-0.0016","1.9759","360.1579","2.4688"
"20.1000","2.0418","14.1053","0.0007","2.0058","361.1193","2.5061"
"20.4000","2.0722","14.1502","0.0015","2.0362","362.2677","2.5441"
"20.7000","2.1021","14.1840","0.0000","2.0661","363.1336","2.5815"
"21.0000","2.1319","14.2181","0.0032","2.0959","364.0067","2.6187"
"21.3000","2.1619","14.2541","-0.0002","2.1258","364.9280","2.6561"
"21.6000","2.1916","14.2829","-0.0040","2.1556","365.6668","2.6933"
"21.9000","2.2217","14.3161","-0.0030","2.1856","366.5147","2.7308"
"22.2000","2.2520","14.3547","-0.0034","2.2160","367.5029","2.7687"
"22.5000","2.2821","14.3890","-0.0009","2.2461","368.3832","2.8063"
"22.8000","2.3121","14.4276","0.0011","2.2761","369.3712","2.8438"
"23.1000","2.3422","14.4611","-0.0005","2.3062","370.2284","2.8815"
"23.4000","2.3721","14.4935","0.0013","2.3361","371.0578","2.9188"
"23.7000","2.4017","14.5215","-0.0025","2.3657","371.7754","2.9558"
"24.0000","2.4319","14.5493","0.0021","2.3959","372.4863","2.9935"
"24.3000","2.4619","14.5794","0.0023","2.4259","373.2563","3.0310"
"24.6000","2.4920","14.6132","0.0045","2.4560","374.1227","3.0686"
"24.9000","2.5221","14.6484","0.0018","2.4861","375.0223","3.1062"
"25.2000","2.5520","14.6776","-0.0011","2.5160","375.7714","3.1436"
"25.5000","2.5820","14.7093","0.0008","2.5460","376.5821","3.1811"
"25.8000","2.6119","14.7406","0.0008","2.5759","377.3843","3.2184"
"26.1000","2.6415","14.7604","0.0010","2.6055","377.8905","3.2554"
"26.4000","2.6718","14.7903","-0.0009","2.6358","378.6559","3.2932"
"26.7000","2.7019","14.8240","-0.0031","2.6659","379.5193","3.3309"
"27.0000","2.7320","14.8524","-0.0040","2.6960","380.2461","3.3685"
"27.3000","2.7621","14.8862","-0.0007","2.7261","381.1120","3.4061"
"27.6000","2.7923","14.9158","-0.0019","2.7563","381.8701","3.4438"
"27.9000","2.8222","14.9450","0.0000","2.7862","382.6172","3.4812"
"28.2000","2.8516","14.9630","-0.0025","2.8155","383.0785","3.5178"
"28.5000","2.8819","14.9895","-0.0021","2.8458","383.7557","3.5557"
"28.8000","2.9121","15.0170","0.0002","2.8761","384.4591","3.5935"
"29.1000","2.9419","15.0433","0.0026","2.9059","385.1342","3.6307"
"29.4000","2.9721","15.0747","0.0032","2.9361","385.9359","3.6685"
"29.7000","3.0021","15.1002","0.0009","2.9661","386.5890","3.7059"
"30.0000","3.0320","15.1273","0.0019","2.9960","387.2833","3.7433"
"30.3000","3.0617","15.1521","0.0009","3.0257","387.9176","3.7804"
"30.6000","3.0916","15.1701","0.0039","3.0556","388.3799","3.8178"
"30.9000","3.1219","15.1973","-0.0009","3.0859","389.0766","3.8556"
"31.2000","3.1519","15.2236","0.0011","3.1159","389.7487","3.8931"
"31.5000","3.1822","15.2489","-0.0026","3.1461","390.3958","3.9309"
"31.8000","3.2122","15.2785","-0.0044","3.1761","391.1553","3.9684"
"32.1000","3.2423","15.3061","-0.0029","3.2063","391.8613","4.0060"
"32.4000","3.2720","15.3255","0.0004","3.2360","392.3578","4.0432"
"32.7000","3.3017","15.3460","0.0014","3.2657","392.8821","4.0802"
"33.0000","3.3319","15.3683","-0.0009","3.2959","393.4547","4.1180"
"33.3000","3.3619","15.3870","-0.0014","3.3259","393.9316","4.1555"
"33.6000","3.3917","15.4121","-0.0037","3.3557","394.5743","4.1927"
"33.9000","3.4223","15.4446","0.0029","3.3863","395.4070","4.2310"
"34.2000","3.4521","15.4618","0.0014","3.4161","395.8464","4.2682"
"34.5000","3.4820","15.4841","-0.0022","3.4459","396.4173","4.3055"
"34.8000","3.5119","15.5071","0.0008","3.4758","397.0078","4.3428"
"35.1000","3.5417","15.5218","-0.0010","3.5057","397.3829","4.3801"
"35.4000","3.5716","15.5420","-0.0013","3.5356","397.9003","4.4175"
"35.7000","3.6019","15.5678","0.0009","3.5659","398.5609","4.4554"
"36.0000","3.6322","15.5909","0.0012","3.5961","399.1525","4.4931"
"36.3000","3.6621","15.6157","-0.0010","3.6261","399.7879","4.5306"
"36.6000","3.6922","15.6371","0.0013","3.6562","400.3363","4.5681"
"36.9000","3.7221","15.6570","-0.0036","3.6860","400.8460","4.6055"
"37.2000","3.7517","15.6748","-0.0022","3.7157","401.3009","4.6425"
"37.5000","3.7819","15.6890","-0.0033","3.7458","401.6637","4.6802"
"37.8000","3.8120","15.7084","-0.0013","3.7760","402.1600","4.7178"
"38.1000","3.8420","15.7313","0.0005","3.8060","402.7479","4.7553"
"38.4000","3.8722","15.7561","-0.0015","3.8362","403.3817","4.7931"
"38.7000","3.9020","15.7719","-0.0002","3.8660","403.7856","4.8303"
"39.0000","3.9321","15.7936","-0.0034","3.8960","404.3414","4.8679"
"39.3000","3.9619","15.8133","-0.0001","3.9258","404.8454","4.9051"
"39.6000","3.9915","15.8224","0.0012","3.9555","405.0781","4.9421"
"39.9000","4.0218","15.8425","0.0031","3.9857","405.5948","4.9799"
"40.2000","4.0519","15.8632","0.0040","4.0159","406.1240","5.0176"
"40.5000","4.0822","15.8851","0.0023","4.0461","406.6855","5.0554"
"40.8000","4.1122","15.9056","-0.0020","4.0761","407.2104","5.0929"
"41.1000","4.1423","15.9259","0.0007","4.1062","407.7285","5.1305"
"41.4000","4.1722","15.9436","0.0009","4.1362","408.1813","5.1679"
"41.7000","4.2016","15.9543","0.0010","4.1656","408.4554","5.2046"
"42.0000","4.2319","15.9686","-0.0003","4.1959","408.8217","5.2425"
"42.3000","4.2620","15.9864","-0.0018","4.2260","409.2788","5.2801"
"42.6000","4.2919","16.0027","-0.0028","4.2558","409.6963","5.3174"
"42.9000","4.3221","16.0257","-0.0039","4.2861","410.2840","5.3552"
"43.2000","4.3522","16.0423","-0.0012","4.3161","410.7097","5.3927"
"43.5000","4.3820","16.0596","-0.0015","4.3460","411.1514","5.4300"
"43.8000","4.4117","16.0739","0.0019","4.3757","411.5180","5.4671"
"44.1000","4.4417","16.0846","-0.0024","4.4057","411.7931","5.5046"
"44.4000","4.4719","16.1018","0.0014","4.4358","412.2325","5.5423"
"44.7000","4.5019","16.1189","0.0001","4.4659","412.6711","5.5798"
"45.0000","4.5321","16.1363","0.0046","4.4961","413.1156","5.6176"
"45.3000","4.5622","16.1574","0.0015","4.5262","413.6547","5.6552"
"45.6000","4.5923","16.1762","0.0031","4.5563","414.1362","5.6928"
"45.9000","4.6221","16.1878","0.0007","4.5861","414.4351","5.7301"
"46.2000","4.6517","16.1980","-0.0004","4.6157","414.6948","5.7670"
"46.5000","4.6820","16.2125","0.0025","4.6459","415.0655","5.8048"
"46.8000","4.7118","16.2222","0.0031","4.6757","415.3142","5.8420"
"47.1000","4.7418","16.2410","0.0027","4.7058","415.7964","5.8796"
"47.4000","4.7723","16.2630","-0.0020","4.7363","416.3591","5.9177"
"47.7000","4.8022","16.2750","-0.0018","4.7661","416.6655","5.9550"
"48.0000","4.8319","16.2881","-0.0001","4.7959","417.0020","5.9921"
"48.3000","4.8619","16.3024","-0.0007","4.8258","417.3687","6.0296"
"48.6000","4.8917","16.3102","-0.0023","4.8557","417.5673","6.0669"
"48.9000","4.9217","16.3236","-0.0007","4.8856","417.9113","6.1043"
"49.2000","4.9520","16.3421","-0.0018","4.9160","418.3840","6.1422"
"49.5000","4.9822","16.3567","0.0003","4.9462","418.7577","6.1799"
"49.8000","5.0121","16.3756","0.0008","4.9761","419.2434","6.2173"
"50.1000","5.0421","16.3878","0.0016","5.0061","419.5551","6.2548"
"50.4000","5.0720","16.4017","0.0028","5.0359","419.9105","6.2921"
"50.7000","5.1018","16.4133","-0.0008","5.0658","420.2083","6.3294"
"51.0000","5.1319","16.4193","-0.0004","5.0959","420.3609","6.3670"
"51.3000","5.1620","16.4317","0.0004","5.1260","420.6788","6.4046"
"51.6000","5.1920","16.4478","0.0034","5.1560","421.0902","6.4421"
"51.9000","5.2223","16.4655","0.0004","5.1862","421.5435","6.4799"
"52.2000","5.2520","16.4748","-0.0002","5.2160","421.7828","6.5171"
"52.5000","5.2820","16.4894","-0.0028","5.2460","422.1554","6.5546"
"52.8000","5.3119","16.5022","-0.0025","5.2758","422.4824","6.5918"
"53.1000","5.3414","16.5046","-0.0013","5.3054","422.5452","6.6288"
"53.4000","5.3718","16.5181","0.0001","5.3358","422.8901","6.6668"
"53.7000","5.4019","16.5365","0.0008","5.3659","423.3614","6.7043"
"54.0000","5.4323","16.5502","-0.0027","5.3962","423.7124","6.7422"
"54.3000","5.4622","16.5634","-0.0007","5.4262","424.0510","6.7797"
"54.6000","5.4924","16.5766","-0.0010","5.4563","424.3887","6.8173"
"54.9000","5.5221","16.5883","0.0031","5.4861","424.6879","6.8545"
"55.2000","5.5517","16.5921","0.0021","5.5156","424.7845","6.8914"
"55.5000","5.5819","16.6016","0.0010","5.5458","425.0273","6.9292"
"55.8000","5.6120","16.6126","-0.0007","5.5760","425.3089","6.9669"
"56.1000","5.6419","16.6248","-0.0007","5.6058","425.6210","7.0042"
"56.4000","5.6722","16.6408","0.0010","5.6361","426.0309","7.0420"
"56.7000","5.7021","16.6509","0.0011","5.6661","426.2913","7.0794"
"57.0000","5.7320","16.6636","0.0014","5.6960","426.6158","7.1168"
"57.3000","5.7616","16.6724","-0.0020","5.7256","426.8414","7.1538"
"57.6000","5.7916","16.6762","-0.0024","5.7556","426.9372","7.1912"
"57.9000","5.8219","16.6878","-0.0029","5.7858","427.2354","7.2290"
"58.2000","5.8519","16.7005","-0.0002","5.8158","427.5591","7.2665"
"58.5000","5.8822","16.7125","0.0002","5.8462","427.8665","7.3044"
"58.8000","5.9122","16.7273","-0.0012","5.8762","428.2469","7.3419"
"59.1000","5.9423","16.7404","-0.0019","5.9062","428.5809","7.3795"
"59.4000","5.9721","16.7471","-0.0021","5.9361","428.7521","7.4167"
"59.7000","6.0016","16.7518","0.0012","5.9656","428.8746","7.4536"
"60.0000","6.0319","16.7607","0.0009","5.9958","429.1021","7.4914"
"60.3000","6.0619","16.7688","0.0024","6.0259","429.3094","7.5289"
"60.6000","6.0919","16.7802","-0.0003","6.0559","429.6005","7.5664"
"60.9000","6.1223","16.7965","0.0010","6.0863","430.0184","7.6044"
"61.2000","6.1522","16.8044","-0.0008","6.1162","430.2200","7.6417"
"61.5000","6.1819","16.8125","0.0019","6.1459","430.4284","7.6789"
"61.8000","6.2119","16.8226","0.0003","6.1759","430.6867","7.7164"
"62.1000","6.2417","16.8244","0.0012","6.2057","430.7318","7.7536"
"62.4000","6.2717","16.8331","-0.0017","6.2356","430.9552","7.7910"
"62.7000","6.3020","16.8462","-0.0037","6.2660","431.2892","7.8290"
"63.0000","6.3322","16.8569","-0.0038","6.2962","431.5643","7.8667"
"63.3000","6.3621","16.8701","-0.0031","6.3261","431.9019","7.9041"
"63.6000","6.3922","16.8804","0.0018","6.3562","432.1662","7.9417"
"63.9000","6.4220","16.8875","-0.0003","6.3860","432.3484","7.9789"
"64.2000","6.4517","16.8937","-0.0006","6.4157","432.5070","8.0160"
"64.5000","6.4820","16.8967","-0.0032","6.4459","432.5841","8.0538"
"64.8000","6.5120","16.9040","0.0019","6.4759","432.7698","8.0913"
"65.1000","6.5420","16.9152","-0.0004","6.5060","433.0575","8.1288"
"65.4000","6.5722","16.9289","0.0046","6.5362","433.4071","8.1665"
"65.7000","6.6021","16.9340","-0.0010","6.5660","433.5372","8.2038"
"66.0000","6.6320","16.9450","0.0004","6.5960","433.8185","8.2413"
"66.3000","6.6618","16.9525","0.0005","6.6258","434.0118","8.2785"
"66.6000","6.6915","16.9520","-0.0005","6.6554","433.9978","8.3155"
"66.9000","6.7217","16.9600","0.0012","6.6856","434.2038","8.3533"
"67.2000","6.7520","16.9729","0.0012","6.7159","434.5338","8.3912"
"67.5000","6.7821","16.9818","-0.0025","6.7461","434.7607","8.4288"
"67.8000","6.8123","16.9945","-0.0029","6.7762","435.0866","8.4665"
"68.1000","6.8423","17.0042","-0.0018","6.8063","435.3365","8.5040"
"68.4000","6.8722","17.0118","-0.0007","6.8362","435.5305","8.5414"
"68.7000","6.9017","17.0113","0.0020","6.8656","435.5167","8.5782"
"69.0000","6.9319","17.0166","-0.0002","6.8959","435.6525","8.6160"
"69.3000","6.9620","17.0235","0.0017","6.9260","435.8302","8.6536"
"69.6000","6.9919","17.0312","0.0009","6.9559","436.0264","8.6909"
"69.9000","7.0221","17.0429","0.0003","6.9860","436.3269","8.7286"
"70.2000","7.0520","17.0493","0.0004","7.0160","436.4891","8.7661"
"70.5000","7.0821","17.0593","0.0029","7.0461","436.7448","8.8036"
"70.8000","7.1117","17.0636","0.0001","7.0757","436.8569","8.8406"
"71.1000","7.1417","17.0646","0.0004","7.1056","436.8821","8.8780"
"71.4000","7.1719","17.0726","-0.0039","7.1359","437.0874","8.9158"
"71.7000","7.2019","17.0820","-0.0031","7.1659","437.3284","8.9533"
"72.0000","7.2323","17.0905","0.0011","7.1962","437.5457","8.9912"
"72.3000","7.2622","17.1029","-0.0026","7.2262","437.8625","9.0286"
"72.6000","7.2923","17.1112","-0.0007","7.2563","438.0758","9.0662"
"72.9000","7.3221","17.1147","-0.0012","7.2861","438.1651","9.1035"
"73.2000","7.3517","17.1165","-0.0005","7.3156","438.2097","9.1404"
"73.5000","7.3818","17.1215","-0.0017","7.3458","438.3384","9.1781"
"73.8000","7.4121","17.1302","0.0032","7.3761","438.5618","9.2159"
"74.1000","7.4419","17.1334","0.0023","7.4058","438.6425","9.2531"
"74.4000","7.4723","17.1479","0.0013","7.4363","439.0148","9.2912"
"74.7000","7.5022","17.1510","-0.0001","7.4661","439.0946","9.3285"
"75.0000","7.5319","17.1564","-0.0008","7.4959","439.2310","9.3657"
"75.3000","7.5619","17.1639","0.0011","7.5259","439.4228","9.4031"
"75.6000","7.5916","17.1623","0.0027","7.5556","439.3842","9.4402"
"75.9000","7.6218","17.1686","0.0016","7.5857","439.5439","9.4779"
"76.2000","7.6520","17.1783","0.0001","7.6160","439.7933","9.5157"
"76.5000","7.6823","17.1853","-0.0017","7.6462","439.9717","9.5535"
"76.8000","7.7121","17.1907","0.0000","7.6760","440.1096","9.5907"
"77.1000","7.7423","17.1966","-0.0022","7.7063","440.2617","9.6285"
"77.4000","7.7721","17.2033","-0.0003","7.7360","440.4315","9.6657"
"77.7000","7.8017","17.2091","-0.0035","7.7657","440.5801","9.7028"
"78.0000","7.8319","17.2100","-0.0012","7.7959","440.6037","9.7404"
"78.3000","7.8620","17.2141","-0.0022","7.8260","440.7086","9.7781"
"78.6000","7.8920","17.2237","-0.0028","7.8560","440.9552","9.8156"
"78.9000","7.9223","17.2339","0.0018","7.8862","441.2168","9.8534"
"79.2000","7.9520","17.2351","0.0012","7.9159","441.2479","9.8905"
"79.5000","7.9821","17.2436","0.0014","7.9460","441.4636","9.9281"
"79.8000","8.0118","17.2486","-0.0011","7.9758","441.5926","9.9652"
"80.1000","8.0415","17.2445","0.0005","8.0054","441.4875","10.0023"
"80.4000","8.0717","17.2509","-0.0001","8.0357","441.6523","10.0401"
"80.7000","8.1020","17.2598","0.0034","8.0659","441.8796","10.0779"
"81.0000","8.1320","17.2658","0.0017","8.0960","442.0335","10.1154"
"81.3000","8.1622","17.2758","-0.0001","8.1262","442.2883","10.1531"
"81.6000","8.1923","17.2834","0.0004","8.1563","442.4846","10.1908"
"81.9000","8.2221","17.2872","0.0013","8.1861","442.5811","10.2280"
"82.2000","8.2516","17.2856","0.0007","8.2156","442.5406","10.2649"
"82.5000","8.2819","17.2879","-0.0009","8.2458","442.5990","10.3027"
"82.8000","8.3121","17.2934","-0.0026","8.2760","442.7389","10.3404"
"83.1000","8.3419","17.2978","-0.0032","8.3058","442.8510","10.3776"
"83.4000","8.3721","17.3080","-0.0026","8.3361","443.1124","10.4154"
"83.7000","8.4022","17.3133","-0.0017","8.3662","443.2488","10.4530"
"84.0000","8.4319","17.3181","-0.0003","8.3959","443.3714","10.4902"
"84.3000","8.4618","17.3230","-0.0011","8.4258","443.4969","10.5275"
"84.6000","8.4917","17.3193","-0.0018","8.4557","443.4015","10.5648"
"84.9000","8.5219","17.3244","-0.0023","8.4858","443.5339","10.6025"
"85.2000","8.5519","17.3308","-0.0010","8.5159","443.6978","10.6401"
"85.5000","8.5822","17.3374","0.0014","8.5462","443.8647","10.6779"
"85.8000","8.6122","17.3464","0.0023","8.5762","444.0967","10.7154"
"86.1000","8.6423","17.3537","0.0013","8.6062","444.2834","10.7530"
"86.4000","8.6721","17.3538","0.0004","8.6361","444.2849","10.7902"
"86.7000","8.7016","17.3526","0.0013","8.6656","444.2539","10.8271"
"87.0000","8.7319","17.3448","0.0017","8.6959","444.0563","10.8650"
"87.3000","8.7620","17.3553","0.0021","8.7259","444.3234","10.9025"
"87.6000","8.7918","17.3627","0.0035","8.7558","444.5137","10.9398"
"87.9000","8.8222","17.3747","-0.0022","8.7862","444.8199","10.9778"
"88.2000","8.8522","17.3776","-0.0041","8.8162","444.8957","11.0152"
"88.5000","8.8819","17.3791","-0.0051","8.8459","444.9339","11.0524"
"88.8000","8.9119","17.3837","-0.0004","8.8758","445.0524","11.0898"
"89.1000","8.9418","17.3825","0.0001","8.9057","445.0195","11.1272"
"89.4000","8.9716","17.3843","-0.0010","8.9356","445.0671","11.1645"
"89.7000","9.0020","17.3930","-0.0015","8.9660","445.2884","11.2024"
"90.0000","9.0322","17.3978","-0.0019","8.9962","445.4111","11.2401"
"90.3000","9.0621","17.4051","0.0012","9.0260","445.5988","11.2775"
"90.6000","9.0923","17.4110","-0.0002","9.0562","445.7500","11.3152"
"90.9000","9.1222","17.4148","0.0037","9.0862","445.8464","11.3526"
"91.2000","9.1517","17.4142","-0.0020","9.1157","445.8310","11.3894"
"91.5000","9.1819","17.4127","-0.0005","9.1459","445.7926","11.4272"
"91.8000","9.2120","17.4146","-0.0012","9.1759","445.8427","11.4647"
"92.1000","9.2420","17.4215","0.0009","9.2060","446.0189","11.5023"
"92.4000","9.2723","17.4314","0.0042","9.2362","446.2718","11.5401"
"92.7000","9.3020","17.4296","0.0012","9.2659","446.2263","11.5772"
"93.0000","9.3321","17.4367","-0.0003","9.2960","446.4077","11.6148"
"93.3000","9.3619","17.4397","-0.0011","9.3259","446.4842","11.6521"
"93.6000","9.3914","17.4337","-0.0019","9.3554","446.3325","11.6889"
"93.9000","9.4219","17.4412","0.0001","9.3858","446.5238","11.7270"
"94.2000","9.4519","17.4456","-0.0002","9.4159","446.6368","11.7646"
"94.5000","9.4820","17.4492","0.0001","9.4460","446.7269","11.8022"
"94.8000","9.5122","17.4581","-0.0039","9.4762","446.9559","11.8399"
"95.1000","9.5424","17.4627","-0.0014","9.5063","447.0737","11.8776"
"95.4000","9.5722","17.4658","-0.0022","9.5361","447.1533","11.9148"
"95.7000","9.6016","17.4620","0.0020","9.5656","447.0559","11.9516"
"96.0000","9.6318","17.4612","0.0007","9.5958","447.0360","11.9893"
"96.3000","9.6621","17.4664","0.0019","9.6261","447.1685","12.0272"
"96.6000","9.6919","17.4689","-0.0017","9.6559","447.2332","12.0645"
"96.9000","9.7221","17.4765","0.0031","9.6861","447.4283","12.1022"
"97.2000","9.7522","17.4815","-0.0016","9.7161","447.5540","12.1397"
"97.5000","9.7820","17.4841","0.0052","9.7460","447.6218","12.1770"
"97.8000","9.8116","17.4848","0.0029","9.7756","447.6404","12.2140"
"98.1000","9.8417","17.4814","0.0016","9.8056","447.5518","12.2515"
"98.4000","9.8720","17.4860","0.0006","9.8360","447.6711","12.2895"
"98.7000","9.9019","17.4895","-0.0021","9.8659","447.7601","12.3268"
"99.0000","9.9323","17.4943","-0.0007","9.8962","447.8818","12.3647"
"99.3000","9.9622","17.5019","-0.0028","9.9262","448.0775","12.4021"
"99.6000","9.9923","17.5075","0.0011","9.9563","448.2202","12.4398"
"99.9000","10.0220","17.5062","-0.0034","9.9860","448.1877","12.4769"
"100.2000","10.0517","17.5043","0.0002","10.0156","448.1388","12.5139"
"100.5000","10.0819","17.5070","-0.0052","10.0458","448.2068","12.5516"
"100.8000","10.1120","17.5050","0.0030","10.0759","448.1572","12.5892"
"101.1000","10.1418","17.5100","0.0004","10.1058","448.2851","12.6265"
"101.4000","10.1724","17.5225","0.0014","10.1363","448.6045","12.6647"
"101.7000","10.2022","17.5204","0.0010","10.1662","448.5501","12.7020"
"102.0000","10.2320","17.5219","-0.0012","10.1959","448.5899","12.7392"
"102.3000","10.2618","17.5249","0.0035","10.2258","448.6652","12.7765"
"102.6000","10.2917","17.5200","0.0023","10.2556","448.5401","12.8138"
"102.9000","10.3216","17.5213","0.0030","10.2856","448.5735","12.8512"
"103.2000","10.3520","17.5285","0.0012","10.3159","448.7595","12.8891"
"103.5000","10.3822","17.5315","-0.0015","10.3462","448.8352","12.9269"
"103.8000","10.4121","17.5390","0.0007","10.3761","449.0274","12.9642"
"104.1000","10.4422","17.5422","0.0005","10.4062","449.1080","13.0019"
"104.4000","10.4720","17.5421","0.0012","10.4360","449.1076","13.0391"
"104.7000","10.5017","17.5441","-0.0001","10.4657","449.1570","13.0762"
"105.0000","10.5319","17.5400","-0.0023","10.4959","449.0535","13.1139"
"105.3000","10.5620","17.5403","-0.0041","10.5260","449.0609","13.1515"
"105.6000","10.5920","17.5459","-0.0027","10.5560","449.2050","13.1890"
"105.9000","10.6223","17.5531","-0.0017","10.5862","449.3890","13.2268"
"106.2000","10.6520","17.5522","0.0001","10.6160","449.3641","13.2640"
"106.5000","10.6821","17.5568","-0.0001","10.6460","449.4839","13.3015"
"106.8000","10.7119","17.5587","-0.0011","10.6758","449.5305","13.3388"
"107.1000","10.7415","17.5510","-0.0018","10.7054","449.3347","13.3758"
"107.4000","10.7718","17.5545","0.0001","10.7357","449.4241","13.4136"
"107.7000","10.8020","17.5585","0.0027","10.7659","449.5272","13.4514"
"108.0000","10.8321","17.5399","0.0014","10.7960","449.0491","13.4890"
"108.3000","10.8622","17.5659","0.0026","10.8262","449.7155","13.5266"
"108.6000","10.8923","17.5719","0.0006","10.8563","449.8687","13.5642"
"108.9000","10.9222","17.5742","0.0001","10.8861","449.9291","13.6015"
"109.2000","10.9516","17.5697","0.0010","10.9156","449.8140","13.6384"
"109.5000","10.9819","17.5689","0.0021","10.9459","449.7916","13.6762"
"109.8000","11.0120","17.5707","0.0018","10.9760","449.8394","13.7138"
"110.1000","11.0419","17.5718","0.0024","11.0058","449.8665","13.7511"
"110.4000","11.0721","17.5799","-0.0009","11.0361","450.0737","13.7889"
"110.7000","11.1022","17.5811","-0.0021","11.0661","450.1052","13.8264"
"111.0000","11.1320","17.5827","0.0005","11.0959","450.1451","13.8637"
"111.3000","11.1616","17.5827","0.0008","11.1256","450.1471","13.9007"
"111.6000","11.1918","17.5787","-0.0017","11.1557","450.0444","13.9384"
"111.9000","11.2219","17.5808","-0.0012","11.1858","450.0974","13.9760"
"112.2000","11.2519","17.5850","-0.0030","11.2159","450.2047","14.0136"
"112.5000","11.2822","17.5876","-0.0009","11.2462","450.2720","14.0514"
"112.8000","11.3123","17.5946","0.0013","11.2762","450.4493","14.0889"
"113.1000","11.3423","17.5982","0.0001","11.3063","450.5423","14.1265"
"113.4000","11.3721","17.5975","0.0026","11.3361","450.5237","14.1638"
"113.7000","11.4017","17.5934","-0.0013","11.3656","450.4203","14.2007"
"114.0000","11.4320","17.5942","-0.0011","11.3959","450.4411","14.2385"
"114.3000","11.4619","17.5915","0.0017","11.4258","450.3704","14.2759"
"114.6000","11.4918","17.5944","0.0037","11.4557","450.4461","14.3132"
"114.9000","11.5223","17.6048","0.0024","11.4863","450.7129","14.3514"
"115.2000","11.5522","17.6036","0.0021","11.5162","450.6819","14.3887"
"115.5000","11.5819","17.6034","-0.0003","11.5459","450.6760","14.4259"
"115.8000","11.6119","17.6052","0.0004","11.5758","450.7227","14.4633"
"116.1000","11.6417","17.5998","0.0023","11.6057","450.5840","14.5005"
"116.4000","11.6717","17.6001","0.0008","11.6356","450.5906","14.5380"
"116.7000","11.7020","17.6064","0.0038","11.6659","450.7516","14.5759"
"117.0000","11.7322","17.6086","-0.0006","11.6962","450.8097","14.6137"
"117.3000","11.7621","17.6142","-0.0005","11.7261","450.9533","14.6510"
"117.6000","11.7923","17.6159","-0.0002","11.7562","450.9960","14.6887"
"117.9000","11.8221","17.6166","0.0007","11.7860","451.0138","14.7259"
"118.2000","11.8517","17.6151","0.0010","11.8156","450.9755","14.7629"
"118.5000","11.8819","17.6103","-0.0009","11.8458","450.8517","14.8006"
"118.8000","11.9120","17.6111","-0.0021","11.8760","450.8727","14.8383"
"119.1000","11.9420","17.6151","-0.0043","11.9060","450.9756","14.8758"
"119.4000","11.9723","17.6205","-0.0002","11.9362","451.1129","14.9136"
"119.7000","12.0021","17.6191","-0.0027","11.9661","451.0775","14.9508"
"120.0000","12.0320","17.6219","0.0012","11.9960","451.1494","14.9882"
"120.3000","12.0619","17.6236","-0.0006","12.0258","451.1926","15.0255"
"120.6000","12.0914","17.6140","-0.0008","12.0553","450.9474","15.0624"
"120.9000","12.1219","17.6177","-0.0022","12.0859","451.0417","15.1005"
"121.2000","12.1520","17.6215","0.0029","12.1160","451.1386","15.1381"
"121.5000","12.1821","17.6246","0.0010","12.1461","451.2188","15.1757"
"121.8000","12.2122","17.6292","0.0009","12.1762","451.3370","15.2134"
"122.1000","12.2424","17.6317","0.0016","12.2063","451.4009","15.2511"
"122.4000","12.2721","17.6321","-0.0006","12.2361","451.4118","15.2882"
"122.7000","12.3016","17.6261","0.0026","12.2656","451.2572","15.3251"
"123.0000","12.3319","17.6250","0.0031","12.2959","451.2288","15.3629"
"123.3000","12.3620","17.6251","0.0019","12.3260","451.2309","15.4006"
"123.6000","12.3919","17.6262","0.0007","12.3559","451.2592","15.4379"
"123.9000","12.4222","17.6322","-0.0014","12.3861","451.4134","15.4757"
"124.2000","12.4521","17.6332","-0.0019","12.4161","451.4389","15.5131"
"124.5000","12.4820","17.6337","0.0014","12.4460","451.4507","15.5505"
"124.8000","12.5116","17.6339","0.0015","12.4756","451.4577","15.5874"
"125.1000","12.5416","17.6269","-0.0005","12.5056","451.2769","15.6250"
"125.4000","12.5719","17.6294","-0.0033","12.5358","451.3408","15.6627"
"125.7000","12.6019","17.6315","-0.0023","12.5658","451.3941","15.7002"
"126.0000","12.6322","17.6346","-0.0007","12.5962","451.4742","15.7382"
"126.3000","12.6623","17.6398","-0.0005","12.6262","451.6070","15.7757"
"126.6000","12.6923","17.6428","0.0002","12.6562","451.6852","15.8132"
"126.9000","12.7221","17.6392","-0.0005","12.6860","451.5921","15.8504"
"127.2000","12.7517","17.6356","-0.0027","12.7156","451.5002","15.8874"
"127.5000","12.7819","17.6353","-0.0057","12.7459","451.4923","15.9252"
"127.8000","12.8120","17.6324","-0.0012","12.7759","451.4179","15.9627"
"128.1000","12.8418","17.6341","-0.0023","12.8057","451.4631","16.0000"
"128.4000","12.8723","17.6434","0.0012","12.8363","451.6990","16.0381"
"128.7000","12.9022","17.6413","-0.0039","12.8661","451.6457","16.0754"
"129.0000","12.9319","17.6398","-0.0008","12.8959","451.6072","16.1126"
"129.3000","12.9619","17.6420","-0.0018","12.9259","451.6629","16.1501"
"129.6000","12.9917","17.6352","0.0012","12.9557","451.4911","16.1873"
"129.9000","13.0216","17.6341","0.0024","12.9856","451.4630","16.2247"
"130.2000","13.0521","17.6390","0.0019","13.0160","451.5866","16.2627"
"130.5000","13.0822","17.6411","0.0034","13.0462","451.6415","16.3004"
"130.8000","13.1121","17.6452","0.0002","13.0761","451.7469","16.3378"
"131.1000","13.1422","17.6458","0.0026","13.1062","451.7611","16.3753"
"131.4000","13.1720","17.6445","0.0022","13.1360","451.7268","16.4126"
"131.7000","13.2017","17.6444","0.0031","13.1657","451.7253","16.4497"
"132.0000","13.2318","17.6376","-0.0021","13.1958","451.5518","16.4873"
"132.3000","13.2620","17.6375","-0.0026","13.2259","451.5489","16.5250"
"132.6000","13.2920","17.6404","0.0003","13.2560","451.6237","16.5625"
"132.9000","13.3221","17.6448","-0.0019","13.2861","451.7351","16.6001"
"133.2000","13.3519","17.6435","0.0014","13.3159","451.7025","16.6374"
"133.5000","13.3822","17.6472","-0.0024","13.3461","451.7961","16.6751"
"133.8000","13.4119","17.6450","-0.0010","13.3759","451.7397","16.7123"
"134.1000","13.4415","17.6368","-0.0046","13.4055","451.5308","16.7493"
"134.4000","13.4718","17.6384","-0.0001","13.4358","451.5716","16.7872"
"134.7000","13.5020","17.6420","-0.0007","13.4660","451.6646","16.8249"
"135.0000","13.5321","17.6426","0.0011","13.4960","451.6802","16.8625"
"135.3000","13.5622","17.6470","-0.0024","13.5262","451.7909","16.9001"
"135.6000","13.5924","17.6491","-0.0003","13.5563","451.8464","16.9378"
"135.9000","13.6222","17.6493","-0.0020","13.5862","451.8513","16.9751"
"136.2000","13.6516","17.6416","0.0023","13.6156","451.6542","17.0118"
"136.5000","13.6818","17.6392","0.0011","13.6458","451.5911","17.0496"
"136.8000","13.7121","17.6413","0.0026","13.6761","451.6464","17.0874"
"137.1000","13.7420","17.6396","0.0010","13.7059","451.6014","17.1247"
"137.4000","13.7721","17.6445","-0.0003","13.7361","451.7286","17.1624"
"137.7000","13.8022","17.6452","0.0015","13.7661","451.7459","17.1999"
"138.0000","13.8320","17.6450","0.0045","13.7960","451.7422","17.2372"
"138.3000","13.8616","17.6426","0.0041","13.8256","451.6786","17.2742"
"138.6000","13.8917","17.6372","0.0014","13.8556","451.5404","17.3118"
"138.9000","13.9219","17.6374","-0.0004","13.8859","451.5462","17.3495"
"139.2000","13.9519","17.6396","0.0005","13.9159","451.6033","17.3870"
"139.5000","13.9822","17.6409","0.0023","13.9462","451.6371","17.4249"
"139.8000","14.0121","17.6452","0.0024","13.9761","451.7458","17.4623"
"140.1000","14.0424","17.6495","-0.0006","14.0063","451.8560","17.5000"
"140.4000","14.0721","17.6445","0.0020","14.0361","451.7283","17.5372"
"140.7000","14.1017","17.6395","-0.0018","14.0657","451.6011","17.5742"
"141.0000","14.1319","17.6387","0.0036","14.0959","451.5788","17.6119"
"141.3000","14.1620","17.6352","0.0000","14.1260","451.4901","17.6495"
"141.6000","14.1919","17.6356","0.0038","14.1558","451.4995","17.6868"
"141.9000","14.2223","17.6431","-0.0044","14.1862","451.6910","17.7248"
"142.2000","14.2522","17.6408","-0.0017","14.2162","451.6329","17.7622"
"142.5000","14.2819","17.6389","-0.0030","14.2459","451.5855","17.7994"
"142.8000","14.3119","17.6390","-0.0006","14.2758","451.5880","17.8368"
"143.1000","14.3416","17.6318","0.0003","14.3056","451.4023","17.8739"
"143.4000","14.3717","17.6311","-0.0038","14.3357","451.3859","17.9116"
"143.7000","14.4020","17.6354","0.0004","14.3660","451.4960","17.9494"
"144.0000","14.4322","17.6351","-0.0040","14.3962","451.4887","17.9872"
"144.3000","14.4621","17.6389","0.0025","14.4261","451.5856","18.0245"
"144.6000","14.4923","17.6398","-0.0004","14.4562","451.6078","18.0622"
"144.9000","14.5220","17.6372","0.0028","14.4860","451.5401","18.0993"
"145.2000","14.5517","17.6350","-0.0003","14.5157","451.4851","18.1364"
"145.5000","14.5819","17.6291","0.0024","14.5458","451.3343","18.1741"
"145.8000","14.6120","17.6264","0.0002","14.5759","451.2655","18.2117"
"146.1000","14.6420","17.6300","0.0024","14.6059","451.3565","18.2492"
"146.4000","14.6721","17.6327","0.0017","14.6361","451.4268","18.2869"
"146.7000","14.7019","17.6301","0.0006","14.6659","451.3600","18.3241"
"147.0000","14.7321","17.6314","0.0020","14.6961","451.3929","18.3618"
"147.3000","14.7618","17.6311","-0.0011","14.7258","451.3845","18.3990"
"147.6000","14.7914","17.6208","0.0048","14.7554","451.1212","18.4359"
"147.9000","14.8218","17.6221","0.0009","14.7858","451.1535","18.4739"
"148.2000","14.8520","17.6246","0.0052","14.8159","451.2178","18.5116"
"148.5000","14.8820","17.6249","-0.0015","14.8460","451.2259","18.5491"
"148.8000","14.9122","17.6282","-0.0001","14.8762","451.3120","18.5868"
"149.1000","14.9423","17.6295","-0.0001","14.9063","451.3444","18.6245"
"149.4000","14.9721","17.6281","0.0034","14.9361","451.3083","18.6617"
"149.7000","15.0016","17.6208","-0.0004","14.9655","451.1203","18.6985"
"150.0000","15.0318","17.6169","-0.0024","14.9958","451.0222","18.7363"
"150.3000","15.0622","17.6172","-0.0002","15.0261","451.0284","18.7742"
"150.6000","15.0920","17.6161","-0.0027","15.0559","451.0014","18.8114"
"150.9000","15.1222","17.6203","0.0012","15.0861","451.1085","18.8492"
"151.2000","15.1522","17.6203","-0.0012","15.1162","451.1094","18.8867"
"151.5000","15.1820","17.6189","0.0006","15.1460","451.0739","18.9240"
"151.8000","15.2117","17.6168","-0.0034","15.1757","451.0186","18.9610"
"152.1000","15.2417","17.6090","-0.0013","15.2057","450.8192","18.9985"
"152.4000","15.2719","17.6088","0.0010","15.2358","450.8146","19.0362"
"152.7000","15.3020","17.6092","0.0014","15.2659","450.8237","19.0738"
"153.0000","15.3320","17.6075","0.0009","15.2960","450.7816","19.1113"
"153.3000","15.3622","17.6139","-0.0008","15.3262","450.9441","19.1491"
"153.6000","15.3924","17.6160","-0.0014","15.3563","450.9996","19.1868"
"153.9000","15.4222","17.6107","0.0024","15.3861","450.8634","19.2240"
"154.2000","15.4516","17.6052","0.0020","15.4156","450.7221","19.2608"
"154.5000","15.4819","17.6028","0.0022","15.4459","450.6601","19.2986"
"154.8000","15.5119","17.5982","0.0023","15.4759","450.5434","19.3362"
"155.1000","15.5418","17.5983","-0.0010","15.5058","450.5450","19.3735"
"155.4000","15.5723","17.6053","0.0012","15.5362","450.7235","19.4115"
"155.7000","15.6022","17.6014","0.0026","15.5661","450.6242","19.4489"
"156.0000","15.6319","17.5987","0.0030","15.5959","450.5547","19.4861"
"156.3000","15.6618","17.5976","0.0024","15.6258","450.5261","19.5235"
"156.6000","15.6918","17.5911","-0.0010","15.6557","450.3611","19.5608"
"156.9000","15.7216","17.5876","-0.0017","15.6856","450.2712","19.5982"
"157.2000","15.7520","17.5913","0.0028","15.7160","450.3665","19.6361"
"157.5000","15.7822","17.5902","0.0035","15.7461","450.3381","19.6738"
"157.8000","15.8122","17.5938","0.0012","15.7761","450.4293","19.7113"
"158.1000","15.8423","17.5929","0.0015","15.8063","450.4060","19.7489"
"158.4000","15.8721","17.5903","0.0002","15.8361","450.3401","19.7862"
"158.7000","15.9017","17.5864","-0.0011","15.8657","450.2411","19.8231"
"159.0000","15.9319","17.5794","0.0019","15.8959","450.0610","19.8609"
"159.3000","15.9619","17.5759","0.0001","15.9259","449.9716","19.8984"
"159.6000","15.9919","17.5768","0.0014","15.9559","449.9949","19.9359"
"159.9000","16.0223","17.5818","-0.0002","15.9862","450.1235","19.9738"
"160.2000","16.0521","17.5764","-0.0045","16.0161","449.9840","20.0111"
"160.5000","16.0821","17.5772","0.0004","16.0460","450.0039","20.0485"
"160.8000","16.1119","17.5751","-0.0001","16.0758","449.9523","20.0858"
"161.1000","16.1415","17.5648","-0.0013","16.1054","449.6877","20.1227"
"161.4000","16.1718","17.5640","-0.0016","16.1358","449.6683","20.1607"
"161.7000","16.2020","17.5663","-0.0027","16.1660","449.7259","20.1984"
"162.0000","16.2321","17.5643","-0.0032","16.1960","449.6752","20.2359"
"162.3000","16.2622","17.5671","-0.0006","16.2261","449.7473","20.2735"
"162.6000","16.2923","17.5661","-0.0001","16.2563","449.7221","20.3112"
"162.9000","16.3222","17.5651","-0.0025","16.2861","449.6944","20.3485"
"163.2000","16.3516","17.5571","-0.0001","16.3156","449.4903","20.3853"
"163.5000","16.3819","17.5519","-0.0041","16.3458","449.3577","20.4231"
"163.8000","16.4122","17.5504","0.0014","16.3761","449.3177","20.4609"
"164.1000","16.4420","17.5468","0.0012","16.4059","449.2277","20.4982"
"164.4000","16.4722","17.5498","0.0006","16.4361","449.3035","20.5359"
"164.7000","16.5022","17.5479","-0.0030","16.4661","449.2537","20.5734"
"165.0000","16.5320","17.5467","-0.0007","16.4960","449.2232","20.6107"
"165.3000","16.5617","17.5417","0.0001","16.5256","449.0972","20.6478"
"165.6000","16.5916","17.5333","0.0001","16.5556","448.8802","20.6851"
"165.9000","16.6220","17.5326","0.0005","16.5859","448.8620","20.7231"
"166.2000","16.6519","17.5314","-0.0020","16.6159","448.8336","20.7605"
"166.5000","16.6823","17.5319","0.0002","16.6463","448.8452","20.7985"
"166.8000","16.7123","17.5323","-0.0026","16.6762","448.8565","20.8359"
"167.1000","16.7423","17.5320","0.0055","16.7063","448.8473","20.8735"
"167.4000","16.7721","17.5263","-0.0002","16.7360","448.7024","20.9106"
"167.7000","16.8017","17.5186","0.0018","16.7657","448.5048","20.9476"
"168.0000","16.8319","17.5157","-0.0009","16.7959","448.4299","20.9854"
"168.3000","16.8619","17.5082","0.0004","16.8259","448.2390","21.0229"
"168.6000","16.8918","17.5084","0.0035","16.8558","448.2428","21.0603"
"168.9000","16.9223","17.5119","0.0020","16.8863","448.3335","21.0983"
"169.2000","16.9521","17.5066","0.0019","16.9161","448.1969","21.1356"
"169.5000","16.9819","17.5016","-0.0020","16.9458","448.0685","21.1727"
"169.8000","17.0117","17.5004","0.0032","16.9757","448.0393","21.2101"
"170.1000","17.0418","17.4902","-0.0015","17.0057","447.7770","21.2476"
"170.4000","17.0717","17.4852","0.0048","17.0356","447.6500","21.2849"
"170.7000","17.1020","17.4862","0.0013","17.0660","447.6763","21.3228"
"171.0000","17.1322","17.4837","0.0015","17.0962","447.6122","21.3606"
"171.3000","17.1622","17.4847","-0.0021","17.1261","447.6375","21.3980"
"171.6000","17.1922","17.4813","0.0025","17.1562","447.5497","21.4356"
"171.9000","17.2221","17.4768","0.0021","17.1860","447.4343","21.4729"
"172.2000","17.2517","17.4703","0.0026","17.2156","447.2673","21.5099"
"172.5000","17.2819","17.4609","0.0015","17.2458","447.0274","21.5476"
"172.8000","17.3120","17.4548","-0.0012","17.2759","446.8726","21.5852"
"173.1000","17.3419","17.4526","0.0016","17.3058","446.8146","21.6225"
"173.4000","17.3723","17.4557","0.0010","17.3362","446.8957","21.6605"
"173.7000","17.4022","17.4488","0.0051","17.3661","446.7170","21.6979"
"174.0000","17.4321","17.4443","0.0010","17.3960","446.6019","21.7353"
"174.3000","17.4619","17.4395","0.0026","17.4259","446.4791","21.7725"
"174.6000","17.4915","17.4256","-0.0016","17.4554","446.1227","21.8095"
"174.9000","17.5218","17.4219","0.0008","17.4858","446.0302","21.8474"
"175.2000","17.5520","17.4202","0.0002","17.5160","445.9848","21.8851"
"175.5000","17.5821","17.4154","0.0042","17.5460","445.8639","21.9227"
"175.8000","17.6122","17.4131","0.0031","17.5761","445.8044","21.9603"
"176.1000","17.6423","17.4095","-0.0010","17.6063","445.7110","21.9979"
"176.4000","17.6721","17.4027","0.0029","17.6361","445.5379","22.0352"
"176.7000","17.7016","17.3941","-0.0020","17.6656","445.3176","22.0721"
"177.0000","17.7319","17.3814","0.0024","17.6959","444.9930","22.1099"
"177.3000","17.7621","17.3748","-0.0016","17.7261","444.8224","22.1476"
"177.6000","17.7920","17.3673","0.0024","17.7559","444.6302","22.1849"
"177.9000","17.8221","17.3649","-0.0030","17.7861","444.5687","22.2226"
"178.2000","17.8522","17.3574","-0.0002","17.8162","444.3777","22.2602"
"178.5000","17.8820","17.3510","-0.0027","17.8460","444.2128","22.2975"
"178.8000","17.9117","17.3402","-0.0027","17.8757","443.9373","22.3345"
"179.1000","17.9417","17.3257","-0.0001","17.9057","443.5654","22.3720"
"179.4000","17.9719","17.3176","-0.0022","17.9358","443.3594","22.4097"
"179.7000","18.0019","17.3100","0.0001","17.9659","443.1656","22.4472"
"180.0000","18.0322","17.3037","-0.0040","17.9961","443.0023","22.4851"
"180.3000","18.0623","17.2967","-0.0001","18.0263","442.8244","22.5227"
"180.6000","18.0923","17.2887","-0.0024","18.0563","442.6189","22.5602"
"180.9000","18.1222","17.2754","0.0047","18.0861","442.2796","22.5975"
"181.2000","18.1517","17.2595","-0.0005","18.1157","441.8706","22.6344"
"181.5000","18.1819","17.2468","-0.0020","18.1459","441.5475","22.6722"
"181.8000","18.2119","17.2314","0.0011","18.1759","441.1521","22.7096"
"182.1000","18.2418","17.2197","0.0007","18.2058","440.8528","22.7470"
"182.4000","18.2723","17.2145","0.0008","18.2362","440.7188","22.7850"
"182.7000","18.3022","17.1990","0.0011","18.2661","440.3226","22.8224"
"183.0000","18.3319","17.1833","0.0025","18.2959","439.9202","22.8595"
"183.3000","18.3618","17.1694","-0.0004","18.3257","439.5642","22.8968"
"183.6000","18.3917","17.1476","0.0001","18.3557","439.0074","22.9343"
"183.9000","18.4217","17.1297","-0.0003","18.3857","438.5482","22.9718"
"184.2000","18.4520","17.1185","0.0051","18.4160","438.2617","23.0096"
"184.5000","18.4822","17.1016","0.0009","18.4462","437.8294","23.0474"
"184.8000","18.5122","17.0901","0.0014","18.4761","437.5343","23.0848"
"185.1000","18.5422","17.0715","0.0005","18.5062","437.0594","23.1224"
"185.4000","18.5721","17.0509","0.0004","18.5360","436.5312","23.1596"
"185.7000","18.6017","17.0301","0.0037","18.5657","435.9977","23.1966"
"186.0000","18.6319","17.0047","-0.0007","18.5958","435.3478","23.2343"
"186.3000","18.6620","16.9819","0.0039","18.6260","434.7635","23.2720"
"186.6000","18.6919","16.9631","-0.0004","18.6558","434.2826","23.3093"
"186.9000","18.7223","16.9464","0.0013","18.6863","433.8556","23.3473"
"187.2000","18.7521","16.9207","-0.0019","18.7160","433.1985","23.3845"
"187.5000","18.7821","16.8999","0.0013","18.7460","432.6658","23.4220"
"187.8000","18.8119","16.8760","0.0006","18.7759","432.0537","23.4592"
"188.1000","18.8414","16.8426","-0.0004","18.8054","431.1974","23.4961"
"188.4000","18.8719","16.8193","-0.0019","18.8359","430.6025","23.5343"
"188.7000","18.9020","16.7958","-0.0035","18.8660","429.9987","23.5719"
"189.0000","18.9321","16.7704","-0.0013","18.8961","429.3501","23.6094"
"189.3000","18.9622","16.7475","-0.0004","18.9262","428.7647","23.6471"
"189.6000","18.9924","16.7211","0.0015","18.9563","428.0884","23.6848"
"189.9000","19.0220","16.6918","-0.0019","18.9860","427.3363","23.7218"
"190.2000","19.0517","16.6577","-0.0025","19.0156","426.4643","23.7589"
"190.5000","19.0820","16.6266","-0.0036","19.0460","425.6691","23.7968"
"190.8000","19.1121","16.5935","-0.0029","19.0761","424.8204","23.8344"
"191.1000","19.1419","16.5628","-0.0014","19.1059","424.0345","23.8716"
"191.4000","19.1722","16.5350","-0.0002","19.1361","423.3242","23.9094"
"191.7000","19.2021","16.5019","-0.0047","19.1661","422.4755","23.9468"
"192.0000","19.2321","16.4701","-0.0046","19.1961","421.6620","23.9843"
"192.3000","19.2617","16.4354","-0.0026","19.2256","420.7742","24.0212"
"192.6000","19.2916","16.3928","-0.0005","19.2556","419.6827","24.0587"
"192.9000","19.3219","16.3587","0.0028","19.2858","418.8102","24.0965"
"193.2000","19.3519","16.3236","-0.0007","19.3158","417.9113","24.1339"
"193.5000","19.3822","16.2897","-0.0005","19.3462","417.0436","24.1718"
"193.8000","19.4123","16.2554","-0.0005","19.3762","416.1656","24.2094"
"194.1000","19.4422","16.2195","0.0029","19.4062","415.2450","24.2468"
"194.4000","19.4720","16.1777","0.0018","19.4360","414.1750","24.2841"
"194.7000","19.5018","16.1319","0.0024","19.4657","413.0039","24.3212"
"195.0000","19.5320","16.0917","0.0002","19.4959","411.9740","24.3590"
"195.3000","19.5620","16.0468","-0.0025","19.5260","410.8247","24.3965"
"195.6000","19.5919","16.0061","0.0022","19.5558","409.7812","24.4338"
"195.9000","19.6223","15.9698","0.0000","19.5863","408.8533","24.4718"
"196.2000","19.6522","15.9248","0.0026","19.6162","407.6999","24.5092"
"196.5000","19.6819","15.8776","0.0022","19.6459","406.4931","24.5463"
"196.8000","19.7119","15.8348","0.0014","19.6759","405.3975","24.5838"
"197.1000","19.7418","15.7809","-0.0004","19.7058","404.0162","24.6211"
"197.4000","19.7716","15.7325","0.0012","19.7356","402.7766","24.6583"
"197.7000","19.8021","15.6888","-0.0005","19.7660","401.6579","24.6964"
"198.0000","19.8322","15.6405","0.0043","19.7962","400.4229","24.7341"
"198.3000","19.8621","15.5951","0.0024","19.8261","399.2591","24.7715"
"198.6000","19.8923","15.5449","0.0002","19.8562","397.9748","24.8091"
"198.9000","19.9221","15.4918","0.0029","19.8861","396.6154","24.8465"
"199.2000","19.9517","15.4377","-0.0017","19.9156","395.2306","24.8834"
"199.5000","19.9819","15.3789","0.0020","19.9459","393.7261","24.9211"
"199.8000","20.0120","15.3225","0.0026","19.9759","392.2815","24.9587"
"200.1000","20.0420","15.2699","0.0026","20.0060","390.9337","24.9962"
"200.4000","20.0722","15.2176","0.0001","20.0362","389.5967","25.0339"
"200.7000","20.1020","15.1581","-0.0005","20.0660","388.0714","25.0712"
"201.0000","20.1321","15.1008","-0.0010","20.0961","386.6055","25.1088"
"201.3000","20.1619","15.0412","0.0017","20.1259","385.0802","25.1460"
"201.6000","20.1915","14.9732","0.0020","20.1555","383.3380","25.1831"
"201.9000","20.2218","14.9127","0.0002","20.1858","381.7897","25.2209"
"202.2000","20.2521","14.8532","0.0008","20.2161","380.2664","25.2587"
"202.5000","20.2821","14.7904","-0.0014","20.2460","378.6589","25.2961"
"202.8000","20.3122","14.7292","0.0002","20.2762","377.0920","25.3338"
"203.1000","20.3424","14.6646","-0.0010","20.3063","375.4375","25.3715"
"203.4000","20.3723","14.5987","0.0008","20.3362","373.7495","25.4089"
"203.7000","20.4018","14.5231","-0.0027","20.3657","371.8157","25.4457"
"204.0000","20.4318","14.4510","0.0009","20.3958","369.9705","25.4833"
"204.3000","20.4621","14.3810","-0.0080","20.4260","368.1778","25.5211"
"204.6000","20.4920","14.3083","0.0019","20.4560","366.3164","25.5585"
"204.9000","20.5222","14.2400","-0.0029","20.4861","364.5665","25.5961"
"205.2000","20.5522","14.1643","-0.0008","20.5162","362.6291","25.6336"
"205.5000","20.5821","14.0892","-0.0028","20.5460","360.7061","25.6710"
"205.8000","20.6118","14.0105","-0.0017","20.5757","358.6919","25.7081"
"206.1000","20.6417","13.9250","-0.0047","20.6057","356.5016","25.7455"
"206.4000","20.6719","13.8462","-0.0014","20.6359","354.4842","25.7833"
"206.7000","20.7019","13.7661","-0.0001","20.6659","352.4358","25.8208"
"207.0000","20.7322","13.6836","-0.0006","20.6962","350.3213","25.8586"
"207.3000","20.7621","13.6022","-0.0046","20.7261","348.2374","25.8960"
"207.6000","20.7923","13.5199","-0.0016","20.7563","346.1308","25.9337"
"207.9000","20.8222","13.4266","-0.0073","20.7862","343.7421","25.9710"
"208.2000","20.8517","13.3316","0.0043","20.8157","341.3119","26.0079"
"208.5000","20.8820","13.2398","-0.0026","20.8460","338.9618","26.0457"
"208.8000","20.9120","13.1437","-0.0006","20.8760","336.4994","26.0832"
"209.1000","20.9419","13.0485","-0.0018","20.9059","334.0629","26.1206"
"209.4000","20.9722","12.9570","-0.0016","20.9362","331.7196","26.1584"
"209.7000","21.0022","12.8556","-0.0009","20.9662","329.1233","26.1959"
"210.0000","21.0320","12.7533","0.0037","20.9959","326.5065","26.2331"
"210.3000","21.0619","12.6496","0.0013","21.0259","323.8514","26.2705"
"210.6000","21.0917","12.5390","-0.0012","21.0556","321.0178","26.3077"
"210.9000","21.1218","12.4323","-0.0005","21.0858","318.2868","26.3454"
"211.2000","21.1521","12.3214","0.0022","21.1160","315.4480","26.3832"
"211.5000","21.1823","12.2079","0.0029","21.1462","312.5432","26.4209"
"211.8000","21.2121","12.0937","0.0024","21.1761","309.6187","26.4582"
"212.1000","21.2424","11.9687","-0.0007","21.2063","306.4183","26.4960"
"212.4000","21.2721","11.8291","0.0019","21.2361","302.8437","26.5332"
"212.7000","21.3019","11.5185","0.0029","21.2659","294.8931","26.5704"
"212.7490","21.3161","3.3921","-0.0078","21.2801","86.8439","26.5882"