File: Datasets/abs.csv
Time,Force,Displacement,Strain 1
(s),(kN),(mm),(mm/mm)
0,0.0001,0.0966,-2e-06
1,0.0006,0.0988,2.6e-05
2,0.0036,0.103,7.900000000000001e-05
3,0.0073,0.1069,0.000127
4,0.0105,0.1108,0.00017500000000000003
5,0.014,0.115,0.00022700000000000002
6,0.0175,0.119,0.000278
7,0.0211,0.1232,0.00033
8,0.0245,0.127,0.00037699999999999995
9,0.0277,0.1309,0.000427
10,0.0309,0.1351,0.000478
11,0.034,0.1387,0.000524
12,0.0366,0.1428,0.000575
13,0.0396,0.1471,0.000628
14,0.0427,0.1508,0.000675
15,0.0451,0.1548,0.000725
16,0.0475,0.159,0.000777
17,0.0494,0.1628,0.000825
18,0.0508,0.1667,0.0008740000000000001
19,0.0517,0.1709,0.0009260000000000001
20,0.0526,0.1748,0.0009750000000000001
21,0.0533,0.1789,0.0010249999999999999
22,0.0538,0.1827,0.0010730000000000002
23,0.0541,0.1866,0.001122
24,0.0547,0.1908,0.0011740000000000001
25,0.0553,0.1945,0.00122
26,0.0555,0.1986,0.0012720000000000001
27,0.0554,0.2029,0.001325
28,0.0556,0.2068,0.001374
29,0.0558,0.2108,0.001423
30,0.0559,0.2149,0.001476
31,0.0558,0.2188,0.0015240000000000002
32,0.0559,0.2226,0.001572
33,0.0562,0.2268,0.0016239999999999998
34,0.0564,0.2308,0.001673
35,0.0566,0.2349,0.001725
36,0.0566,0.2387,0.001773
37,0.0567,0.2427,0.001822
38,0.0566,0.2469,0.001875
39,0.0568,0.2506,0.001921
40,0.057,0.2547,0.001972
41,0.0571,0.259,0.0020250000000000003
42,0.0572,0.2628,0.002074
43,0.0575,0.2666,0.002121
44,0.0575,0.2708,0.002173
45,0.0578,0.2747,0.002221
46,0.058,0.2785,0.0022689999999999997
47,0.0581,0.2827,0.002322
48,0.0583,0.2868,0.002373
49,0.0584,0.291,0.002425
50,0.0586,0.2949,0.002473
51,0.0588,0.2988,0.002523
52,0.059,0.3029,0.0025729999999999998
53,0.059,0.3066,0.00262
54,0.0591,0.3107,0.002671
55,0.0591,0.3149,0.002724
56,0.0592,0.3188,0.002773
57,0.0593,0.3227,0.002821
58,0.0595,0.3269,0.002873
59,0.0597,0.3307,0.0029210000000000004
60,0.0599,0.3346,0.00297
61,0.0599,0.3388,0.0030220000000000004
62,0.0602,0.3428,0.0030719999999999996
63,0.0602,0.347,0.003124
64,0.0604,0.3508,0.0031709999999999998
65,0.0604,0.3546,0.00322
66,0.0604,0.3588,0.0032719999999999997
67,0.0605,0.3626,0.003319
68,0.0607,0.3666,0.0033689999999999996
69,0.061,0.3709,0.003423
70,0.0612,0.375,0.003473
71,0.0611,0.3787,0.0035199999999999997
72,0.0612,0.3829,0.0035730000000000002
73,0.0613,0.3868,0.0036209999999999997
74,0.0616,0.3906,0.003669
75,0.062,0.3948,0.003721
76,0.0622,0.3988,0.003771
77,0.0628,0.4029,0.003822
78,0.0636,0.4067,0.00387
79,0.065,0.4107,0.003919000000000001
80,0.0668,0.4148,0.003971
81,0.0686,0.4187,0.004019
82,0.0701,0.4227,0.004069
83,0.0721,0.4269,0.004122
84,0.0735,0.4309,0.004172
85,0.0749,0.4347,0.004219
86,0.0769,0.4388,0.004271
87,0.0794,0.4427,0.004319
88,0.0822,0.4466,0.004368
89,0.085,0.4508,0.00442
90,0.0879,0.4548,0.00447
91,0.0907,0.4591,0.004523
92,0.0937,0.4629,0.004571
93,0.0967,0.4668,0.00462
94,0.0997,0.4709,0.004672
95,0.103,0.4747,0.004719
96,0.1059,0.4787,0.004768
97,0.1092,0.483,0.004822
98,0.1126,0.487,0.0048720000000000005
99,0.1158,0.4906,0.004917
100,0.119,0.4948,0.00497
101,0.1225,0.4988,0.005019
102,0.1257,0.5026,0.005067
103,0.129,0.5068,0.00512
104,0.1326,0.5108,0.00517
105,0.1358,0.5149,0.005221
106,0.1392,0.5187,0.005269
107,0.1424,0.5226,0.005317
108,0.1457,0.5267,0.005368
109,0.1492,0.5306,0.005417
110,0.1524,0.5346,0.0054659999999999995
111,0.1558,0.5389,0.005520000000000001
112,0.1594,0.543,0.0055720000000000006
113,0.1627,0.5468,0.005618
114,0.1659,0.551,0.005671000000000001
115,0.1695,0.5548,0.005718999999999999
116,0.1727,0.5587,0.0057669999999999996
117,0.176,0.5628,0.0058189999999999995
118,0.1795,0.5668,0.005869
119,0.1828,0.571,0.005920999999999999
120,0.1862,0.5748,0.005968
121,0.1894,0.5786,0.0060160000000000005
122,0.1926,0.5827,0.006067
123,0.1961,0.5868,0.006118
124,0.1993,0.5907,0.006167000000000001
125,0.2029,0.595,0.00622
126,0.2063,0.599,0.006271
127,0.2093,0.6027,0.006316
128,0.2126,0.6068,0.006368
129,0.2159,0.6107,0.006417000000000001
130,0.2191,0.6146,0.006464999999999999
131,0.2224,0.6187,0.006515999999999999
132,0.2258,0.6228,0.006568000000000001
133,0.2292,0.627,0.00662
134,0.2325,0.6309,0.0066690000000000004
135,0.2357,0.6348,0.006717
136,0.2389,0.6388,0.006767
137,0.2424,0.6427,0.006816
138,0.2455,0.6466,0.006865
139,0.2488,0.6508,0.0069169999999999995
140,0.2523,0.6549,0.0069689999999999995
141,0.2555,0.6586,0.007015
142,0.2586,0.6628,0.007068
143,0.2621,0.6668,0.007117
144,0.2653,0.6707,0.0071660000000000005
145,0.2686,0.6748,0.007217
146,0.2721,0.6788,0.007267
147,0.2752,0.6829,0.007319
148,0.2787,0.6868,0.007367
149,0.2819,0.6906,0.007414
150,0.285,0.6947,0.007465
151,0.2884,0.6987,0.007514999999999999
152,0.2916,0.7025,0.007562999999999999
153,0.295,0.7068,0.0076170000000000005
154,0.2986,0.7111,0.00767
155,0.3017,0.7147,0.007715
156,0.3049,0.7189,0.007767
157,0.3082,0.7229,0.007817
158,0.3116,0.7267,0.007865
159,0.3148,0.7307,0.007915
160,0.318,0.7348,0.007967
161,0.3214,0.7389,0.008017
162,0.3247,0.7428,0.008066
163,0.3277,0.7467,0.008114
164,0.3312,0.7507,0.008165
165,0.3345,0.7548,0.008215
166,0.3376,0.7586,0.008264
167,0.3409,0.7628,0.008316
168,0.3442,0.767,0.008367
169,0.3476,0.7706,0.008413
170,0.3507,0.7747,0.008464000000000001
171,0.354,0.7787,0.008514
172,0.3573,0.7827,0.008564
173,0.3604,0.7867,0.008614
174,0.3638,0.7909,0.008666
175,0.3671,0.795,0.008718
176,0.3705,0.799,0.008768
177,0.3737,0.8028,0.008815
178,0.3768,0.8069,0.008866
179,0.3802,0.8109,0.008916
180,0.3833,0.8146,0.008963
181,0.3864,0.8189,0.009015
182,0.3898,0.823,0.009068
183,0.3931,0.8266,0.009112
184,0.3961,0.8307,0.009164
185,0.3994,0.8349,0.009215
186,0.4026,0.8387,0.009263
187,0.4056,0.8427,0.009313
188,0.4088,0.8469,0.009365
189,0.4122,0.8508,0.009415
190,0.415,0.8547,0.009463000000000001
191,0.4178,0.8586,0.009512
192,0.4209,0.8627,0.009563
193,0.4243,0.8668,0.009614000000000001
194,0.4274,0.8705,0.00966
195,0.4305,0.8748,0.009714
196,0.434,0.879,0.009766
197,0.4372,0.8827,0.009812999999999999
198,0.4402,0.8869,0.009865
199,0.4434,0.8909,0.009915
200,0.4467,0.8947,0.009963
201,0.4497,0.8987,0.010012
202,0.4529,0.9028,0.010064
203,0.4562,0.9068,0.010114000000000001
204,0.4596,0.9108,0.010164
205,0.4626,0.9147,0.010212
206,0.4657,0.9187,0.010262
207,0.469,0.9229,0.010315000000000001
208,0.4721,0.9266,0.010361
209,0.4752,0.9307,0.010412
210,0.4786,0.935,0.010466
211,0.4819,0.9387,0.010511999999999999
212,0.4848,0.9427,0.010561000000000001
213,0.488,0.9468,0.010612
214,0.4912,0.9506,0.010661
215,0.4942,0.9545,0.010709
216,0.4973,0.9588,0.010762
217,0.5007,0.9629,0.010813
218,0.504,0.9669,0.010864
219,0.5071,0.9708,0.010912999999999999
220,0.5101,0.9748,0.010963
221,0.5134,0.9789,0.011013
222,0.5165,0.9826,0.01106
223,0.5195,0.9868,0.011112
224,0.5229,0.991,0.011164
225,0.5262,0.9947,0.011211
226,0.5289,0.9987,0.011261
227,0.5323,1.0028,0.011312
228,0.5354,1.0067,0.011361000000000001
229,0.5384,1.0107,0.011411
230,0.5417,1.0148,0.011462000000000002
231,0.5448,1.0188,0.011511
232,0.548,1.0228,0.011562
233,0.5511,1.0266,0.01161
234,0.5541,1.0306,0.011659
235,0.5573,1.0348,0.011711000000000001
236,0.5603,1.0385,0.011758
237,0.5634,1.0426,0.011809
238,0.5668,1.047,0.011862999999999999
239,0.5701,1.0508,0.011912
240,0.5729,1.0548,0.011961
241,0.5761,1.0589,0.012013000000000001
242,0.5793,1.0628,0.012060999999999999
243,0.5822,1.0666,0.012109000000000002
244,0.5853,1.0708,0.012161
245,0.5886,1.0748,0.012211000000000001
246,0.5918,1.0788,0.012261
247,0.5948,1.0827,0.012309
248,0.5977,1.0867,0.012359
249,0.6009,1.0908,0.012411
250,0.604,1.0946,0.012458
251,0.607,1.0987,0.012509
252,0.6102,1.1029,0.012562
253,0.6133,1.1068,0.01261
254,0.6162,1.1107,0.012659
255,0.6194,1.1148,0.012710999999999998
256,0.6225,1.1187,0.012759
257,0.6255,1.1226,0.012806999999999999
258,0.6286,1.1268,0.01286
259,0.6319,1.1308,0.012910999999999999
260,0.6349,1.135,0.012963
261,0.6381,1.1389,0.013011
262,0.641,1.1428,0.01306
263,0.6441,1.1469,0.013111
264,0.6471,1.1506,0.013157
265,0.6501,1.1547,0.013208
266,0.6533,1.159,0.013262000000000001
267,0.6564,1.1629,0.013309999999999999
268,0.6594,1.1667,0.013358000000000002
269,0.6625,1.1709,0.013411
270,0.6654,1.1748,0.013459
271,0.6684,1.1787,0.013507
272,0.6715,1.1829,0.013561
273,0.6747,1.1869,0.01361
274,0.6778,1.1909,0.013661000000000001
275,0.6807,1.1948,0.013709
276,0.6837,1.1987,0.013758
277,0.6867,1.2028,0.013809
278,0.6897,1.2066,0.013856
279,0.6927,1.2107,0.013907000000000001
280,0.6959,1.2149,0.013961
281,0.6989,1.2189,0.01401
282,0.7018,1.2228,0.014058999999999999
283,0.7048,1.2269,0.014110000000000001
284,0.7078,1.2308,0.014157999999999999
285,0.7107,1.2346,0.014206000000000002
286,0.7137,1.2388,0.014258
287,0.7167,1.2427,0.014308000000000001
288,0.7196,1.247,0.01436
289,0.7224,1.2507,0.014408
290,0.7251,1.2547,0.014456
291,0.7282,1.2589,0.014509000000000001
292,0.7312,1.2627,0.014556
293,0.7339,1.2666,0.014606
294,0.737,1.2709,0.01466
295,0.7401,1.2749,0.014709000000000002
296,0.7428,1.2786,0.014755
297,0.7459,1.2827,0.014806999999999999
298,0.7488,1.2866,0.014856000000000001
299,0.7518,1.2904,0.014903
300,0.7546,1.2947,0.014956
301,0.7578,1.2988,0.015007999999999999
302,0.7609,1.303,0.01506
303,0.7637,1.3069,0.015108
304,0.7667,1.3108,0.015157
305,0.7696,1.3148,0.015208
306,0.7725,1.3186,0.015255000000000001
307,0.7754,1.3226,0.015305
308,0.7784,1.3269,0.015358
309,0.7814,1.3309,0.015408
310,0.7843,1.3346,0.015455000000000002
311,0.7873,1.3388,0.015507
312,0.7901,1.3427,0.015555000000000001
313,0.7931,1.3466,0.015605
314,0.796,1.3508,0.015657
315,0.7989,1.3548,0.015706
316,0.8018,1.3589,0.015758
317,0.8048,1.3627,0.015806
318,0.8076,1.3666,0.015853
319,0.8104,1.3707,0.015905
320,0.8134,1.3746,0.015954
321,0.8162,1.3785,0.016002000000000002
322,0.8193,1.3828,0.016057
323,0.8223,1.387,0.016109
324,0.8251,1.3907,0.016155
325,0.8279,1.3948,0.016207
326,0.831,1.3988,0.016256
327,0.8338,1.4026,0.016303
328,0.8366,1.4068,0.016354999999999998
329,0.8395,1.4108,0.016406
330,0.8423,1.4149,0.016457
331,0.8452,1.4188,0.016505000000000002
332,0.8481,1.4227,0.016554
333,0.8509,1.4267,0.016605
334,0.8538,1.4307,0.016654
335,0.8566,1.4346,0.016703
336,0.8595,1.4389,0.016756
337,0.8624,1.4429,0.016807000000000002
338,0.8651,1.4466,0.016853
339,0.8679,1.4507,0.016904
340,0.8709,1.4547,0.016954
341,0.8737,1.4586,0.017002
342,0.8764,1.4627,0.017054
343,0.8794,1.4668,0.017105
344,0.8823,1.471,0.017158
345,0.8852,1.475,0.017207
346,0.888,1.4788,0.017255
347,0.8907,1.4829,0.017306
348,0.8936,1.4868,0.017354
349,0.8962,1.4906,0.017403
350,0.8992,1.4949,0.017456
351,0.9022,1.4991,0.017508
352,0.9048,1.5026,0.017552
353,0.9073,1.5068,0.017603999999999998
354,0.9104,1.5108,0.017654
355,0.9131,1.5146,0.017702
356,0.9158,1.5188,0.017754000000000002
357,0.9187,1.5229,0.017805
358,0.9215,1.5269,0.017856
359,0.9244,1.5308,0.017904
360,0.927,1.5347,0.017953
361,0.9298,1.5388,0.018004
362,0.9326,1.5427,0.018053
363,0.9351,1.5466,0.018101
364,0.938,1.5509,0.018154999999999998
365,0.941,1.555,0.018207
366,0.9437,1.5588,0.018253
367,0.9463,1.5629,0.018305000000000002
368,0.9493,1.5668,0.018354
369,0.9517,1.5707,0.018402
370,0.9544,1.5748,0.018453
371,0.9572,1.5788,0.018503000000000002
372,0.9599,1.5829,0.018554
373,0.9628,1.5868,0.018603
374,0.9653,1.5907,0.018651
375,0.968,1.5948,0.018703
376,0.9707,1.5988,0.018753
377,0.9732,1.6027,0.018801000000000002
378,0.9759,1.6069,0.018854
379,0.9786,1.611,0.018906
380,0.9811,1.6146,0.018951
381,0.9835,1.6187,0.019001999999999998
382,0.9862,1.6228,0.019052
383,0.9889,1.6266,0.0191
384,0.9914,1.6306,0.01915
385,0.9941,1.6348,0.019202
386,0.997,1.6389,0.019254
387,0.9997,1.6428,0.019303
388,1.0022,1.6468,0.019352
389,1.0048,1.6508,0.019402
390,1.0075,1.6548,0.019452
391,1.01,1.6586,0.0195
392,1.0127,1.6628,0.019552
393,1.0155,1.667,0.019604
394,1.018,1.6706,0.01965
395,1.0205,1.6747,0.019701
396,1.0232,1.6787,0.019751
397,1.0258,1.6827,0.019799999999999998
398,1.0284,1.6868,0.019851
399,1.0311,1.6908,0.019902
400,1.0336,1.6948,0.019952
401,1.0363,1.6988,0.020001
402,1.0387,1.7026,0.020049
403,1.0412,1.7066,0.020099
404,1.044,1.7108,0.020151
405,1.0464,1.7145,0.020197
406,1.0489,1.7188,0.020251
407,1.0517,1.723,0.020304000000000003
408,1.0543,1.7267,0.02035
409,1.0567,1.7308,0.020401
410,1.0594,1.7348,0.020451999999999998
411,1.0618,1.7387,0.020499999999999997
412,1.0643,1.7427,0.020548999999999998
413,1.067,1.7468,0.020600999999999998
414,1.0694,1.7509,0.020652
415,1.0721,1.7548,0.0207
416,1.0744,1.7587,0.020749
417,1.0768,1.7627,0.020798999999999998
418,1.0795,1.7668,0.020851
419,1.082,1.7706,0.020898
420,1.0843,1.7748,0.020950000000000003
421,1.087,1.7789,0.021002
422,1.0894,1.7827,0.021049000000000002
423,1.0916,1.7867,0.021099
424,1.0943,1.7908,0.021150000000000002
425,1.0968,1.7947,0.021199
426,1.0991,1.7987,0.021248
427,1.1017,1.8028,0.0213
428,1.1043,1.8069,0.021351
429,1.1068,1.811,0.021402
430,1.1092,1.8149,0.02145
431,1.1115,1.8189,0.0215
432,1.1139,1.8229,0.021551
433,1.1162,1.8266,0.021596999999999998
434,1.1187,1.8308,0.021648999999999998
435,1.1212,1.835,0.021702
436,1.1236,1.8387,0.021748
437,1.1257,1.8427,0.021798
438,1.1283,1.8469,0.02185
439,1.1306,1.8508,0.021899000000000002
440,1.133,1.8547,0.021948
441,1.1353,1.8589,0.022000000000000002
442,1.1377,1.8628,0.022049
443,1.1401,1.8668,0.022099
444,1.1424,1.8707,0.022147999999999998
445,1.1448,1.8747,0.022198000000000002
446,1.1472,1.8788,0.022248999999999998
447,1.1493,1.8825,0.022296
448,1.1516,1.8867,0.022348
449,1.1541,1.891,0.022401
450,1.1566,1.8948,0.022448000000000003
451,1.1587,1.8988,0.022498
452,1.1609,1.9029,0.02255
453,1.1633,1.9068,0.022597999999999997
454,1.1654,1.9107,0.022647
455,1.1678,1.9148,0.022698999999999997
456,1.1701,1.9188,0.022748
457,1.1725,1.9229,0.022799
458,1.1746,1.9267,0.022847
459,1.1767,1.9307,0.022896
460,1.1791,1.9349,0.022949999999999998
461,1.1813,1.9386,0.022996
462,1.1834,1.9427,0.023046
463,1.1857,1.947,0.0231
464,1.1881,1.9507,0.023147
465,1.19,1.9546,0.023195
466,1.1922,1.9588,0.023247
467,1.1944,1.9627,0.023296
468,1.1964,1.9665,0.023343
469,1.1984,1.9707,0.023397
470,1.2004,1.9748,0.023448000000000004
471,1.2026,1.9789,0.023499
472,1.2048,1.9829,0.023548
473,1.2069,1.9869,0.023597999999999997
474,1.2089,1.9909,0.023648
475,1.2109,1.9946,0.023694000000000003
476,1.213,1.9987,0.023746
477,1.2151,2.0029,0.023798
478,1.2174,2.0068,0.023846
479,1.2194,2.0107,0.023896
480,1.2214,2.0148,0.023947
481,1.2236,2.0187,0.023996
482,1.2256,2.0227,0.024045
483,1.2277,2.0268,0.024097
484,1.2296,2.0308,0.024146
485,1.2318,2.0349,0.024198
486,1.2337,2.0387,0.024245000000000003
487,1.2356,2.0426,0.024293999999999996
488,1.2376,2.0468,0.024346
489,1.2396,2.0505,0.024392999999999998
490,1.2415,2.0546,0.024443000000000003
491,1.2435,2.0589,0.024498000000000002
492,1.2458,2.0629,0.024547
493,1.2476,2.0667,0.024595
494,1.2495,2.0709,0.024647000000000002
495,1.2516,2.0748,0.024695
496,1.2534,2.0786,0.024743
497,1.2553,2.0828,0.024794999999999998
498,1.2572,2.0868,0.024845000000000002
499,1.2592,2.0909,0.024897
500,1.2611,2.0947,0.024945
501,1.2627,2.0987,0.024994000000000002
502,1.2647,2.1029,0.025046
503,1.2666,2.1067,0.025093999999999998
504,1.2683,2.1107,0.025144000000000003
505,1.2703,2.115,0.025198
506,1.2723,2.1189,0.025246
507,1.2739,2.1227,0.025293999999999997
508,1.2757,2.1268,0.025346
509,1.2774,2.1307,0.025394
510,1.2792,2.1346,0.025442
511,1.2809,2.1388,0.025495
512,1.2827,2.1428,0.025544999999999998
513,1.2846,2.147,0.025596999999999998
514,1.2864,2.1509,0.025646
515,1.288,2.1548,0.025693999999999998
516,1.2896,2.1589,0.025746
517,1.2915,2.1627,0.025793
518,1.2929,2.1667,0.025842999999999998
519,1.2947,2.171,0.025897
520,1.2965,2.1749,0.025945999999999997
521,1.2979,2.1787,0.025992
522,1.2995,2.1829,0.026045
523,1.3012,2.1868,0.026094
524,1.3027,2.1906,0.026142
525,1.3043,2.1948,0.026194000000000002
526,1.3059,2.1988,0.026244
527,1.3075,2.2029,0.026295000000000002
528,1.309,2.2067,0.026343000000000002
529,1.3104,2.2106,0.026391
530,1.312,2.2148,0.026442999999999998
531,1.3135,2.2186,0.026490999999999997
532,1.3149,2.2226,0.026541000000000002
533,1.3163,2.2269,0.026595
534,1.318,2.231,0.026646
535,1.3193,2.2348,0.026692999999999998
536,1.3207,2.2389,0.026745
537,1.3221,2.2428,0.026793
538,1.3235,2.2467,0.026842
539,1.3249,2.2508,0.026894
540,1.3262,2.2548,0.026943
541,1.3274,2.2589,0.026995
542,1.3287,2.2627,0.027042
543,1.3298,2.2666,0.02709
544,1.3311,2.2708,0.027143
545,1.3324,2.2747,0.027191
546,1.3334,2.2786,0.02724
547,1.3347,2.2829,0.027294
548,1.3361,2.287,0.027345
549,1.337,2.2906,0.027389999999999998
550,1.3381,2.2948,0.027442
551,1.3392,2.2987,0.027490999999999998
552,1.3401,2.3025,0.027538999999999998
553,1.341,2.3067,0.027591
554,1.3421,2.3108,0.027643
555,1.3431,2.315,0.027694999999999997
556,1.3441,2.3189,0.027743000000000004
557,1.3447,2.3228,0.027791
558,1.3455,2.3268,0.027842
559,1.3463,2.3306,0.02789
560,1.3469,2.3346,0.02794
561,1.3476,2.3389,0.027993
562,1.3485,2.3429,0.028044
563,1.349,2.3466,0.028089
564,1.3495,2.3508,0.028142
565,1.3499,2.3547,0.028191
566,1.3503,2.3587,0.028239999999999998
567,1.3507,2.3628,0.028291
568,1.351,2.3668,0.028340999999999998
569,1.3512,2.371,0.028394
570,1.3516,2.3748,0.028441
571,1.3514,2.3786,0.028489
572,1.3514,2.3827,0.02854
573,1.3515,2.3867,0.028589000000000003
574,1.3514,2.3905,0.028637000000000003
575,1.3512,2.3949,0.028692000000000002
576,1.3514,2.3991,0.028744000000000002
577,1.351,2.4027,0.02879
578,1.3505,2.4069,0.028842
579,1.3502,2.4108,0.028891
580,1.3496,2.4146,0.028939
581,1.3489,2.4188,0.028991
582,1.3484,2.4228,0.029041
583,1.3477,2.4269,0.029091999999999996
584,1.3469,2.4308,0.029140000000000003
585,1.346,2.4347,0.029189
586,1.3451,2.4388,0.02924
587,1.3441,2.4428,0.029289999999999997
588,1.343,2.4467,0.029338000000000003
589,1.3419,2.4509,0.029390999999999997
590,1.3409,2.455,0.029442
591,1.3396,2.4586,0.029488
592,1.3381,2.4628,0.02954
593,1.3368,2.4667,0.029588999999999997
594,1.3355,2.4706,0.029638
595,1.3341,2.4747,0.029689
596,1.3327,2.4788,0.029740000000000003
597,1.3312,2.483,0.029792
598,1.3298,2.487,0.029842
599,1.3282,2.4908,0.029889000000000002
600,1.3266,2.4949,0.02994
601,1.3251,2.4989,0.029990000000000003
602,1.3234,2.5026,0.030036999999999998
603,1.3218,2.5069,0.03009
604,1.3204,2.5111,0.030143
605,1.3188,2.5147,0.030187
606,1.317,2.5188,0.030239
607,1.3155,2.5228,0.030289999999999997
608,1.3139,2.5267,0.030337999999999997
609,1.3122,2.5308,0.030389
610,1.3108,2.5349,0.030438999999999997
611,1.3093,2.5389,0.03049
612,1.3077,2.5428,0.030539
613,1.3061,2.5467,0.030587
614,1.3045,2.5507,0.030638000000000002
615,1.303,2.5548,0.030688
616,1.3015,2.5586,0.030735000000000002
617,1.2999,2.5628,0.030789
618,1.2985,2.567,0.030840999999999997
619,1.297,2.5707,0.030886999999999998
620,1.2954,2.5749,0.030939
621,1.2941,2.5788,0.030989
622,1.2924,2.5827,0.031037
623,1.2909,2.5867,0.031086999999999997
624,1.2895,2.5908,0.031138
625,1.2881,2.5949,0.031189
626,1.2867,2.5989,0.031239
627,1.2849,2.6027,0.031286999999999995
628,1.2836,2.6068,0.031337000000000004
629,1.2822,2.6109,0.031389
630,1.2807,2.6146,0.031436
631,1.2793,2.6188,0.031488
632,1.278,2.6231,0.031541
633,1.2765,2.6267,0.031585999999999996
634,1.2749,2.6307,0.031636000000000004
635,1.2736,2.6348,0.031687
636,1.2721,2.6387,0.031735
637,1.2705,2.6426,0.031785
638,1.2693,2.6468,0.031837
639,1.2678,2.6509,0.031888
640,1.2666,2.6548,0.031938
641,1.2651,2.6588,0.031987
642,1.2637,2.6628,0.032037
643,1.2623,2.6668,0.032087
644,1.2608,2.6706,0.032134
645,1.2593,2.6748,0.032187
646,1.2582,2.6789,0.032238
647,1.2567,2.6827,0.032285
648,1.2551,2.6868,0.032336000000000004
649,1.2539,2.6908,0.032386
650,1.2525,2.6947,0.032436
651,1.251,2.6988,0.032486
652,1.2495,2.7028,0.032536
653,1.2481,2.7068,0.032586
654,1.2468,2.7108,0.032636
655,1.2452,2.7146,0.032684000000000005
656,1.2436,2.7186,0.032734
657,1.2423,2.7228,0.032787000000000004
658,1.2406,2.7265,0.032832
659,1.239,2.7307,0.032885
660,1.2377,2.735,0.032938999999999996
661,1.2363,2.7387,0.032985
662,1.2343,2.7428,0.033035
663,1.2329,2.7469,0.033087
664,1.2311,2.7508,0.033135
665,1.2291,2.7547,0.033184
666,1.2274,2.7589,0.033236
667,1.2255,2.7628,0.033285999999999996
668,1.2235,2.7668,0.033336000000000005
669,1.2214,2.7707,0.033384
670,1.2193,2.7747,0.033434
671,1.2169,2.7789,0.033485999999999995
672,1.2144,2.7827,0.033533
673,1.2118,2.7868,0.033585
674,1.2093,2.791,0.033637
675,1.2062,2.7947,0.033684
676,1.2027,2.7988,0.033734
677,1.1991,2.8028,0.033784999999999996
678,1.1948,2.8067,0.033834
679,1.1897,2.8106,0.033883
680,1.1835,2.8148,0.033935
681,1.1758,2.8189,0.033986
682,1.1652,2.823,0.034037000000000005
683,1.1499,2.8269,0.034085000000000004
684,1.1255,2.8308,0.034135
685,1.0821,2.835,0.034186999999999995
686,0.9884,2.8388,0.034234
687,0.6098,2.8433,0.034291