File: Datasets/aluminum.csv
Time,Displacement,Force,Strain 1
(s),(mm),(kN),(mm/mm)
0,0,-0.1464,0.00003148
0.5,0.03,-0.08326,0.00005747
1,0.06,0.3626,0.0002286
1.5,0.09,0.9086,0.0004268
2,0.13,1.311,0.0005831
2.5,0.16,1.611,0.0007018
3,0.19,1.859,0.000794
3.5,0.23,2.069,0.0008832
4,0.26,2.25,0.0009524
4.5,0.29,2.414,0.001016
5,0.33,2.558,0.001081
5.5,0.36,2.679,0.00113
6,0.39,2.793,0.001174
6.5,0.43,2.9,0.00122
7,0.46,3.013,0.00127
7.5,0.49,3.125,0.001314
8,0.53,3.239,0.001359
8.5,0.56,3.353,0.001406
9,0.59,3.478,0.00145
9.5,0.63,3.601,0.001498
10,0.66,3.733,0.001551
10.5,0.69,3.865,0.001598
11,0.73,4.007,0.00165
11.5,0.76,4.154,0.001707
12,0.79,4.307,0.001767
12.5,0.83,4.462,0.001821
13,0.86,4.626,0.001885
13.5,0.89,4.797,0.001949
14,0.93,4.97,0.002013
14.5,0.96,5.146,0.002082
15,0.99,5.327,0.002153
15.5,1.03,5.51,0.002222
16,1.06,5.702,0.002294
16.5,1.09,5.89,0.002369
17,1.13,6.083,0.002436
17.5,1.16,6.273,0.00251
18,1.19,6.46,0.002584
18.5,1.23,6.644,0.002647
19,1.26,6.82,0.002719
19.5,1.29,6.99,0.002786
20,1.33,7.16,0.002851
20.5,1.36,7.333,0.002914
21,1.39,7.506,0.002989
21.5,1.43,7.684,0.003059
22,1.46,7.866,0.003128
22.5,1.49,8.048,0.003196
23,1.53,8.235,0.003274
23.5,1.56,8.423,0.003352
24,1.59,8.612,0.003424
24.5,1.63,8.803,0.003502
25,1.66,8.992,0.003587
25.5,1.69,9.181,0.003691
26,1.73,9.362,0.003831
26.5,1.76,9.524,0.004009
27,1.79,9.666,0.004247
27.5,1.83,9.783,0.004573
28,1.86,9.874,0.004991
28.5,1.89,9.947,0.005484
29,1.93,10,0.006043
29.5,1.96,10.05,0.006652
30,1.99,10.09,0.007317
30.5,2.03,10.13,0.008009
31,2.06,10.16,0.008723
31.5,2.09,10.18,0.009464
32,2.13,10.21,0.01022
32.5,2.16,10.23,0.01099
33,2.19,10.26,0.01175
33.5,2.23,10.28,0.01251
34,2.26,10.3,0.0133
34.5,2.29,10.33,0.01407
35,2.33,10.34,0.01484
35.5,2.36,10.37,0.01561
36,2.39,10.39,0.01637
36.5,2.43,10.41,0.01715
37,2.46,10.43,0.01791
37.5,2.49,10.45,0.01868
38,2.53,10.47,0.01943
38.5,2.56,10.49,0.0202
39,2.59,10.52,0.02097
39.5,2.63,10.53,0.02172
40,2.66,10.56,0.02248
40.5,2.69,10.58,0.02323
41,2.73,10.59,0.02398
41.5,2.76,10.62,0.02474
42,2.79,10.64,0.02548
42.5,2.83,10.66,0.02622
43,2.86,10.68,0.02698
43.5,2.89,10.69,0.02773
44,2.93,10.71,0.02847
44.5,2.96,10.73,0.02921
45,2.99,10.75,0.02994
45.5,3.03,10.77,0.03069
46,3.06,10.79,0.03145
46.5,3.09,10.81,0.03219
47,3.13,10.83,0.03293
47.5,3.16,10.85,0.03366
48,3.19,10.87,0.03441
48.5,3.23,10.89,0.03515
49,3.26,10.9,0.03589
49.5,3.29,10.92,0.03663
50,3.33,10.94,0.03737
50.5,3.36,10.96,0.03811
51,3.39,10.98,0.03886
51.5,3.43,10.99,0.03959
52,3.46,11.01,0.04033
52.5,3.49,11.03,0.04108
53,3.53,11.05,0.04182
53.5,3.56,11.06,0.04255
54,3.59,11.08,0.04329
54.5,3.63,11.1,0.04404
55,3.66,11.11,0.04478
55.5,3.69,11.13,0.04553
56,3.73,11.15,0.04627
56.5,3.76,11.16,0.047
57,3.79,11.18,0.04775
57.5,3.83,11.19,0.0485
58,3.86,11.2,0.04925
58.5,3.89,11.22,0.04999
59,3.93,11.24,0.05074
59.5,3.96,11.25,0.05149
60,3.99,11.26,0.05223
60.5,4.03,11.28,0.05299
61,4.06,11.29,0.05373
61.5,4.09,11.31,0.05449
62,4.13,11.32,0.05525
62.5,4.16,11.33,0.05601
63,4.19,11.35,0.05677
63.5,4.23,11.36,0.05752
64,4.26,11.37,0.05828
64.5,4.29,11.39,0.05905
65,4.33,11.4,0.05981
65.5,4.36,11.41,0.06058
66,4.39,11.42,0.06135
66.5,4.43,11.43,0.06212
67,4.46,11.45,0.06289
67.5,4.49,11.46,0.06366
68,4.53,11.47,0.06443
68.5,4.56,11.48,0.06522
69,4.59,11.49,0.06599
69.5,4.63,11.5,0.06677
70,4.66,11.51,0.06755
70.5,4.69,11.52,0.06835
71,4.73,11.53,0.06913
71.5,4.76,11.54,0.06993
72,4.79,11.54,0.07072
72.5,4.83,11.55,0.07151
73,4.86,11.56,0.07231
73.5,4.89,11.57,0.07311
74,4.93,11.58,0.07392
74.5,4.96,11.59,0.07472
75,4.99,11.59,0.07553
75.5,5.03,11.61,0.07634
76,5.06,11.61,0.07715
76.5,5.09,11.62,0.07796
77,5.13,11.62,0.07878
77.5,5.16,11.63,0.0796
78,5.19,11.64,0.08043
78.5,5.23,11.64,0.08126
79,5.26,11.65,0.08209
79.5,5.29,11.65,0.08293
80,5.33,11.66,0.08376
80.5,5.36,11.66,0.0846
81,5.39,11.67,0.08544
81.5,5.43,11.68,0.0863
82,5.46,11.68,0.08715
82.5,5.49,11.68,0.08801
83,5.53,11.69,0.08886
83.5,5.56,11.69,0.08972
84,5.59,11.7,0.09059
84.5,5.63,11.7,0.09147
85,5.66,11.7,0.09235
85.5,5.69,11.71,0.09323
86,5.73,11.71,0.09412
86.5,5.76,11.71,0.09502
87,5.79,11.71,0.09592
87.5,5.83,11.72,0.09682
88,5.86,11.72,0.09772
88.5,5.89,11.72,0.09865
89,5.93,11.72,0.09956
89.5,5.96,11.72,0.1005
90,5.99,11.73,0.1014
90.5,6.03,11.73,0.1024
91,6.06,11.73,0.1033
91.5,6.09,11.73,0.1043
92,6.13,11.73,0.1052
92.5,6.16,11.73,0.1062
93,6.19,11.73,0.1071
93.5,6.23,11.73,0.1081
94,6.26,11.73,0.1091
94.5,6.29,11.73,0.1101
95,6.33,11.72,0.1111
95.5,6.36,11.72,0.1121
96,6.39,11.72,0.1131
96.5,6.43,11.72,0.1141
97,6.46,11.71,0.1151
97.5,6.49,11.71,0.1162
98,6.53,11.71,0.1172
98.5,6.56,11.7,0.1183
99,6.59,11.7,0.1193
99.5,6.63,11.69,0.1204
100,6.66,11.68,0.1215
100.5,6.69,11.67,0.1225
101,6.73,11.67,0.1236
101.5,6.76,11.66,0.1247
102,6.79,11.65,0.1258
102.5,6.83,11.64,0.1269
103,6.86,11.62,0.128
103.5,6.89,11.61,0.1291
104,6.93,11.6,0.1303
104.5,6.96,11.59,0.1314
105,6.99,11.57,0.1326
105.5,7.03,11.55,0.1337
106,7.06,11.53,0.1349
106.5,7.09,11.51,0.1361
107,7.13,11.49,0.1372
107.5,7.16,11.47,0.1384
108,7.19,11.45,0.1396
108.5,7.23,11.43,0.1408
109,7.26,11.4,0.1421
109.5,7.29,11.38,0.1433
110,7.33,11.36,0.1445
110.5,7.36,11.33,0.1457
111,7.39,11.3,0.147
111.5,7.43,11.27,0.1482
112,7.46,11.24,0.1495
112.5,7.49,11.22,0.1508
113,7.53,11.18,0.152
113.5,7.56,11.15,0.1533
114,7.59,11.12,0.1546
114.5,7.63,11.09,0.1558
115,7.66,11.05,0.1571
115.5,7.69,11.02,0.1584
116,7.73,10.98,0.1597
116.5,7.76,10.95,0.161
117,7.79,10.91,0.1623
117.5,7.83,10.87,0.1637
118,7.86,10.83,0.165
118.5,7.89,10.8,0.1663
119,7.93,10.75,0.1676
119.5,7.96,10.71,0.169
120,7.99,10.67,0.1703
120.5,8.03,10.63,0.1716
121,8.06,10.59,0.173
121.5,8.09,10.54,0.1743
122,8.13,10.5,0.1757
122.5,8.16,10.46,0.177
123,8.19,10.41,0.1784
123.5,8.23,10.36,0.1797
124,8.26,10.32,0.1811
124.5,8.29,10.27,0.1825
125,8.33,10.22,0.1838
125.5,8.36,10.17,0.1852
126,8.39,10.12,0.1866
126.5,8.43,10.07,0.1879
127,8.46,10.02,0.1893
127.5,8.49,9.969,0.1907
128,8.53,9.919,0.192
128.5,8.56,9.866,0.1934
129,8.59,9.814,0.1948
129.5,8.63,9.758,0.1962
130,8.66,9.704,0.1976
130.5,8.69,9.647,0.199
131,8.73,9.592,0.2003
131.5,8.76,9.532,0.2017
132,8.79,9.476,0.2031
132.5,8.83,9.417,0.2045
133,8.86,9.357,0.2059
133.5,8.89,9.295,0.2073
134,8.93,9.236,0.2087
134.5,8.96,9.172,0.2101
135,8.99,9.112,0.2115
135.5,9.03,9.048,0.2129
136,9.06,8.981,0.2143
136.5,9.09,8.915,0.2157
137,9.13,8.849,0.2172
137.5,9.16,8.782,0.2185
138,9.19,8.715,0.22
138.5,9.23,8.645,0.2214
139,9.26,8.573,0.2228
139.5,9.29,8.503,0.2242
140,9.33,8.431,0.2256
140.5,9.36,8.357,0.2271
141,9.39,8.284,0.2285
141.5,9.43,8.209,0.2299
142,9.46,8.13,0.2313
142.5,9.49,8.054,0.2328
143,9.53,7.973,0.2342
143.5,9.56,7.894,0.2356
144,9.59,7.811,0.2371
144.5,9.63,7.725,0.2385
145,9.66,7.637,0.24
145.5,9.69,7.543,0.2414
146,9.73,5.137,0.2466
146.03,9.73,4.179,0.2509