File: Datasets/brass.csv
Time,Displacement,Force,Strain 1
(s),(mm),(kN),(mm/mm)
0,0,0.72,-0.00001475
0.5,0.03,1.29,0.00009344
1,0.07,1.731,0.0002092
1.5,0.1,2.181,0.0003325
2,0.13,2.634,0.0004623
2.5,0.17,3.095,0.0005842
3,0.2,3.576,0.0007269
3.5,0.23,4.056,0.0008942
4,0.27,4.53,0.001067
4.5,0.3,5.001,0.001254
4.5,0.3,5.003,0.001256
4.6,0.31,5.086,0.001269
5.1,0.27,4.172,0.001097
5.6,0.24,3.218,0.0008498
6.1,0.21,2.37,0.0006255
6.6,0.17,1.767,0.0004578
7.1,0.14,1.418,0.000357
7.6,0.11,1.107,0.0002518
7.79,0.09,1,0.0002189
7.79,0.09,0.9992,0.0002188
7.79,0.09,0.9982,0.0002188
8.29,0.13,1.824,0.0003943
8.79,0.16,2.685,0.0006015
9.29,0.19,3.24,0.0007436
9.79,0.23,3.762,0.0009011
10.29,0.26,4.295,0.00104
10.79,0.29,4.826,0.001211
11.29,0.33,5.343,0.001385
11.79,0.36,5.794,0.001601
12.29,0.39,6.156,0.001899
12.79,0.43,6.291,0.002572
13.29,0.46,6.352,0.003416
13.79,0.49,6.399,0.004063
14.29,0.53,6.451,0.004714
14.79,0.56,6.499,0.005372
15.29,0.59,6.555,0.00602
15.79,0.63,6.616,0.006676
16.29,0.66,6.671,0.007332
16.79,0.69,6.73,0.007983
17.29,0.73,6.789,0.008645
17.79,0.76,6.844,0.009278
18.29,0.79,6.902,0.00992
18.79,0.83,6.957,0.01057
19.29,0.86,7.01,0.0112
19.79,0.89,7.067,0.01183
20.29,0.93,7.12,0.01247
20.79,0.96,7.17,0.01311
21.29,0.99,7.225,0.01375
21.79,1.03,7.271,0.01436
22.29,1.06,7.321,0.01498
22.79,1.09,7.371,0.0156
23.29,1.13,7.417,0.01622
23.79,1.16,7.465,0.01684
24.29,1.19,7.514,0.01745
24.79,1.23,7.557,0.01807
25.29,1.26,7.601,0.01869
25.79,1.29,7.647,0.01931
26.29,1.33,7.69,0.01992
26.36,1.33,7.695,0.02
26.37,1.33,7.695,0.02
26.44,1.34,7.706,0.0201
26.94,1.3,6.775,0.02006
27.44,1.27,5.871,0.01979
27.94,1.24,5.014,0.01954
28.44,1.2,4.21,0.01929
28.94,1.17,3.481,0.01903
29.44,1.14,2.953,0.01884
29.94,1.1,2.618,0.01871
30.44,1.07,2.3,0.0186
30.94,1.04,1.982,0.01845
31.44,1,1.684,0.01832
31.94,0.97,1.389,0.01818
32.44,0.94,1.111,0.01805
32.66,0.92,0.9993,0.018
32.66,0.92,0.9985,0.018
32.66,0.92,0.9976,0.018
33.16,0.95,1.828,0.01815
33.66,0.99,2.682,0.01836
34.16,1.02,3.294,0.01853
34.66,1.06,3.805,0.01869
35.16,1.09,4.32,0.01885
35.66,1.12,4.844,0.01903
36.16,1.16,5.349,0.0192
36.66,1.19,5.825,0.01935
37.16,1.22,6.293,0.01952
37.66,1.26,6.724,0.01972
38.16,1.29,7.11,0.01986
38.66,1.32,7.474,0.02005
39.16,1.36,7.751,0.0203
39.66,1.39,7.824,0.02075
40.16,1.42,7.836,0.02137
40.66,1.46,7.858,0.02205
41.16,1.49,7.896,0.02271
41.66,1.52,7.934,0.02336
42.16,1.56,7.971,0.024
42.66,1.59,8.014,0.02462
43.16,1.62,8.053,0.02526
43.66,1.66,8.092,0.02587
44.16,1.69,8.135,0.02651
44.66,1.72,8.172,0.02713
45.16,1.76,8.21,0.02775
45.66,1.79,8.251,0.02838
46.16,1.82,8.287,0.02899
46.66,1.86,8.326,0.02962
47.16,1.89,8.365,0.03024
47.66,1.92,8.398,0.03086
48.16,1.96,8.436,0.03148
48.66,1.99,8.476,0.03211
49.16,2.02,8.509,0.03273
49.66,2.06,8.544,0.03335
50.16,2.09,8.58,0.03397
50.66,2.12,8.614,0.03458
51.16,2.16,8.65,0.03521
51.66,2.19,8.684,0.03584
52.16,2.22,8.716,0.03645
52.66,2.26,8.754,0.03708
53.16,2.29,8.788,0.03771
53.66,2.32,8.818,0.03832
54.16,2.36,8.856,0.03896
54.66,2.39,8.887,0.03958
55.16,2.42,8.918,0.0402
55.66,2.46,8.953,0.04082
56.16,2.49,8.983,0.04144
56.66,2.52,9.017,0.04205
57.16,2.56,9.05,0.04268
57.66,2.59,9.078,0.04331
58.16,2.62,9.113,0.04393
58.66,2.66,9.145,0.04455
59.16,2.69,9.173,0.04516
59.66,2.72,9.207,0.04579
60.16,2.76,9.237,0.04642
60.66,2.79,9.267,0.04703
61.16,2.82,9.301,0.04767
61.66,2.86,9.33,0.04829
62.16,2.89,9.359,0.04889
62.66,2.92,9.391,0.04953
63.16,2.96,9.419,0.05016
63.66,2.99,9.448,0.05078
64.16,3.02,9.48,0.05141
64.66,3.06,9.507,0.05204
65.16,3.09,9.536,0.05267
65.66,3.12,9.568,0.0533
66.16,3.16,9.594,0.05393
66.66,3.19,9.623,0.05454
67.16,3.22,9.652,0.05517
67.66,3.26,9.678,0.0558
68.16,3.29,9.705,0.05641
68.66,3.32,9.733,0.05703
69.16,3.36,9.76,0.05767
69.66,3.39,9.789,0.05829
70.16,3.42,9.816,0.05892
70.66,3.46,9.841,0.05955
71.16,3.49,9.871,0.06019
71.66,3.52,9.897,0.06081
72.16,3.56,9.921,0.06144
72.66,3.59,9.95,0.06207
73.16,3.62,9.975,0.06269
73.66,3.66,10,0.06332
74.16,3.69,10.03,0.06394
74.66,3.72,10.05,0.06458
75.16,3.76,10.08,0.0652
75.66,3.79,10.11,0.06584
76.16,3.82,10.13,0.06647
76.66,3.85,10.15,0.06709
77.16,3.89,10.18,0.06772
77.66,3.92,10.21,0.06835
78.16,3.96,10.23,0.06898
78.66,3.99,10.26,0.06963
79.16,4.02,10.28,0.07025
79.66,4.06,10.31,0.07088
80.16,4.09,10.33,0.07149
80.66,4.12,10.36,0.07211
81.16,4.16,10.38,0.07275
81.66,4.19,10.41,0.07338
82.16,4.22,10.43,0.07401
82.66,4.26,10.46,0.07466
83.16,4.29,10.48,0.07528
83.66,4.32,10.51,0.0759
84.16,4.36,10.53,0.07654
84.66,4.39,10.55,0.07716
85.16,4.42,10.58,0.07778
85.66,4.46,10.6,0.07844
86.16,4.49,10.62,0.07906
86.66,4.52,10.65,0.07968
86.92,4.54,10.66,0.08
86.92,4.54,10.66,0.08
86.98,4.54,10.66,0.08008
87.48,4.51,9.76,0.0801
87.98,4.48,8.914,0.07994
88.48,4.44,8.141,0.07969
88.98,4.41,7.373,0.07944
89.48,4.38,6.646,0.07918
89.98,4.34,5.941,0.07892
90.48,4.31,5.247,0.07864
90.98,4.28,4.617,0.07838
91.48,4.24,4.154,0.07817
91.98,4.21,3.816,0.07802
92.48,4.18,3.55,0.07789
92.98,4.14,3.297,0.07779
93.48,4.11,3.057,0.07768
93.98,4.08,2.826,0.07758
94.48,4.04,2.592,0.07745
94.98,4.01,2.373,0.07736
95.48,3.98,2.16,0.07723
95.98,3.94,1.952,0.07713
96.48,3.91,1.752,0.07701
96.98,3.88,1.531,0.07691
97.48,3.84,1.288,0.07678
97.98,3.81,1.057,0.07666
98.1,3.8,0.9993,0.07663
98.1,3.8,0.9984,0.07663
98.11,3.8,0.9975,0.07663
98.61,3.83,1.772,0.0767
99.11,3.87,2.562,0.07684
99.61,3.9,3.267,0.07707
100.11,3.94,3.731,0.07722
100.61,3.97,4.141,0.07736
101.11,4,4.538,0.0775
101.61,4.04,4.929,0.07764
102.11,4.07,5.327,0.07777
102.61,4.1,5.724,0.0779
103.11,4.14,6.119,0.07804
103.61,4.17,6.525,0.07819
104.11,4.2,6.913,0.07833
104.61,4.24,7.296,0.07848
105.11,4.27,7.681,0.07864
105.61,4.3,8.064,0.0788
106.11,4.34,8.437,0.07895
106.61,4.37,8.807,0.07911
107.11,4.4,9.166,0.07928
107.61,4.44,9.518,0.07943
108.11,4.47,9.86,0.07961
108.61,4.5,10.18,0.07978
109.11,4.54,10.46,0.07995
109.61,4.57,10.71,0.08015
110.11,4.6,10.86,0.08042
110.61,4.64,10.84,0.08077
111.11,4.67,10.81,0.08106
111.61,4.7,10.79,0.08135
112.11,4.74,10.79,0.08186
112.61,4.77,10.79,0.08268
113.11,4.8,10.79,0.08373
113.61,4.84,10.81,0.08483
114.11,4.87,10.85,0.0859
114.61,4.9,10.88,0.08688
115.11,4.94,10.9,0.08769
115.61,4.97,10.91,0.08826
116.11,5,10.92,0.08857
116.61,5.04,10.97,0.08884
117.11,5.07,10.99,0.08921
117.61,5.1,11.01,0.08983
118.11,5.14,11.02,0.09068
118.61,5.17,11.05,0.0916
119.11,5.2,11.08,0.09248
119.61,5.24,11.1,0.09326
120.11,5.27,11.12,0.09386
120.61,5.3,11.13,0.09428
121.11,5.34,11.17,0.09462
121.61,5.37,11.19,0.09504
122.11,5.4,11.21,0.09564
122.61,5.44,11.22,0.09643
123.11,5.47,11.24,0.09733
123.61,5.5,11.27,0.09822
124.11,5.54,11.3,0.09904
124.61,5.57,11.32,0.0997
125.11,5.6,11.33,0.1001
125.61,5.64,11.35,0.1004
126.11,5.67,11.38,0.1008
126.61,5.7,11.41,0.1012
127.11,5.74,11.42,0.1018
127.61,5.77,11.43,0.1027
128.11,5.8,11.45,0.1037
128.61,5.84,11.48,0.1047
129.11,5.87,11.51,0.1056
129.61,5.9,11.53,0.1064
130.11,5.94,11.54,0.1069
130.61,5.97,11.54,0.1072
131.11,6,11.57,0.1074
131.61,6.04,11.61,0.1076
132.11,6.07,11.64,0.1079
132.61,6.1,11.66,0.1083
133.11,6.14,11.67,0.109
133.61,6.17,11.67,0.11
134.11,6.2,11.67,0.111
134.61,6.24,11.7,0.1122
135.11,6.27,11.76,0.1132
135.61,6.3,11.79,0.1142
136.11,6.34,11.8,0.115
136.61,6.37,11.81,0.1157
137.11,6.4,11.79,0.1161
137.61,6.44,11.82,0.1163
138.11,6.47,11.81,0.1165
138.61,6.5,11.87,0.1167
139.11,6.54,11.91,0.117
139.61,6.57,11.93,0.1174
140.11,6.6,11.95,0.1177
140.61,6.64,11.97,0.1182
141.11,6.67,11.98,0.1191
141.61,6.7,11.98,0.1201
142.11,6.74,11.98,0.1212
142.61,6.77,11.98,0.1224
143.11,6.8,12.06,0.1235
143.61,6.84,12.11,0.1245
144.11,6.87,12.13,0.1254
144.61,6.9,12.13,0.1261
145.11,6.94,12.13,0.1266
145.61,6.97,12.12,0.1269
146.11,7,12.09,0.1272
146.61,7.04,12.14,0.1277
147.11,7.07,12.15,0.128
147.61,7.1,12.21,0.1282
148.11,7.14,12.25,0.1286
148.61,7.17,12.26,0.1291
149.11,7.2,12.28,0.1297
149.61,7.24,12.29,0.1304
150.11,7.27,12.29,0.1309
150.61,7.3,12.32,0.1314
151.11,7.34,12.32,0.1323
151.61,7.37,12.31,0.1334
152.11,7.4,12.32,0.1345
152.61,7.44,12.39,0.1356
153.11,7.47,12.44,0.1366
153.61,7.5,12.45,0.1376
154.11,7.54,12.45,0.1384
154.61,7.57,12.45,0.1389
155.11,7.6,12.42,0.1391
155.61,7.64,12.49,0.1393
156.11,7.67,12.49,0.1398
156.61,7.7,12.47,0.1407
157.11,7.74,12.5,0.1412
157.61,7.77,12.49,0.1413
158.11,7.8,12.56,0.1414
158.61,7.84,12.63,0.1415
159.11,7.87,12.66,0.1418
159.61,7.9,12.63,0.1425
160.11,7.94,12.64,0.1436
160.61,7.97,12.66,0.1447
161.11,8,12.66,0.1458
161.61,8.04,12.66,0.147
162.11,8.07,12.68,0.1482
162.61,8.1,12.68,0.1493
163.11,8.14,12.69,0.1501
163.61,8.17,12.72,0.1505
164.11,8.2,12.69,0.1506
164.61,8.24,12.77,0.1507
165.11,8.27,12.85,0.1508
165.61,8.3,12.89,0.1509
166.11,8.34,12.89,0.1513
166.61,8.37,12.89,0.1521
167.11,8.4,12.89,0.1529
167.61,8.44,12.88,0.1535
168.11,8.47,12.88,0.154
168.61,8.5,12.88,0.1543
169.11,8.54,12.88,0.1547
169.61,8.57,12.88,0.1553
170.11,8.6,12.89,0.1562
170.61,8.64,12.9,0.1574
171.11,8.67,12.88,0.1586
171.61,8.7,12.96,0.1598
172.11,8.74,13.01,0.1609
172.61,8.77,13.04,0.1621
173.11,8.8,13.07,0.1632
173.61,8.84,13.08,0.1643
174.11,8.87,13.09,0.1651
174.61,8.9,13.09,0.1658
175.11,8.94,13.1,0.1662
175.61,8.97,13.08,0.1664
176.11,9,13.14,0.1666
176.61,9.04,13.13,0.1673
177.11,9.07,13.13,0.1681
177.61,9.1,13.13,0.1685
178.11,9.14,13.12,0.1686
178.61,9.17,13.06,0.1687
179.11,9.2,13.16,0.1687
179.61,9.24,13.24,0.1687
180.11,9.27,13.29,0.1688
180.61,9.3,13.33,0.169
181.11,9.34,13.33,0.1694
181.61,9.37,13.32,0.1702
182.11,9.4,13.31,0.1714
182.61,9.44,13.31,0.1725
183.11,9.47,13.3,0.1737
183.61,9.5,13.28,0.1749
184.11,9.54,13.27,0.1762
184.61,9.57,13.29,0.1774
185.11,9.6,13.31,0.1786
185.61,9.64,13.33,0.1796
186.11,9.67,13.34,0.1803
186.61,9.7,13.35,0.1806
187.11,9.74,13.35,0.1807
187.61,9.77,13.37,0.1808
188.11,9.8,13.45,0.1808
188.61,9.84,13.51,0.1809
189.11,9.87,13.54,0.181
189.61,9.9,13.54,0.1814
190.11,9.94,13.55,0.1822
190.61,9.97,13.54,0.1833
191.11,10,13.53,0.1845
191.61,10.04,13.53,0.1856
192.11,10.07,13.54,0.1868
192.61,10.1,13.56,0.188
193.11,10.14,13.57,0.1892
193.61,10.17,13.57,0.1904
194.11,10.2,13.57,0.1916
194.61,10.24,13.59,0.1927
195.11,10.27,13.59,0.1934
195.61,10.3,13.58,0.1938
196.11,10.34,13.57,0.1939
196.61,10.37,13.52,0.1939
197.11,10.4,13.57,0.1939
197.61,10.44,13.67,0.1939
198.11,10.47,13.72,0.194
198.61,10.5,13.76,0.194
199.11,10.54,13.79,0.1942
199.61,10.57,13.8,0.1947
200.11,10.6,13.8,0.1956
200.61,10.64,13.8,0.1967
201.11,10.67,13.8,0.1978
201.61,10.7,13.8,0.1989
202.11,10.74,13.8,0.2
202.61,10.77,13.78,0.2011
203.11,10.8,13.78,0.2022
203.61,10.84,13.77,0.2033
204.11,10.87,13.78,0.2044
204.61,10.9,13.79,0.2054
205.11,10.94,13.79,0.2064
205.61,10.97,13.78,0.207
206.11,11,13.78,0.2074
206.61,11.04,13.67,0.2076
207.11,11.07,13.74,0.2077
207.61,11.1,13.82,0.2078
208.11,11.14,13.87,0.208
208.61,11.17,13.92,0.2082
209.11,11.2,13.95,0.2085
209.61,11.24,13.98,0.2089
210.11,11.27,13.99,0.2095
210.61,11.3,14.01,0.2104
211.11,11.34,14.01,0.2115
211.61,11.37,14.02,0.2126
212.11,11.4,14.02,0.2138
212.61,11.44,14.03,0.215
213.11,11.47,14.04,0.2162
213.61,11.5,14.05,0.2174
214.11,11.54,14.06,0.2186
214.61,11.57,14.06,0.2198
215.11,11.6,14.06,0.221
215.61,11.64,14.06,0.2222
216.11,11.67,14.06,0.2231
216.61,11.7,14.05,0.2237
217.11,11.74,14.04,0.2239
217.61,11.77,14.02,0.224
218.11,11.8,14,0.224
218.61,11.84,13.98,0.224
219.11,11.87,14.09,0.224
219.61,11.9,14.16,0.2241
220.11,11.94,14.19,0.2241
220.61,11.97,14.22,0.2242
221.11,12,14.24,0.2244
221.61,12.04,14.26,0.2249
222.11,12.07,14.27,0.2257
222.61,12.1,14.27,0.2267
223.11,12.14,14.28,0.2278
223.61,12.17,14.28,0.229
224.11,12.2,14.28,0.2301
224.61,12.24,14.28,0.2313
225.11,12.27,14.27,0.2325
225.61,12.3,14.26,0.2337
226.11,12.34,14.26,0.2349
226.61,12.37,14.25,0.2361
227.11,12.4,14.25,0.2373
227.61,12.44,14.25,0.2386
228.11,12.47,14.23,0.2397
228.61,12.5,14.21,0.2406
229.11,12.54,14.19,0.241
229.61,12.57,14.17,0.2412
230.11,12.6,14.18,0.2413
230.61,12.64,14.18,0.2413
231.11,12.67,14.19,0.2413
231.61,12.7,14.28,0.2414
232.11,12.74,14.33,0.2414
232.61,12.77,14.35,0.2414
233.11,12.8,14.37,0.2416
233.61,12.84,14.39,0.242
234.11,12.87,14.41,0.2427
234.61,12.9,14.44,0.2436
235.11,12.94,14.45,0.2446
235.61,12.97,14.46,0.2457
236.11,13,14.47,0.2469
236.61,13.04,14.47,0.2481
237.11,13.07,14.48,0.2493
237.61,13.1,14.49,0.2505
238.11,13.14,14.49,0.2517
238.61,13.17,14.5,0.2529
239.11,13.2,14.51,0.2541
239.61,13.24,14.51,0.2553
240.11,13.27,14.51,0.2565
240.61,13.3,14.51,0.2578
241.11,13.33,14.5,0.259
241.61,13.37,14.5,0.2602
242.11,13.4,14.5,0.2611
242.61,13.44,14.49,0.2618
243.11,13.47,14.48,0.2621
243.61,13.5,14.46,0.2622
244.11,13.54,14.44,0.2622
244.61,13.57,14.44,0.2623
245.11,13.6,14.44,0.2623
245.61,13.64,14.48,0.2623
246.11,13.67,14.58,0.2623
246.61,13.7,14.6,0.2624
247.11,13.74,14.62,0.2624
247.61,13.77,14.64,0.2624
248.11,13.8,14.66,0.2627
248.61,13.84,14.68,0.2631
249.11,13.87,14.69,0.2639
249.61,13.9,14.69,0.2648
250.11,13.94,14.7,0.2659
250.61,13.97,14.71,0.2671
251.11,14,14.71,0.2682
251.61,14.04,14.71,0.2694
252.11,14.07,14.71,0.2706
252.61,14.1,14.71,0.2718
253.11,14.14,14.71,0.2731
253.61,14.17,14.7,0.2743
254.11,14.2,14.7,0.2755
254.61,14.24,14.7,0.2767
255.11,14.27,14.69,0.278
255.61,14.3,14.68,0.2792
256.11,14.34,14.68,0.2805
256.61,14.37,14.67,0.2817
257.11,14.4,14.66,0.2829
257.61,14.44,14.64,0.2839
258.11,14.47,14.62,0.2846
258.61,14.5,14.61,0.2849
259.11,14.54,14.59,0.2851
259.61,14.57,14.57,0.2851
260.11,14.6,14.57,0.2851
260.61,14.63,14.55,0.2851
261.11,14.67,14.59,0.2852
261.61,14.7,14.67,0.2852
262.11,14.74,14.7,0.2852
262.61,14.77,14.72,0.2853
263.11,14.8,14.74,0.2853
263.61,14.84,14.76,0.2855
264.11,14.87,14.77,0.2858
264.61,14.9,14.79,0.2863
265.11,14.94,14.8,0.2871
265.61,14.97,14.82,0.288
266.11,15,14.83,0.2891
266.61,15.04,14.84,0.2902
267.11,15.07,14.85,0.2914
267.61,15.1,14.86,0.2926
268.11,15.14,14.86,0.2939
268.61,15.17,14.87,0.2951
269.11,15.2,14.87,0.2963
269.61,15.24,14.88,0.2975
270.11,15.27,14.88,0.2987
270.61,15.3,14.89,0.3
271.11,15.34,14.89,0.3012
271.61,15.37,14.9,0.3025
272.11,15.4,14.89,0.3037
272.61,15.44,14.9,0.3049
273.11,15.47,14.9,0.3062
273.61,15.5,14.9,0.3075
274.11,15.54,14.9,0.3087
274.61,15.57,14.89,0.31
275.11,15.6,14.89,0.3112
275.61,15.64,14.89,0.3123
276.11,15.67,14.88,0.3132
276.61,15.7,14.87,0.3138
277.11,15.74,14.86,0.3141
277.61,15.77,14.85,0.3143
278.11,15.8,14.84,0.3144
278.61,15.84,14.83,0.3144
279.11,15.87,14.83,0.3144
279.61,15.9,14.84,0.3145
280.11,15.94,14.87,0.3145
280.61,15.97,14.88,0.3145
281.11,16,14.98,0.3145
281.61,16.04,14.98,0.3145
282.11,16.07,14.97,0.3146
282.61,16.1,14.97,0.3146
283.11,16.14,14.99,0.3147
283.61,16.17,14.99,0.315
284.11,16.2,15,0.3155
284.61,16.24,15.01,0.3163
285.11,16.27,15.01,0.3172
285.61,16.3,15.02,0.3182
286.11,16.34,15.02,0.3194
286.61,16.37,15.02,0.3206
287.11,16.4,15.03,0.3218
287.61,16.44,15.03,0.3231
288.11,16.47,15.03,0.3243
288.61,16.5,15.03,0.3256
289.11,16.54,15.03,0.3269
289.61,16.57,15.03,0.3281
290.11,16.6,15.03,0.3294
290.61,16.64,15.03,0.3306
291.11,16.67,15.03,0.3319
291.61,16.7,15.02,0.3332
292.11,16.74,15.02,0.3344
292.61,16.77,15.02,0.3357
293.11,16.8,15.02,0.337
293.61,16.84,15.01,0.3383
294.11,16.87,15.01,0.3396
294.61,16.9,15.01,0.3408
295.11,16.94,15,0.3421
295.61,16.97,15,0.3434
296.11,17,14.99,0.3447
296.61,17.04,14.98,0.3459
297.11,17.07,14.98,0.3469
297.61,17.1,14.97,0.3477
298.11,17.14,14.95,0.3483
298.61,17.17,14.94,0.3487
299.11,17.2,14.93,0.3489
299.61,17.24,14.92,0.349
300.11,17.27,14.91,0.349
300.61,17.3,14.9,0.349
301.11,17.34,14.91,0.349
301.61,17.37,14.93,0.3491
302.11,17.4,14.95,0.3491
302.61,17.44,14.98,0.3491
303.11,17.47,15.05,0.3491
303.61,17.5,15.02,0.3491
304.11,17.54,15.01,0.3491
304.61,17.57,15.01,0.3492
305.11,17.6,15.02,0.3493
305.61,17.64,15.03,0.3496
306.11,17.67,15.03,0.35
306.61,17.7,15.04,0.3505
307.11,17.74,15.05,0.3511
307.61,17.77,15.05,0.3519
308.11,17.8,15.06,0.3528
308.61,17.84,15.06,0.3538
309.11,17.87,15.06,0.3549
309.61,17.9,15.07,0.356
310.11,17.94,15.07,0.3572
310.61,17.97,15.07,0.3584
311.11,18,15.08,0.3597
311.61,18.04,15.08,0.3609
312.11,18.07,15.08,0.3622
312.61,18.1,15.09,0.3634
313.11,18.14,15.09,0.3647
313.61,18.17,15.09,0.366
314.11,18.2,15.09,0.3673
314.61,18.24,15.09,0.3685
315.11,18.27,15.09,0.3698
315.61,18.3,15.1,0.3711
316.11,18.34,15.1,0.3724
316.61,18.37,15.1,0.3736
317.11,18.4,15.1,0.3749
317.61,18.44,15.1,0.3762
318.11,18.47,15.1,0.3775
318.61,18.5,15.11,0.3788
319.11,18.54,15.1,0.38
319.61,18.57,15.1,0.3813
320.11,18.6,15.11,0.3826
320.61,18.64,15.1,0.3839
321.11,18.67,15.1,0.3852
321.61,18.7,15.1,0.3865
322.11,18.74,15.1,0.3877
322.61,18.77,15.1,0.389
323.11,18.8,15.1,0.3903
323.61,18.84,15.1,0.3916
324.11,18.87,15.1,0.3929
324.61,18.9,15.1,0.3942
325.11,18.93,15.1,0.3955
325.61,18.97,15.1,0.3967
326.11,19,15.1,0.398
326.61,19.04,15.1,0.3993
327.11,19.07,15.1,0.4006
327.61,19.1,15.1,0.4019
328.11,19.14,15.1,0.4032
328.61,19.17,15.1,0.4044
329.11,19.2,15.1,0.4057
329.61,19.24,15.1,0.4069
330.11,19.27,15.1,0.4079
330.61,19.3,15.1,0.4089
331.11,19.34,15.1,0.4098
331.61,19.37,15.1,0.4105
332.11,19.4,15.1,0.4112
332.61,19.44,15.1,0.4116
333.11,19.47,15.1,0.412
333.61,19.5,15.1,0.4123
334.11,19.54,15.1,0.4124
334.61,19.57,15.1,0.4125
335.11,19.6,15.1,0.4126
335.61,19.64,15.1,0.4126
336.11,19.67,15.1,0.4127
336.61,19.7,15.11,0.4127
337.11,19.74,15.13,0.4127
337.61,19.77,15.14,0.4127
338.11,19.8,15.15,0.4127
338.61,19.84,15.16,0.4127
339.11,19.87,15.14,0.4128
339.61,19.9,15.13,0.413
340.11,19.94,15.12,0.4133
340.61,19.97,15.11,0.4138
341.11,20,15.1,0.4145
341.61,20.04,15.1,0.4153
342.11,20.07,15.09,0.4163
342.61,20.1,15.08,0.4173
343.11,20.14,15.08,0.4183
343.61,20.17,15.07,0.4195
344.11,20.2,15.06,0.4206
344.61,20.24,15.05,0.4218
345.11,20.27,15.05,0.423
345.61,20.3,15.04,0.4242
346.11,20.34,15.03,0.4255
346.61,20.37,15.02,0.4267
347.11,20.4,15.01,0.4279
347.61,20.44,14.99,0.4291
348.11,20.47,14.98,0.4303
348.61,20.5,14.96,0.4314
349.11,20.54,14.95,0.4325
349.61,20.57,14.94,0.4336
350.11,20.6,14.92,0.4348
350.61,20.64,14.9,0.4359
351.11,20.67,14.88,0.4371
351.61,20.7,14.86,0.4383
352.11,20.74,14.84,0.4395
352.61,20.77,14.82,0.4406
353.11,20.8,14.79,0.4418
353.61,20.84,14.77,0.443
354.11,20.87,14.74,0.4442
354.61,20.9,14.71,0.4454
355.11,20.94,14.68,0.4466
355.61,20.97,14.65,0.4478
356.11,21,14.62,0.4491
356.61,21.04,14.59,0.4503
357.11,21.07,14.56,0.4515
357.61,21.1,14.51,0.4528
358.11,21.14,14.48,0.454
358.61,21.17,14.44,0.4553
359.11,21.2,14.39,0.4566
359.61,21.24,14.35,0.4579
360.11,21.27,14.31,0.4592
360.61,21.3,14.26,0.4604
361.11,21.34,14.21,0.4618
361.61,21.37,14.15,0.4631
362.11,21.4,14.1,0.4644
362.61,21.44,14.04,0.4657
363.11,21.47,13.97,0.4671
363.61,21.5,13.91,0.4684
364.11,21.54,13.84,0.4698
364.61,21.57,13.76,0.4712
365.11,21.6,13.66,0.4726
365.23,21.61,7.655,0.4823