File: Datasets/hcs.csv
Time,Force,Displacement,Strain 1
(s),(kN),(mm),(mm/mm)
0,0.0024,0.0365,5.999999999999999e-06
1,0.0289,0.0567,0.000258
2,0.0508,0.0764,0.000504
3,0.0759,0.096,0.000749
4,0.1005,0.116,0.000999
5,0.1305,0.136,0.00125
6,0.1706,0.156,0.001499
7,0.2296,0.176,0.001749
8,0.3209,0.1956,0.001994
9,0.472,0.216,0.002248
10,0.6811,0.2359,0.002497
11,0.9437,0.2558,0.002746
12,1.2702,0.2757,0.002994
13,1.6061,0.2958,0.003246
14,1.942,0.3159,0.003497
15,2.2975,0.3357,0.003744
16,2.6652,0.3556,0.003993
17,3.051,0.3758,0.004245
18,3.4173,0.3957,0.004494
19,3.7926,0.4159,0.004746
20,4.1587,0.4357,0.004993
21,4.5241,0.4558,0.005245
22,4.8798,0.4755,0.005491
23,5.2198,0.4958,0.005744
24,5.5754,0.5159,0.005996
25,5.91,0.5356,0.006242
26,6.258,0.5558,0.006495
27,6.5892,0.5757,0.006742
28,6.9183,0.596,0.006997
29,7.2387,0.6154,0.007239
30,7.56,0.6358,0.007494
31,7.8777,0.6559,0.0077449999999999
32,8.1781,0.6758,0.007993
33,8.4805,0.6958,0.008244
34,8.775,0.7156,0.008491
35,9.0615,0.7359,0.008744
36,9.3391,0.7557,0.008992
37,9.6005,0.7758,0.009243
38,9.861,0.7962,0.009498
39,10.0657,0.8156,0.00974
40,10.2647,0.8359,0.009993
41,10.4515,0.8557,0.010241
42,10.637,0.876,0.010495
43,10.818,0.8958,0.010742
44,10.9879,0.9157,0.0109909999999999
45,11.1675,0.9363,0.011248
46,11.3159,0.9557,0.01149
47,11.4771,0.976,0.011744
48,11.6243,0.9957,0.01199
49,11.764,1.0159,0.0122429999999999
50,11.8966,1.0358,0.012492
51,12.0108,1.0559,0.0127429999999999
52,12.1303,1.0761,0.012995
53,12.2271,1.0957,0.01324
54,12.3268,1.116,0.0134939999999999
55,12.4193,1.136,0.013744
56,12.4933,1.1559,0.013993
57,12.5757,1.1759,0.014242
58,12.6414,1.196,0.014492
59,12.7152,1.2162,0.0147459999999999
60,12.7673,1.2358,0.014991
61,12.826,1.256,0.015242
62,12.8853,1.2758,0.015489
63,12.9316,1.2959,0.015741
64,12.9832,1.3161,0.0159939999999999
65,13.0216,1.3357,0.016239
66,13.0733,1.356,0.016492
67,13.112,1.3755,0.016736
68,13.1565,1.3963,0.016996
69,13.1943,1.416,0.017241
70,13.2279,1.4359,0.01749
71,13.2697,1.4559,0.017741
72,13.3032,1.4759,0.01799
73,13.3407,1.4962,0.018244
74,13.3696,1.5155,0.018486
75,13.4049,1.536,0.018741
76,13.446,1.5562,0.018993
77,13.4678,1.576,0.0192409999999999
78,13.5041,1.5962,0.019493
79,13.5271,1.6157,0.019737
80,13.5674,1.6361,0.019992
81,13.5936,1.6558,0.020238
82,13.62,1.676,0.0204899999999999
83,13.6562,1.6962,0.020743
84,13.6748,1.7156,0.020985
85,13.7132,1.7361,0.021241
86,13.736,1.7558,0.021487
87,13.7656,1.7762,0.0217419999999999
88,13.7918,1.7958,0.021987
89,13.8174,1.816,0.022239
90,13.8527,1.8362,0.022492
91,13.8679,1.8558,0.0227369999999999
92,13.9003,1.876,0.02299
93,13.9276,1.8958,0.023236
94,13.9524,1.916,0.02349
95,13.9818,1.9361,0.02374
96,13.9961,1.9559,0.0239869999999999
97,14.0335,1.9762,0.024241
98,14.0483,1.9958,0.0244859999999999
99,14.08,2.0161,0.024739
100,14.1044,2.0359,0.024987
101,14.1233,2.0559,0.025236
102,14.1536,2.0759,0.025487
103,14.1712,2.0959,0.025737
104,14.2052,2.1164,0.025993
105,14.217,2.1356,0.026233
106,14.2447,2.1561,0.026489
107,14.2713,2.1757,0.026734
108,14.2931,2.1961,0.0269879999999999
109,14.3169,2.2161,0.027238
110,14.3335,2.236,0.0274869999999999
111,14.3625,2.2561,0.027738
112,14.3823,2.2756,0.0279829999999999
113,14.405,2.2961,0.028238
114,14.4326,2.3161,0.028488
115,14.4455,2.3359,0.028735
116,14.4738,2.3561,0.028987
117,14.4903,2.3758,0.029234
118,14.518,2.3963,0.02949
119,14.5316,2.4157,0.0297319999999999
120,14.5555,2.436,0.029986
121,14.5838,2.4561,0.030237
122,14.5941,2.4759,0.030484
123,14.6224,2.4963,0.030739
124,14.6338,2.5156,0.0309799999999999
125,14.6643,2.5361,0.031237
126,14.6808,2.5557,0.031482
127,14.701,2.5761,0.031737
128,14.7246,2.5963,0.0319879999999999
129,14.7356,2.6158,0.032233
130,14.7644,2.6361,0.032486
131,14.7803,2.6559,0.032733
132,14.7996,2.6761,0.032986
133,14.8202,2.6958,0.033232
134,14.8342,2.7157,0.033481
135,14.8659,2.7363,0.033738
136,14.8705,2.7559,0.033983
137,14.8954,2.776,0.034235
138,14.9129,2.7958,0.034481
139,14.9335,2.816,0.034734
140,14.9541,2.836,0.034984
141,14.9609,2.8558,0.035232
142,14.9916,2.8762,0.035486
143,15.0007,2.8956,0.035728
144,15.0271,2.9162,0.035986
145,15.0432,2.9359,0.036232
146,15.0565,2.9561,0.036484
147,15.0767,2.9758,0.036731
148,15.0918,2.996,0.036983
149,15.1153,3.0162,0.037236
150,15.1248,3.0358,0.03748
151,15.1435,3.056,0.0377329999999999
152,15.1671,3.0758,0.03798
153,15.1784,3.096,0.038233
154,15.1991,3.1161,0.038484
155,15.2069,3.1359,0.038731
156,15.2321,3.1561,0.038984
157,15.2426,3.1757,0.039228
158,15.2619,3.1962,0.039484
159,15.2801,3.216,0.0397319999999999
160,15.2895,3.2358,0.03998
161,15.3135,3.2561,0.040233
162,15.3216,3.2758,0.040479
163,15.3459,3.2963,0.040736
164,15.3534,3.3155,0.040975
165,15.3723,3.336,0.041231
166,15.3933,3.3561,0.041482
167,15.4003,3.3759,0.04173
168,15.4194,3.3959,0.04198
169,15.4302,3.4157,0.042226
170,15.4533,3.4363,0.042484
171,15.4645,3.4558,0.042728
172,15.476,3.476,0.042981
173,15.4994,3.4964,0.043235
174,15.5012,3.5158,0.0434769999999999
175,15.5261,3.5361,0.043731
176,15.5349,3.5559,0.043979
177,15.551,3.576,0.04423
178,15.5654,3.5958,0.044478
179,15.5756,3.6158,0.0447269999999999
180,15.6019,3.6363,0.044984
181,15.6005,3.6557,0.0452259999999999
182,15.6227,3.6761,0.045481
183,15.6335,3.6956,0.045724
184,15.6502,3.716,0.045979
185,15.6651,3.7359,0.046228
186,15.6714,3.756,0.046479
187,15.6943,3.7763,0.0467319999999999
188,15.6988,3.7958,0.046976
189,15.7177,3.8161,0.047229
190,15.7337,3.836,0.047478
191,15.7388,3.856,0.047728
192,15.7582,3.876,0.0479779999999999
193,15.7639,3.8959,0.048226
194,15.787,3.9163,0.0484809999999999
195,15.7893,3.9358,0.048725
196,15.8046,3.956,0.048977
197,15.8216,3.9758,0.049225
198,15.8299,3.996,0.049477
199,15.8461,4.0161,0.049728
200,15.8494,4.0358,0.049974
201,15.8699,4.0561,0.050228
202,15.8813,4.0756,0.050472
203,15.8941,4.0963,0.05073
204,15.9068,4.116,0.0509769999999999
205,15.9129,4.1359,0.0512249999999999
206,15.9301,4.156,0.0514759999999999
207,15.9384,4.1759,0.051726
208,15.9551,4.1963,0.05198
209,15.9602,4.2157,0.052222
210,15.9729,4.236,0.052476
211,15.9934,4.2561,0.052727
212,15.9957,4.276,0.052976
213,16.0107,4.2962,0.053228
214,16.0148,4.3157,0.053471
215,16.0351,4.3361,0.053726
216,16.0427,4.3558,0.053973
217,16.0508,4.376,0.054226
218,16.0693,4.3962,0.054478
219,16.0681,4.4156,0.05472
220,16.0919,4.4362,0.054977
221,16.0949,4.4558,0.055222
222,16.1085,4.4762,0.055477
223,16.1173,4.4957,0.055721
224,16.1269,4.5159,0.0559729999999999
225,16.1462,4.5363,0.056228
226,16.1444,4.556,0.056474
227,16.1591,4.5759,0.0567229999999999
228,16.1709,4.5958,0.056971
229,16.1806,4.616,0.057224
230,16.1957,4.636,0.057474
231,16.1941,4.656,0.057723
232,16.216,4.6762,0.057976
233,16.2163,4.6957,0.05822
234,16.2325,4.716,0.058473
235,16.2426,4.7358,0.0587209999999999
236,16.2477,4.7559,0.058972
237,16.2628,4.776,0.059223
238,16.2658,4.796,0.059472
239,16.2845,4.8163,0.0597269999999999
240,16.2843,4.8356,0.059968
241,16.2967,4.8561,0.060224
242,16.3113,4.8758,0.0604699999999999
243,16.3173,4.8961,0.060724
244,16.3276,4.916,0.060972
245,16.3319,4.936,0.061222
246,16.3471,4.9562,0.061474
247,16.3533,4.9757,0.061717
248,16.3634,4.9962,0.061974
249,16.3773,5.016,0.062222
250,16.3768,5.0358,0.062469
251,16.3925,5.0559,0.06272
252,16.3954,5.0756,0.062966
253,16.4169,5.0965,0.063227
254,16.4129,5.1158,0.063468
255,16.4241,5.1361,0.063722
256,16.4392,5.1561,0.063972
257,16.4378,5.1759,0.064219
258,16.454,5.1963,0.064474
259,16.4523,5.2156,0.064716
260,16.4715,5.2362,0.064973
261,16.4763,5.2557,0.065216
262,16.4841,5.2761,0.065472
263,16.4964,5.2963,0.065723
264,16.495,5.3158,0.065967
265,16.513,5.336,0.06622
266,16.5171,5.3559,0.066468
267,16.5239,5.376,0.066719
268,16.5349,5.3957,0.066965
269,16.5361,5.4157,0.067215
270,16.5619,5.4364,0.067475
271,16.5508,5.456,0.067719
272,16.5657,5.4762,0.067971
273,16.5701,5.4958,0.068216
274,16.5808,5.5159,0.068468
275,16.5918,5.5361,0.068719
276,16.589,5.556,0.068969
277,16.6076,5.5762,0.069221
278,16.6055,5.5956,0.069463
279,16.6222,5.6162,0.069721
280,16.6272,5.6359,0.069966
281,16.631,5.6561,0.0702189999999999
282,16.6404,5.6759,0.070466
283,16.645,5.696,0.070718
284,16.6585,5.7162,0.07097
285,16.6587,5.7358,0.071215
286,16.6663,5.7559,0.071467
287,16.6817,5.7758,0.071715
288,16.6825,5.7961,0.0719679999999999
289,16.6933,5.8162,0.0722189999999999
290,16.6909,5.8358,0.072465
291,16.707,5.8561,0.072718
292,16.709,5.8757,0.072963
293,16.7187,5.8962,0.07322
294,16.7271,5.916,0.073467
295,16.7261,5.9358,0.073714
296,16.7417,5.9561,0.073967
297,16.7415,5.9758,0.074214
298,16.7545,5.9964,0.074471
299,16.7533,6.0154,0.074708
300,16.7634,6.036,0.074966
301,16.7761,6.056,0.075216
302,16.7757,6.076,0.075465
303,16.7876,6.0962,0.075718
304,16.7859,6.1158,0.075963
305,16.8002,6.1362,0.076217
306,16.8047,6.1559,0.076463
307,16.8058,6.176,0.076715
308,16.8214,6.1963,0.076968
309,16.816,6.2158,0.077213
310,16.8324,6.2362,0.077467
311,16.832,6.2559,0.077713
312,16.8405,6.2761,0.077965
313,16.8467,6.2959,0.078213
314,16.8479,6.3159,0.078463
315,16.8653,6.3363,0.078718
316,16.8559,6.3557,0.07896
317,16.8707,6.3761,0.079215
318,16.8763,6.3956,0.079459
319,16.8815,6.4159,0.079713
320,16.8933,6.436,0.0799629999999999
321,16.8895,6.4561,0.080215
322,16.903,6.4763,0.080467
323,16.9002,6.4959,0.0807109999999999
324,16.9117,6.516,0.080964
325,16.9201,6.536,0.081213
326,16.9183,6.5561,0.081464
327,16.9299,6.5759,0.081712
328,16.9284,6.5959,0.081962
329,16.9439,6.6163,0.082217
330,16.9392,6.6358,0.08246
331,16.9471,6.656,0.082713
332,16.9563,6.6758,0.0829589999999999
333,16.958,6.6959,0.083211
334,16.9657,6.716,0.083462
335,16.964,6.7358,0.083709
336,16.9784,6.7561,0.083964
337,16.9789,6.7755,0.084206
338,16.9881,6.7963,0.084465
339,16.9942,6.816,0.084712
340,16.9929,6.836,0.084961
341,17.0028,6.856,0.085211
342,17.0052,6.8759,0.08546
343,17.0152,6.8964,0.085716
344,17.0123,6.9157,0.085957
345,17.019,6.936,0.08621
346,17.033,6.9561,0.086462
347,17.0274,6.976,0.08671
348,17.0379,6.9962,0.086963
349,17.0337,7.0155,0.0872049999999999
350,17.0475,7.036,0.08746
351,17.0479,7.0557,0.087706
352,17.0547,7.0762,0.087962
353,17.062,7.0963,0.088213
354,17.0565,7.1156,0.0884549999999999
355,17.0741,7.1362,0.088712
356,17.0708,7.1558,0.088957
357,17.0795,7.1762,0.089212
358,17.0815,7.1957,0.089456
359,17.085,7.2159,0.089708
360,17.0986,7.2363,0.089963
361,17.0909,7.2559,0.090208
362,17.1005,7.276,0.090459
363,17.1061,7.2958,0.090706
364,17.1096,7.316,0.090959
365,17.1184,7.336,0.091209
366,17.1115,7.3559,0.091458
367,17.127,7.3761,0.09171
368,17.1212,7.3955,0.0919519999999999
369,17.1362,7.4162,0.092211
370,17.1373,7.4359,0.092457
371,17.1367,7.4559,0.092707
372,17.1466,7.476,0.092957
373,17.1445,7.496,0.093207
374,17.158,7.5164,0.0934619999999999
375,17.1513,7.5357,0.093703
376,17.1604,7.5562,0.09396
377,17.1662,7.5757,0.094203
378,17.1688,7.5961,0.094459
379,17.1739,7.616,0.094707
380,17.1724,7.6359,0.094956
381,17.1823,7.6562,0.0952089999999999
382,17.1825,7.6757,0.095452
383,17.188,7.6962,0.095709
384,17.1891,7.7159,0.0959559999999999
385,17.1812,7.7357,0.096203
386,17.1989,7.7561,0.0964579999999999
387,17.197,7.7758,0.096703
388,17.2102,7.7963,0.0969599999999999
389,17.2067,7.8157,0.097202
390,17.2127,7.836,0.097456
391,17.2243,7.8562,0.0977079999999999
392,17.2172,7.8759,0.097954
393,17.2286,7.8963,0.098209
394,17.2219,7.9156,0.098451
395,17.2376,7.9362,0.0987079999999999
396,17.2354,7.9556,0.09895
397,17.2393,7.9761,0.099207
398,17.2476,7.9963,0.099459
399,17.2405,8.0157,0.099701
400,17.2532,8.036,0.099955
401,17.2543,8.0559,0.100203
402,17.2573,8.0761,0.100455
403,17.2618,8.0958,0.100702
404,17.2603,8.1158,0.100951
405,17.2763,8.1363,0.1012079999999999
406,17.265,8.1559,0.101452
407,17.2755,8.1761,0.101705
408,17.2764,8.1957,0.10195
409,17.2809,8.2159,0.102203
410,17.2879,8.2361,0.102454
411,17.2814,8.256,0.102703
412,17.296,8.2763,0.102957
413,17.288,8.2956,0.103198
414,17.3015,8.3162,0.1034549999999999
415,17.3016,8.3358,0.103701
416,17.3004,8.356,0.103953
417,17.3075,8.3758,0.1042
418,17.3086,8.396,0.1044529999999999
419,17.3163,8.4162,0.1047049999999999
420,17.3118,8.4357,0.104948
421,17.3184,8.456,0.105202
422,17.3258,8.4758,0.10545
423,17.3255,8.4962,0.1057039999999999
424,17.3307,8.5162,0.1059539999999999
425,17.3243,8.5359,0.106201
426,17.337,8.5562,0.106454
427,17.3347,8.5757,0.106697
428,17.3411,8.5962,0.106955
429,17.3449,8.616,0.107202
430,17.3409,8.6358,0.107448
431,17.3525,8.6562,0.107703
432,17.3466,8.6758,0.107949
433,17.3567,8.6963,0.108205
434,17.3369,8.7154,0.108443
435,17.3514,8.7362,0.108703
436,17.3637,8.7561,0.108952
437,17.3607,8.776,0.1092
438,17.3676,8.7961,0.109451
439,17.3661,8.8157,0.109696
440,17.376,8.8361,0.109952
441,17.3769,8.8559,0.110198
442,17.3756,8.8761,0.110452
443,17.3861,8.8963,0.110703
444,17.3761,8.9158,0.1109469999999999
445,17.3921,8.9362,0.111203
446,17.3854,8.9558,0.111447
447,17.3907,8.9761,0.1117
448,17.3944,8.9959,0.111948
449,17.3916,9.0158,0.112196
450,17.4055,9.0363,0.112453
451,17.3932,9.0557,0.112695
452,17.4048,9.076,0.112949
453,17.4042,9.0956,0.113194
454,17.4096,9.1161,0.11345
455,17.4139,9.1359,0.1136969999999999
456,17.4088,9.1561,0.113949
457,17.4188,9.1762,0.114201
458,17.4143,9.1958,0.1144449999999999
459,17.4222,9.2161,0.114699
460,17.4262,9.236,0.114947
461,17.4217,9.256,0.115198
462,17.431,9.276,0.115447
463,17.4247,9.2959,0.115696
464,17.4384,9.3163,0.115951
465,17.4302,9.3358,0.116195
466,17.4347,9.3561,0.116448
467,17.4408,9.3758,0.1166939999999999
468,17.4382,9.3959,0.116945
469,17.4461,9.4161,0.117198
470,17.4389,9.4359,0.117445
471,17.4506,9.4561,0.117698
472,17.4477,9.4755,0.11794
473,17.4555,9.4964,0.118201
474,17.4563,9.516,0.118446
475,17.4531,9.536,0.118697
476,17.4592,9.556,0.118946
477,17.4593,9.5759,0.119194
478,17.4658,9.5964,0.119451
479,17.4613,9.6157,0.119692
480,17.4637,9.6359,0.119944
481,17.4758,9.6561,0.120197
482,17.4664,9.676,0.120445
483,17.4754,9.6963,0.120699
484,17.4673,9.7156,0.1209399999999999
485,17.4784,9.736,0.121195
486,17.4808,9.7558,0.121443
487,17.4785,9.776,0.121695
488,17.4861,9.7962,0.121948
489,17.4758,9.8155,0.122188
490,17.4939,9.8362,0.122447
491,17.4853,9.8558,0.122692
492,17.4915,9.8763,0.122948
493,17.4903,9.8957,0.123191
494,17.4904,9.916,0.123443
495,17.503,9.9363,0.123698
496,17.491,9.9559,0.123943
497,17.4984,9.976,0.124194
498,17.5012,9.9958,0.12444
499,17.503,10.016,0.124694
500,17.5084,10.036,0.124944
501,17.4997,10.056,0.125193
502,17.512,10.0761,0.125444
503,17.5061,10.0958,0.12569
504,17.5135,10.1162,0.125945
505,17.5139,10.1358,0.12619
506,17.5101,10.1558,0.12644
507,17.5202,10.176,0.126693
508,17.5148,10.1961,0.126943
509,17.5235,10.2163,0.127196
510,17.5163,10.2357,0.127438
511,17.5221,10.2562,0.127694
512,17.527,10.2758,0.127939
513,17.5258,10.2961,0.128194
514,17.5281,10.316,0.128442
515,17.5252,10.3359,0.12869
516,17.5323,10.3561,0.128943
517,17.5312,10.3757,0.129188
518,17.5333,10.3961,0.129443
519,17.5402,10.416,0.129691
520,17.5324,10.4359,0.12994
521,17.5418,10.456,0.130191
522,17.5356,10.4757,0.130438
523,17.5454,10.4963,0.130694
524,17.5397,10.5157,0.130936
525,17.5431,10.5361,0.131192
526,17.5492,10.5561,0.131442
527,17.5431,10.5759,0.131689
528,17.5508,10.5963,0.131943
529,17.5431,10.6157,0.132186
530,17.5545,10.6362,0.132442
531,17.5511,10.6556,0.132685
532,17.5532,10.6762,0.132942
533,17.5581,10.6962,0.133192
534,17.5506,10.7158,0.133437
535,17.5603,10.736,0.13369
536,17.5592,10.7558,0.133937
537,17.56,10.7761,0.134191
538,17.5615,10.7958,0.134437
539,17.5537,10.8158,0.134686
540,17.5552,10.8363,0.134943
541,17.5542,10.8559,0.135188
542,17.5666,10.8762,0.135441
543,17.5654,10.8957,0.135685
544,17.5689,10.916,0.135938
545,17.5733,10.936,0.136189
546,17.5648,10.956,0.136438
547,17.576,10.9762,0.136691
548,17.5677,10.9956,0.136933
549,17.5783,11.0162,0.13719
550,17.5759,11.0358,0.137436
551,17.574,11.056,0.137688
552,17.5785,11.0758,0.137935
553,17.5767,11.096,0.138187
554,17.5842,11.1163,0.1384409999999999
555,17.5763,11.1357,0.138683
556,17.5789,11.1558,0.138935
557,17.5898,11.1759,0.139185
558,17.5836,11.1961,0.139438
559,17.5884,11.2162,0.139689
560,17.5793,11.2359,0.139935
561,17.5906,11.2562,0.140189
562,17.5859,11.2757,0.140432
563,17.5903,11.2963,0.14069
564,17.5931,11.316,0.140937
565,17.5872,11.3358,0.141184
566,17.5953,11.3561,0.141437
567,17.5902,11.3758,0.141684
568,17.5977,11.3964,0.141941
569,17.5894,11.4155,0.142179
570,17.5963,11.4361,0.142437
571,17.6008,11.456,0.142685
572,17.5938,11.4759,0.142934
573,17.5988,11.496,0.143185
574,17.5971,11.5157,0.143431
575,17.6036,11.5362,0.143687
576,17.6023,11.5559,0.143933
577,17.5998,11.576,0.144185
578,17.609,11.5963,0.1444389999999999
579,17.5971,11.6158,0.144682
580,17.6097,11.6362,0.144937
581,17.603,11.6558,0.145182
582,17.6062,11.676,0.145435
583,17.6077,11.6959,0.1456819999999999
584,17.6039,11.7158,0.145932
585,17.6162,11.7364,0.146188
586,17.6017,11.7557,0.14643
587,17.612,11.7761,0.146685
588,17.6092,11.7956,0.146929
589,17.6115,11.816,0.1471829999999999
590,17.6155,11.8359,0.147431
591,17.6098,11.8561,0.147684
592,17.6188,11.8763,0.1479359999999999
593,17.6113,11.8958,0.14818
594,17.6171,11.9161,0.148434
595,17.6208,11.936,0.148683
596,17.6138,11.9561,0.148933
597,17.6194,11.9759,0.149182
598,17.615,11.996,0.1494319999999999
599,17.6236,12.0162,0.149685
600,17.6159,12.0358,0.14993
601,17.6187,12.0561,0.150183
602,17.6231,12.0758,0.150429
603,17.6192,12.0959,0.1506809999999999
604,17.625,12.1161,0.1509329999999999
605,17.6162,12.1358,0.151179
606,17.6261,12.1562,0.1514339999999999
607,17.6217,12.1754,0.151674
608,17.6276,12.1963,0.151935
609,17.6275,12.216,0.152181
610,17.6227,12.2361,0.152432
611,17.6272,12.256,0.15268
612,17.6253,12.2759,0.1529299999999999
613,17.6304,12.2964,0.153185
614,17.625,12.3157,0.1534259999999999
615,17.6265,12.336,0.15368
616,17.6351,12.3561,0.153931
617,17.6262,12.376,0.1541799999999999
618,17.6321,12.3962,0.154433
619,17.6237,12.4157,0.1546759999999999
620,17.6345,12.4361,0.154931
621,17.6312,12.4558,0.155177
622,17.6287,12.476,0.1554299999999999
623,17.636,12.4962,0.155682
624,17.6263,12.5155,0.155924
625,17.6382,12.5362,0.156181
626,17.6315,12.5558,0.1564269999999999
627,17.6345,12.5762,0.156681
628,17.633,12.5957,0.156925
629,17.6322,12.6159,0.157178
630,17.6417,12.6363,0.157433
631,17.6298,12.6559,0.1576779999999999
632,17.635,12.676,0.1579289999999999
633,17.6369,12.6957,0.1581739999999999
634,17.6367,12.716,0.158429
635,17.6408,12.7361,0.158679
636,17.6298,12.7559,0.1589269999999999
637,17.6435,12.7763,0.159181
638,17.6325,12.7958,0.159425
639,17.6401,12.8161,0.159679
640,17.6391,12.8358,0.1599249999999999
641,17.6366,12.8559,0.160177
642,17.6417,12.876,0.160427
643,17.6344,12.8959,0.1606759999999999
644,17.6443,12.9164,0.160932
645,17.6335,12.9356,0.161172
646,17.6398,12.9561,0.161429
647,17.6415,12.9758,0.161674
648,17.6408,12.9962,0.161929
649,17.6407,13.016,0.162177
650,17.6354,13.0359,0.1624249999999999
651,17.6428,13.0562,0.162679
652,17.6395,13.0757,0.162922
653,17.6408,13.0962,0.163178
654,17.646,13.116,0.163427
655,17.6372,13.1359,0.163674
656,17.6444,13.1561,0.163926
657,17.6375,13.1757,0.164172
658,17.6476,13.1963,0.164429
659,17.6384,13.2157,0.1646709999999999
660,17.6411,13.2361,0.164926
661,17.6473,13.2561,0.165177
662,17.6384,13.2759,0.165424
663,17.6451,13.2963,0.165678
664,17.6365,13.3156,0.1659199999999999
665,17.6442,13.336,0.166175
666,17.6429,13.3556,0.1664189999999999
667,17.6464,13.3763,0.166679
668,17.6459,13.3963,0.166928
669,17.637,13.4159,0.167172
670,17.6459,13.4361,0.167425
671,17.6424,13.4558,0.167672
672,17.6436,13.4762,0.167926
673,17.6436,13.4958,0.168172
674,17.6387,13.5158,0.168421
675,17.6519,13.5363,0.168678
676,17.6373,13.5559,0.168922
677,17.6444,13.5761,0.169175
678,17.6416,13.5957,0.16942
679,17.6423,13.6159,0.169672
680,17.6477,13.636,0.169924
681,17.6368,13.656,0.170173
682,17.6457,13.6761,0.170424
683,17.6375,13.6955,0.170666
684,17.6479,13.7163,0.170926
685,17.6443,13.7359,0.171171
686,17.6398,13.7561,0.171423
687,17.6435,13.7758,0.17167
688,17.6405,13.796,0.171922
689,17.6472,13.8163,0.172176
690,17.6385,13.8358,0.172419
691,17.6389,13.8559,0.17267
692,17.6487,13.8758,0.172919
693,17.6418,13.8961,0.173173
694,17.6441,13.9161,0.173423
695,17.6362,13.9359,0.17367
696,17.6448,13.9561,0.173923
697,17.6394,13.9757,0.174167
698,17.6425,13.9963,0.174425
699,17.6433,14.0159,0.17467
700,17.6369,14.0358,0.174918
701,17.6447,14.0562,0.175173
702,17.6373,14.0758,0.175418
703,17.6441,14.0964,0.175676
704,17.6342,14.1154,0.175913
705,17.6405,14.136,0.176171
706,17.6447,14.1561,0.176421
707,17.636,14.176,0.17667
708,17.6402,14.1961,0.176921
709,17.6348,14.2156,0.177165
710,17.6422,14.2362,0.177422
711,17.6399,14.2559,0.177668
712,17.6358,14.276,0.17792
713,17.6428,14.2963,0.178173
714,17.6307,14.3158,0.178417
715,17.643,14.3361,0.178671
716,17.6351,14.3558,0.178916
717,17.6372,14.3761,0.17917
718,17.6367,14.3959,0.179417
719,17.6317,14.4159,0.179667
720,17.6426,14.4364,0.179923
721,17.6284,14.4557,0.180165
722,17.6352,14.476,0.180419
723,17.6329,14.4957,0.180664
724,17.6352,14.516,0.180918
725,17.6357,14.5358,0.181166
726,17.6296,14.5561,0.181419
727,17.6371,14.5762,0.181671
728,17.6285,14.5958,0.181915
729,17.6333,14.6161,0.182169
730,17.6355,14.6359,0.182417
731,17.6276,14.656,0.182668
732,17.6323,14.6758,0.182915
733,17.6269,14.6959,0.183166
734,17.6373,14.7164,0.1834219999999999
735,17.6253,14.7359,0.183665
736,17.6277,14.7561,0.183918
737,17.6312,14.7758,0.184164
738,17.6257,14.7959,0.184416
739,17.6299,14.8161,0.184668
740,17.6206,14.8358,0.184913
741,17.6282,14.8561,0.185168
742,17.624,14.8755,0.18541
743,17.6271,14.8963,0.185669
744,17.6268,14.916,0.185916
745,17.6203,14.936,0.1861659999999999
746,17.6251,14.956,0.186415
747,17.6217,14.9759,0.186665
748,17.6246,14.9963,0.186919
749,17.6185,15.0156,0.18716
750,17.6189,15.0359,0.187414
751,17.6277,15.0562,0.187667
752,17.6171,15.0761,0.187916
753,17.6209,15.0962,0.188168
754,17.6126,15.1157,0.188411
755,17.6208,15.1361,0.1886649999999999
756,17.6182,15.1558,0.188913
757,17.6135,15.1761,0.189165
758,17.619,15.1962,0.189417
759,17.6092,15.2156,0.189659
760,17.6195,15.2362,0.189917
761,17.6115,15.2558,0.190162
762,17.6138,15.2762,0.1904169999999999
763,17.6109,15.2957,0.190661
764,17.6088,15.316,0.190913
765,17.6153,15.3361,0.1911649999999999
766,17.6064,15.356,0.191413
767,17.6099,15.3761,0.191664
768,17.6096,15.3958,0.19191
769,17.608,15.4161,0.192165
770,17.6102,15.4361,0.1924139999999999
771,17.5994,15.4559,0.192662
772,17.6096,15.4762,0.192915
773,17.6,15.4958,0.19316
774,17.6062,15.5161,0.193414
775,17.6037,15.5359,0.193661
776,17.598,15.5559,0.193911
777,17.6038,15.5759,0.194161
778,17.5961,15.596,0.194411
779,17.6046,15.6164,0.194667
780,17.5923,15.6356,0.194907
781,17.5962,15.6561,0.195163
782,17.5988,15.6758,0.195409
783,17.595,15.6961,0.1956629999999999
784,17.5949,15.716,0.195911
785,17.5884,15.7359,0.19616
786,17.5944,15.7562,0.196413
787,17.59,15.7757,0.196657
788,17.5898,15.7961,0.1969119999999999
789,17.594,15.816,0.197161
790,17.5846,15.8359,0.19741
791,17.59,15.8561,0.197662
792,17.5828,15.8758,0.197908
793,17.5889,15.8963,0.198164
794,17.5799,15.9156,0.1984059999999999
795,17.5817,15.936,0.198661
796,17.5864,15.9561,0.198911
797,17.5752,15.9758,0.199157
798,17.5806,15.9962,0.1994119999999999
799,17.5736,16.0156,0.199655
800,17.5818,16.0363,0.1999129999999999
801,17.5751,16.0557,0.200156
802,17.5746,16.0762,0.200411
803,17.5767,16.0963,0.2006629999999999
804,17.5669,16.1158,0.2009069999999999
805,17.5741,16.136,0.20116
806,17.5696,16.1558,0.201406
807,17.5685,16.1761,0.20166
808,17.5689,16.1959,0.201907
809,17.5618,16.2158,0.2021559999999999
810,17.5734,16.2363,0.2024119999999999
811,17.5581,16.2559,0.2026569999999999
812,17.5634,16.2761,0.202909
813,17.5591,16.2957,0.203155
814,17.5594,16.316,0.203408
815,17.5602,16.3359,0.203657
816,17.5505,16.356,0.2039079999999999
817,17.5595,16.3762,0.204161
818,17.5498,16.3957,0.204403
819,17.5566,16.4163,0.204661
820,17.5523,16.4359,0.204906
821,17.547,16.4561,0.2051589999999999
822,17.5484,16.4758,0.205405
823,17.5442,16.4961,0.205658
824,17.5478,16.5162,0.205909
825,17.5409,16.5358,0.206154
826,17.5389,16.556,0.2064059999999999
827,17.5445,16.5757,0.2066529999999999
828,17.5379,16.5961,0.2069079999999999
829,17.5395,16.6162,0.207158
830,17.5288,16.6359,0.207404
831,17.5359,16.6562,0.2076579999999999
832,17.5281,16.6755,0.2079
833,17.5314,16.6963,0.2081599999999999
834,17.5299,16.716,0.2084059999999999
835,17.5217,16.7359,0.208654
836,17.5276,16.7561,0.2089069999999999
837,17.519,16.7758,0.2091529999999999
838,17.5243,16.7964,0.2094099999999999
839,17.5137,16.8155,0.209648
840,17.5165,16.8361,0.209906
841,17.5192,16.8561,0.2101559999999999
842,17.5098,16.876,0.210405
843,17.5119,16.8961,0.210656
844,17.5049,16.9157,0.210901
845,17.5101,16.9362,0.211157
846,17.5053,16.9558,0.211402
847,17.4993,16.976,0.211654
848,17.5051,16.9962,0.2119069999999999
849,17.4922,17.0157,0.21215
850,17.5008,17.0362,0.212407
851,17.4911,17.0559,0.212652
852,17.4907,17.076,0.212904
853,17.4888,17.0959,0.213152
854,17.4825,17.1159,0.2134019999999999
855,17.4909,17.1363,0.213657
856,17.474,17.1557,0.213899
857,17.4805,17.1762,0.214155
858,17.4745,17.1956,0.214398
859,17.4746,17.216,0.2146529999999999
860,17.4734,17.2359,0.214902
861,17.4638,17.256,0.215153
862,17.4699,17.2762,0.215406
863,17.4587,17.2958,0.21565
864,17.4608,17.316,0.2159029999999999
865,17.4598,17.3359,0.216151
866,17.4494,17.3558,0.2164
867,17.4535,17.3759,0.2166509999999999
868,17.4454,17.396,0.216902
869,17.4493,17.4164,0.217156
870,17.4372,17.4358,0.2173999999999999
871,17.4368,17.4561,0.2176529999999999
872,17.4368,17.4758,0.2178989999999999
873,17.4301,17.496,0.218151
874,17.4303,17.5162,0.2184029999999999
875,17.4174,17.5358,0.2186489999999999
876,17.4235,17.5562,0.218904
877,17.4147,17.5755,0.219144
878,17.4149,17.5963,0.219404
879,17.4121,17.616,0.2196509999999999
880,17.4024,17.636,0.2198999999999999
881,17.4023,17.656,0.22015
882,17.3938,17.6758,0.2203979999999999
883,17.3959,17.6963,0.220654
884,17.384,17.7156,0.220895
885,17.3834,17.7361,0.221151
886,17.3857,17.7561,0.221402
887,17.3718,17.7761,0.221651
888,17.3719,17.7963,0.221903
889,17.3591,17.8157,0.222145
890,17.3628,17.8361,0.222401
891,17.354,17.8558,0.222647
892,17.3474,17.8761,0.2229
893,17.347,17.8962,0.223152
894,17.3317,17.9156,0.223394
895,17.3378,17.9362,0.223652
896,17.3247,17.9558,0.223896
897,17.3209,17.9762,0.224152
898,17.3139,17.9957,0.2243949999999999
899,17.3033,18.0157,0.224645
900,17.312,18.0364,0.224903
901,17.2899,18.0561,0.225149
902,17.2872,18.076,0.225398
903,17.2814,18.0957,0.2256449999999999
904,17.2735,18.1161,0.225899
905,17.2708,18.1361,0.226149
906,17.2522,18.156,0.226398
907,17.2556,18.1762,0.22665
908,17.2382,18.1957,0.2268939999999999
909,17.2378,18.2162,0.227149
910,17.2273,18.2358,0.2273949999999999
911,17.2145,18.2559,0.227646
912,17.2112,18.2759,0.227896
913,17.1957,18.296,0.228146
914,17.1947,18.3163,0.228401
915,17.175,18.3356,0.228641
916,17.1681,18.3559,0.228896
917,17.1656,18.3758,0.229144
918,17.15,18.3962,0.229398
919,17.1402,18.4161,0.229647
920,17.1246,18.436,0.229896
921,17.1198,18.4562,0.230148
922,17.1049,18.4757,0.230392
923,17.0939,18.4962,0.230648
924,17.0877,18.516,0.230896
925,17.0658,18.5359,0.231144
926,17.0619,18.5562,0.231397
927,17.0414,18.5757,0.231642
928,17.0361,18.5963,0.231899
929,17.0152,18.6157,0.232141
930,17.0042,18.636,0.232395
931,16.9962,18.6561,0.232646
932,16.9719,18.6758,0.232893
933,16.9653,18.6962,0.233147
934,16.9418,18.7157,0.233391
935,16.9368,18.7363,0.233648
936,16.9166,18.7557,0.23389
937,16.9015,18.7761,0.234146
938,16.8897,18.7963,0.234398
939,16.8642,18.8158,0.234641
940,16.8574,18.836,0.234894
941,16.8375,18.8559,0.235142
942,16.821,18.8762,0.235396
943,16.8041,18.8959,0.235642
944,16.7793,18.9157,0.23589
945,16.7774,18.9363,0.236147
946,16.7432,18.9559,0.236392
947,16.7313,18.9761,0.236645
948,16.7103,18.9958,0.23689
949,16.6923,19.0159,0.237141
950,16.677,19.036,0.237392
951,16.6485,19.0561,0.237643
952,16.6387,19.0763,0.237896
953,16.6078,19.0956,0.238138
954,16.5968,19.1163,0.238396
955,16.5734,19.1359,0.238641
956,16.5479,19.1561,0.238893
957,16.53,19.1758,0.23914
958,16.5057,19.196,0.239392
959,16.4899,19.2163,0.239645
960,16.4595,19.2359,0.23989
961,16.4381,19.2559,0.240141
962,16.4229,19.2758,0.240389
963,16.3929,19.2961,0.240642
964,16.3727,19.3162,0.240893
965,16.3402,19.3358,0.241139
966,16.3232,19.356,0.241391
967,16.2974,19.3757,0.241638
968,16.2732,19.3963,0.241894
969,16.2489,19.4161,0.242142
970,16.2157,19.4358,0.242387
971,16.1986,19.456,0.24264
972,16.1667,19.4758,0.242888
973,16.1459,19.4965,0.2431459999999999
974,16.1112,19.5155,0.243384
975,16.0869,19.5361,0.243641
976,16.0647,19.5561,0.243891
977,16.0295,19.576,0.24414
978,16.0043,19.5961,0.244391
979,15.972,19.6158,0.244636
980,15.9482,19.6361,0.244891
981,15.9185,19.6559,0.245138
982,15.884,19.6761,0.24539
983,15.8605,19.6962,0.245641
984,15.821,19.7158,0.245887
985,15.7986,19.7362,0.246141
986,15.7613,19.7559,0.246387
987,15.7317,19.776,0.246639
988,15.7005,19.7959,0.246887
989,15.6636,19.8159,0.247137
990,15.6407,19.8363,0.247392
991,15.5945,19.8558,0.247635
992,15.5687,19.8762,0.24789
993,15.5326,19.8957,0.248134
994,15.4998,19.9161,0.248389
995,15.466,19.9359,0.248637
996,15.4245,19.956,0.248887
997,15.3956,19.9762,0.249139
998,15.3532,19.9959,0.249386
999,15.3208,20.016,0.249638
1000,15.2872,20.036,0.249887
1001,15.2427,20.0561,0.2501379999999999
1002,15.2097,20.0759,0.250386
1003,15.1656,20.0959,0.250635
1004,15.1375,20.1164,0.250891
1005,15.087,20.1359,0.251135
1006,15.0498,20.1561,0.251388
1007,15.0137,20.1759,0.251635
1008,14.9688,20.1959,0.251885
1009,14.9321,20.2162,0.252138
1010,14.8821,20.2359,0.2523849999999999
1011,14.8481,20.2562,0.252638
1012,14.802,20.2755,0.25288
1013,14.7613,20.2963,0.253139
1014,14.7194,20.3161,0.253386
1015,14.6699,20.336,0.253636
1016,14.6287,20.356,0.253885
1017,14.5825,20.376,0.254135
1018,14.5412,20.3964,0.25439
1019,14.4876,20.4157,0.254631
1020,14.4436,20.4359,0.254884
1021,14.4061,20.4561,0.255136
1022,14.3472,20.476,0.255385
1023,14.3036,20.4963,0.255639
1024,14.2474,20.5157,0.25588
1025,14.2059,20.5361,0.256135
1026,14.1527,20.5559,0.256383
1027,14.1002,20.5761,0.256635
1028,14.0539,20.5963,0.256887
1029,13.993,20.6156,0.257129
1030,13.9501,20.6362,0.257386
1031,13.8914,20.6558,0.257631
1032,13.8399,20.6763,0.257887
1033,13.7827,20.6958,0.258131
1034,13.7258,20.7159,0.258382
1035,13.6792,20.7364,0.258638
1036,13.6111,20.7559,0.258882
1037,13.5579,20.7759,0.259132
1038,13.5017,20.7959,0.259381
1039,13.4413,20.8161,0.259634
1040,13.3851,20.8361,0.259884
1041,13.3151,20.8559,0.260132
1042,13.2649,20.8763,0.260386
1043,13.1938,20.8958,0.26063
1044,13.1367,20.9161,0.260884
1045,13.0726,20.936,0.261132
1046,13.004,20.9559,0.261381
1047,12.9422,20.976,0.261631
1048,12.8718,20.9961,0.261882
1049,12.8117,21.0164,0.262136
1050,12.7357,21.0357,0.262378
1051,12.6688,21.0562,0.262634
1052,12.6012,21.0758,0.262878
1053,12.5293,21.0961,0.263132
1054,12.4577,21.116,0.263381
1055,12.3789,21.1361,0.263632
1056,12.3084,21.1562,0.263883
1057,12.2299,21.1758,0.264128
1058,12.1531,21.1962,0.264383
1059,12.077,21.2161,0.264632
1060,11.988,21.236,0.264881
1061,11.9051,21.2561,0.265132
1062,11.8019,21.2759,0.265378
1063,11.6684,21.2963,0.265633