File: Datasets/lowcarbon.csv
Time,Displacement,Force,Strain 1
(s),(mm),(kN),(mm/mm)
0,0,0.1054,0.00006465
0.5,0.03,1.005,0.0001744
1,0.07,1.987,0.0002909
1.5,0.1,2.793,0.0003867
2,0.13,3.467,0.0004751
2.5,0.17,4.059,0.0005538
3,0.2,4.554,0.0006202
3.5,0.23,4.963,0.0006614
4,0.27,5.345,0.0007247
4.5,0.3,5.718,0.0007691
5,0.33,6.08,0.0008101
5.5,0.37,6.422,0.0008516
6,0.4,6.753,0.0008911
6.5,0.43,7.082,0.0009351
7,0.47,7.405,0.0009705
7.5,0.5,7.731,0.001012
8,0.53,8.071,0.001057
8.5,0.57,8.408,0.001093
9,0.6,8.744,0.00114
9.5,0.63,9.07,0.001181
10,0.67,9.383,0.001219
10.5,0.7,9.713,0.001262
11,0.73,10.02,0.00131
11.5,0.77,10.33,0.001341
12,0.8,10.65,0.001382
12.5,0.83,10.96,0.001419
13,0.87,11.26,0.001456
13.5,0.9,11.58,0.001492
14,0.93,11.87,0.001525
14.5,0.97,12.17,0.00156
15,1,12.48,0.001601
15.5,1.03,12.79,0.00163
16,1.07,13.1,0.001675
16.5,1.1,13.41,0.001718
17,1.13,13.73,0.001747
17.5,1.17,14.04,0.001778
18,1.2,14.36,0.001824
18.5,1.23,14.68,0.001859
19,1.27,15,0.0019
19.5,1.3,15.33,0.001943
20,1.33,15.65,0.00198
20.5,1.37,15.98,0.002025
21,1.4,16.3,0.002067
21.5,1.43,16.63,0.002099
22,1.47,16.96,0.00215
22.5,1.5,17.29,0.002186
23,1.53,17.62,0.002227
23.5,1.57,17.96,0.002274
24,1.6,18.28,0.002324
24.5,1.63,18.62,0.002364
25,1.67,18.96,0.002409
25.5,1.7,19.29,0.002468
26,1.73,19.62,0.002524
26.5,1.77,19.96,0.002582
27,1.8,20.29,0.002643
27.5,1.83,20.62,0.002707
28,1.87,20.95,0.00279
28.5,1.9,21.28,0.002867
29,1.93,21.6,0.002942
29.5,1.97,21.93,0.003038
30,2,22.25,0.003143
30.5,2.03,22.56,0.003244
31,2.07,22.88,0.003367
31.5,2.1,23.19,0.003504
32,2.13,23.49,0.00365
32.5,2.17,23.79,0.003816
33,2.2,24.07,0.003997
33.5,2.23,24.35,0.004192
34,2.27,24.62,0.004421
34.5,2.3,24.88,0.00467
35,2.33,25.13,0.004932
35.5,2.37,25.37,0.005225
36,2.4,25.59,0.00556
36.5,2.43,25.8,0.005919
37,2.47,25.99,0.006327
37.5,2.5,26.16,0.006775
38,2.53,26.32,0.007286
38.5,2.57,26.45,0.007841
39,2.6,26.56,0.008453
39.5,2.63,26.66,0.009129
40,2.67,26.73,0.00986
40.5,2.7,26.8,0.01065
41,2.73,26.85,0.01148
41.5,2.77,26.89,0.01234
42,2.8,26.93,0.01326
42.5,2.83,26.96,0.01419
43,2.87,26.99,0.01514
43.5,2.9,27.02,0.0161
44,2.93,27.04,0.01709
44.5,2.97,27.06,0.01807
45,3,27.08,0.01907
45.5,3.03,27.09,0.02007
46,3.07,27.11,0.02107
46.5,3.1,27.12,0.02209
47,3.13,27.13,0.02311
47.5,3.17,27.14,0.02415
48,3.2,27.15,0.0252
48.5,3.23,27.15,0.02625
49,3.27,27.16,0.0273
49.5,3.3,27.17,0.02838
50,3.33,27.17,0.02946
50.5,3.37,27.17,0.03056
51,3.4,27.16,0.03168
51.5,3.43,27.16,0.03281
52,3.47,27.15,0.03395
52.5,3.5,27.14,0.0351
53,3.53,27.13,0.03629
53.5,3.57,27.11,0.03748
54,3.6,27.09,0.03869
54.5,3.63,27.07,0.03991
55,3.67,27.05,0.04117
55.5,3.7,27.01,0.04244
56,3.73,26.98,0.0437
56.5,3.77,26.94,0.04499
57,3.8,26.89,0.04631
57.5,3.83,26.85,0.04762
58,3.87,26.8,0.04895
58.5,3.9,26.74,0.05028
59,3.93,26.68,0.0516
59.5,3.97,26.62,0.05295
60,4,26.56,0.05429
60.5,4.03,26.49,0.05564
61,4.07,26.42,0.05699
61.5,4.1,26.35,0.05834
62,4.13,26.28,0.0597
62.5,4.17,26.2,0.06105
63,4.2,26.13,0.0624
63.5,4.23,26.05,0.06376
64,4.27,25.98,0.06513
64.5,4.3,25.9,0.06649
65,4.33,25.82,0.06786
65.5,4.37,25.73,0.06923
66,4.4,25.65,0.0706
66.5,4.43,25.57,0.07198
67,4.47,25.48,0.07335
67.5,4.5,25.4,0.07472
68,4.53,25.32,0.07608
68.5,4.57,25.23,0.07745
69,4.6,25.14,0.07883
69.5,4.63,25.05,0.08021
70,4.67,24.96,0.08159
70.5,4.7,24.88,0.08296
71,4.73,24.78,0.08434
71.5,4.77,24.69,0.08572
72,4.8,24.6,0.0871
72.5,4.83,24.51,0.08847
73,4.87,24.41,0.08986
73.5,4.9,24.31,0.09126
74,4.93,24.21,0.09264
74.5,4.97,24.12,0.09403
75,5,24.02,0.0954
75.5,5.03,23.92,0.09681
76,5.07,23.82,0.0982
76.5,5.1,23.71,0.09959
77,5.13,23.61,0.101
77.5,5.17,23.5,0.1024
78,5.2,23.39,0.1038
78.5,5.23,23.29,0.1052
79,5.27,23.18,0.1066
79.5,5.3,23.06,0.108
80,5.33,22.95,0.1094
80.5,5.37,22.84,0.1108
81,5.4,22.72,0.1122
81.5,5.43,22.6,0.1136
82,5.47,22.48,0.1151
82.5,5.5,22.35,0.1165
83,5.53,22.23,0.1179
83.5,5.57,22.1,0.1193
84,5.6,21.97,0.1208
84.5,5.63,21.84,0.1222
85,5.67,21.71,0.1236
85.5,5.7,21.57,0.125
86,5.73,21.43,0.1265
86.5,5.77,21.29,0.1279
87,5.8,21.15,0.1293
87.5,5.83,21,0.1308
88,5.87,20.85,0.1322
88.5,5.9,20.7,0.1337
89,5.93,20.54,0.1351
89.5,5.97,20.38,0.1366
90,6,20.22,0.138
90.5,6.03,20.05,0.1395
91,6.07,19.87,0.141
91.5,6.1,19.68,0.1424
92,6.13,19.4,0.144
92.05,6.14,11.35,0.1467